Workbook

Sheet SET-UP & SUMMARY
A1: SUMMARY - NPO PAYOUT - AP
A3: PAYOUT EVENT DETAILS - SETUP
A4: Event Date: | B4: 46270
A5: Event Day of Week: | B5: =B4 -> 46270
A6: Event Description: | B6: Football
A10: SUMMARY REPORT — ASSIGNMENT-DRIVEN
A11: NPO | B11: ASSIGNMENT SALES | C11: CONTRACT DONATION | D11: TIPS | E11: TOTAL PAYOUT*
A12: ARVC | B12: =SUMIFS('CONTRACT CALC'!$J$13:$J$112,'CONTRACT CALC'!$B$13:$B$112,A12) -> 48024 | C12: =SUMIFS('CONTRACT CALC'!$K$13:$K$112,'CONTRACT CALC'!$B$13:$B$112,A12) -> 4486.82 | D12: =SUMIFS('TIPS DATA'!$H$2:$H$101,'TIPS DATA'!$C$2:$C$101,A12) -> 3421.74 | E12: =C12+D12 -> 7908.56
A13: AIRFORCE | B13: =SUMIFS('CONTRACT CALC'!$J$13:$J$112,'CONTRACT CALC'!$B$13:$B$112,A13) -> 0 | C13: =SUMIFS('CONTRACT CALC'!$K$13:$K$112,'CONTRACT CALC'!$B$13:$B$112,A13) -> 0 | D13: =SUMIFS('TIPS DATA'!$H$2:$H$101,'TIPS DATA'!$C$2:$C$101,A13) -> 0 | E13: =C13+D13 -> 0
A14: UNITED FIT | B14: =SUMIFS('CONTRACT CALC'!$J$13:$J$112,'CONTRACT CALC'!$B$13:$B$112,A14) -> 0 | C14: =SUMIFS('CONTRACT CALC'!$K$13:$K$112,'CONTRACT CALC'!$B$13:$B$112,A14) -> 0 | D14: =SUMIFS('TIPS DATA'!$H$2:$H$101,'TIPS DATA'!$C$2:$C$101,A14) -> 0 | E14: =C14+D14 -> 0
A15: DCVA | B15: =SUMIFS('CONTRACT CALC'!$J$13:$J$112,'CONTRACT CALC'!$B$13:$B$112,A15) -> 0 | C15: =SUMIFS('CONTRACT CALC'!$K$13:$K$112,'CONTRACT CALC'!$B$13:$B$112,A15) -> 0 | D15: =SUMIFS('TIPS DATA'!$H$2:$H$101,'TIPS DATA'!$C$2:$C$101,A15) -> 0 | E15: =C15+D15 -> 0
A16: DEL N CHEER | B16: =SUMIFS('CONTRACT CALC'!$J$13:$J$112,'CONTRACT CALC'!$B$13:$B$112,A16) -> 0 | C16: =SUMIFS('CONTRACT CALC'!$K$13:$K$112,'CONTRACT CALC'!$B$13:$B$112,A16) -> 0 | D16: =SUMIFS('TIPS DATA'!$H$2:$H$101,'TIPS DATA'!$C$2:$C$101,A16) -> 0 | E16: =C16+D16 -> 0
A17: RIO GRANDE RGHS | B17: =SUMIFS('CONTRACT CALC'!$J$13:$J$112,'CONTRACT CALC'!$B$13:$B$112,A17) -> 0 | C17: =SUMIFS('CONTRACT CALC'!$K$13:$K$112,'CONTRACT CALC'!$B$13:$B$112,A17) -> 0 | D17: =SUMIFS('TIPS DATA'!$H$2:$H$101,'TIPS DATA'!$C$2:$C$101,A17) -> 0 | E17: =C17+D17 -> 0
A18: VICTORY OUTREACH | B18: =SUMIFS('CONTRACT CALC'!$J$13:$J$112,'CONTRACT CALC'!$B$13:$B$112,A18) -> 6694.5 | C18: =SUMIFS('CONTRACT CALC'!$K$13:$K$112,'CONTRACT CALC'!$B$13:$B$112,A18) -> 643.12 | D18: =SUMIFS('TIPS DATA'!$H$2:$H$101,'TIPS DATA'!$C$2:$C$101,A18) -> 0 | E18: =C18+D18 -> 643.12
A19: TOTAL | B19: =SUM(B12:B18) -> 54718.5 | C19: =SUM(C12:C18) -> 5129.94 | D19: =SUM(D12:D18) -> 3421.74 | E19: =SUM(E12:E18) -> 8551.68
A21: VENDOR PAYOUT is the reusable settlement OUTPUT controlled by Event Date + Payee/NPO. Update source data, select Event + Payee on VENDOR PAYOUT, review, export PDF. One-way only: SOURCE → CALCULATION → OUTPUT.
A23: SETUP - STAND LOCATIONS
A24: STAND ID | B24: STAND DESCRIPTION
A25: BASEBALL | B25: TRAILER | C25: baseball
A26: 207 - PREM | B26: DESSERT CART | C26: PIT
A27: PREM 000 | B27: PREMIUM BANQUET | C27: PIT
A28: FB 100 | B28: TRAILER N CONCOURSE | C28: FB
A29: FB 100B | B29: MBP TRAILER N CONCOURSE | C29: FB
A30: FB 101 | B30: STADIUM SIPS SHACK SW | C30: FB
A31: FB 102 | B31: TOWER SOUTH | C31: FB
A32: FB 103 | B32: TOWER NORTH | C32: FB
A33: FB 104 | B33: RED RALLY NORTH WEST | C33: FB
A34: FB 105 | B34: NW SPECIALTY DAWG 2.0 | C34: FB
A35: FB 106 | B35: RED RALLY NORTH EAST | C35: FB
A36: FB 107 | B36: NE SPECIALTY DAWG O.G. | C36: FB
... A80: PIT CU1 | B80: CULINARY SUPPORT | C80: PIT

Sheet VENDOR PAYOUT
C2: SETTLEMENT STATEMENT
C3: LEVY • UNM ATHLETICS
B5: =$E$10 -> ARVC | G5: TOTAL PAYABLE
B6: ='SET-UP & SUMMARY'!B6 -> Football | G6: =SUM(H33,I33,I36,I37,I38,I39,I40,I41) -> 7908.56
B9: EVENT DATE | C9: INVOICE | E9: PAYEE / NPO | G9: SAP ID | H9: BSS ID
B10: 46270 | C10: =CONCATENATE("UNM-",TEXT(B10,"MMDDYY-"),E10) -> UNM-090526-ARVC | E10: ARVC
B11: Controls: Event Date (B10) + Payee/NPO (E10). Location rows filter from EVENT ASSIGNMENT via CONTRACT CALC. Flow: SOURCE → CALCULATION → OUTPUT (never reverse).
B12: SALES COMMISSION (DONATION TO NPO): POS SALES | E12: NON-CALCULATED SALES DATA
B13: FOOD / NON-ALCOHOLIC | C13: ALCOHOL | D13: GROUP NET | E13: SALES TAX | F13: GROSS SALES
B14: =D33 -> 32245 | C14: =F33 -> 15779 | D14: =C33 -> 48024 | E14: =D33 -> 32245 | F14: =E33 -> 3224.5
B16: LOCATION SERVICE DETAIL
A17: # | B17: SERVICE AREA | C17: NET SALES | D17: FOOD / NON-ALC NET SALES | E17: 10% FOOD / NON-ALC COMMISSION | F17: ALCOHOL NET SALES | G17: 8% ALCOHOL COMMISSION | H17: TOTAL COMMISSION | I17: GRATUITIES
A18: =IFERROR(MATCH(TEXT($B$10,"yyyymmdd")&"|"&$E$10&"|1",'EVENT ASSIGNMENT'!$K$2:$K$101,0),"") -> 1 | B18: =IF(IFERROR(MATCH(TEXT($B$10,"yyyymmdd")&"|"&$E$10&"|1",'EVENT ASSIGNMENT'!$K$2:$K$101,0),"")="","",IFERROR(INDEX('EVENT ASSIGNMENT'!$D$2:$D$101,IFERROR(MATCH(TEXT($B$10,"yyyymmdd")&"|"&$E$10&"|1",'EVENT ASSIGNMENT'!$K$2:$K$101,0),"")),"")) -> RED RALLY NORTH EAST | C18: =IF(OR(IFERROR(MATCH(TEXT($B$10,"yyyymmdd")&"|"&$E$10&"|1",'EVENT ASSIGNMENT'!$K$2:$K$101,0),"")="",B18=""),"",IFERROR(INDEX('CONTRACT CALC'!$G$13:$G$112,IFERROR(MATCH(TEXT($B$10,"yyyymmdd")&"|"&$E$10&"|1",'EVENT ASSIGNMENT'!$K$2:$K$101,0),""))*INDEX('CONTRACT CALC'!$F$13:$F$112,IFERROR(MATCH(TEXT($B$10,"yyyymmdd")&"|"&$E$10&"|1",'EVENT ASSIGNMENT'!$K$2:$K$101,0),"")),"")) -> 29393 | D18: =IF(OR(IFERROR(MATCH(TEXT($B$10,"yyyymmdd")&"|"&$E$10&"|1",'EVENT ASSIGNMENT'!$K$2:$K$101,0),"")="",B18=""),"",IFERROR(INDEX('CONTRACT CALC'!$I$13:$I$112,IFERROR(MATCH(TEXT($B$10,"yyyymmdd")&"|"&$E$10&"|1",'EVENT ASSIGNMENT'!$K$2:$K$101,0),""))*INDEX('CONTRACT CALC'!$F$13:$F$112,IFERROR(MATCH(TEXT($B$10,"yyyymmdd")&"|"&$E$10&"|1",'EVENT ASSIGNMENT'!$K$2:$K$101,0),"")),"")) -> 22292 | E18: =IF(D18="","",D18*'CONTRACT CALC'!$B$4) -> 2229.2 | F18: =IF(OR(IFERROR(MATCH(TEXT($B$10,"yyyymmdd")&"|"&$E$10&"|1",'EVENT ASSIGNMENT'!$K$2:$K$101,0),"")="",B18=""),"",IFERROR(INDEX('CONTRACT CALC'!$H$13:$H$112,IFERROR(MATCH(TEXT($B$10,"yyyymmdd")&"|"&$E$10&"|1",'EVENT ASSIGNMENT'!$K$2:$K$101,0),""))*INDEX('CONTRACT CALC'!$F$13:$F$112,IFERROR(MATCH(TEXT($B$10,"yyyymmdd")&"|"&$E$10&"|1",'EVENT ASSIGNMENT'!$K$2:$K$101,0),"")),"")) -> 7101 | G18: =IF(F18="","",F18*'CONTRACT CALC'!$B$5) -> 568.08 | H18: =IF(B18="","",N(E18)+N(G18)) -> 2797.28 | I18: =IF(OR(IFERROR(MATCH(TEXT($B$10,"yyyymmdd")&"|"&$E$10&"|1",'EVENT ASSIGNMENT'!$K$2:$K$101,0),"")="",B18=""),"",IF(COUNTIFS('TIPS DATA'!$A$2:$A$101,$B$10,'TIPS DATA'!$C$2:$C$101,$E$10,'TIPS DATA'!$D$2:$D$101,INDEX('EVENT ASSIGNMENT'!$C$2:$C$101,IFERROR(MATCH(TEXT($B$10,"yyyymmdd")&"|"&$E$10&"|1",'EVENT ASSIGNMENT'!$K$2:$K$101,0),"")))>0,SUMIFS('TIPS DATA'!$H$2:$H$101,'TIPS DATA'!$A$2:$A$101,$B$10,'TIPS DATA'!$C$2:$C$101,$E$10,'TIPS DATA'!$D$2:$D$101,INDEX('EVENT ASSIGNMENT'!$C$2:$C$101,IFERROR(MATCH(TEXT($B$10,"yyyymmdd")&"|"&$E$10&"|1",'EVENT ASSIGNMENT'!$K$2:$K$101,0),""))),SUMIFS('TIPS DATA'!$H$2:$H$101,'TIPS DATA'!$A$2:$A$101,$B$10,'TIPS DATA'!$C$2:$C$101,$E$10,'TIPS DATA'!$E$2:$E$101,INDEX('EVENT ASSIGNMENT'!$D$2:$D$101,IFERROR(MATCH(TEXT($B$10,"yyyymmdd")&"|"&$E$10&"|1",'EVENT ASSIGNMENT'!$K$2:$K$101,0),""))))) -> 1905.76
A19: =IFERROR(MATCH(TEXT($B$10,"yyyymmdd")&"|"&$E$10&"|2",'EVENT ASSIGNMENT'!$K$2:$K$101,0),"") -> 2 | B19: =IF(IFERROR(MATCH(TEXT($B$10,"yyyymmdd")&"|"&$E$10&"|2",'EVENT ASSIGNMENT'!$K$2:$K$101,0),"")="","",IFERROR(INDEX('EVENT ASSIGNMENT'!$D$2:$D$101,IFERROR(MATCH(TEXT($B$10,"yyyymmdd")&"|"&$E$10&"|2",'EVENT ASSIGNMENT'!$K$2:$K$101,0),"")),"")) -> MBP MINI MELTS (NW) | C19: =IF(OR(IFERROR(MATCH(TEXT($B$10,"yyyymmdd")&"|"&$E$10&"|2",'EVENT ASSIGNMENT'!$K$2:$K$101,0),"")="",B19=""),"",IFERROR(INDEX('CONTRACT CALC'!$G$13:$G$112,IFERROR(MATCH(TEXT($B$10,"yyyymmdd")&"|"&$E$10&"|2",'EVENT ASSIGNMENT'!$K$2:$K$101,0),""))*INDEX('CONTRACT CALC'!$F$13:$F$112,IFERROR(MATCH(TEXT($B$10,"yyyymmdd")&"|"&$E$10&"|2",'EVENT ASSIGNMENT'!$K$2:$K$101,0),"")),"")) -> 1930 | D19: =IF(OR(IFERROR(MATCH(TEXT($B$10,"yyyymmdd")&"|"&$E$10&"|2",'EVENT ASSIGNMENT'!$K$2:$K$101,0),"")="",B19=""),"",IFERROR(INDEX('CONTRACT CALC'!$I$13:$I$112,IFERROR(MATCH(TEXT($B$10,"yyyymmdd")&"|"&$E$10&"|2",'EVENT ASSIGNMENT'!$K$2:$K$101,0),""))*INDEX('CONTRACT CALC'!$F$13:$F$112,IFERROR(MATCH(TEXT($B$10,"yyyymmdd")&"|"&$E$10&"|2",'EVENT ASSIGNMENT'!$K$2:$K$101,0),"")),"")) -> 1930 | E19: =IF(D19="","",D19*'CONTRACT CALC'!$B$4) -> 193 | F19: =IF(OR(IFERROR(MATCH(TEXT($B$10,"yyyymmdd")&"|"&$E$10&"|2",'EVENT ASSIGNMENT'!$K$2:$K$101,0),"")="",B19=""),"",IFERROR(INDEX('CONTRACT CALC'!$H$13:$H$112,IFERROR(MATCH(TEXT($B$10,"yyyymmdd")&"|"&$E$10&"|2",'EVENT ASSIGNMENT'!$K$2:$K$101,0),""))*INDEX('CONTRACT CALC'!$F$13:$F$112,IFERROR(MATCH(TEXT($B$10,"yyyymmdd")&"|"&$E$10&"|2",'EVENT ASSIGNMENT'!$K$2:$K$101,0),"")),"")) -> 0 | G19: =IF(F19="","",F19*'CONTRACT CALC'!$B$5) -> 0 | H19: =IF(B19="","",N(E19)+N(G19)) -> 193 | I19: =IF(OR(IFERROR(MATCH(TEXT($B$10,"yyyymmdd")&"|"&$E$10&"|2",'EVENT ASSIGNMENT'!$K$2:$K$101,0),"")="",B19=""),"",IF(COUNTIFS('TIPS DATA'!$A$2:$A$101,$B$10,'TIPS DATA'!$C$2:$C$101,$E$10,'TIPS DATA'!$D$2:$D$101,INDEX('EVENT ASSIGNMENT'!$C$2:$C$101,IFERROR(MATCH(TEXT($B$10,"yyyymmdd")&"|"&$E$10&"|2",'EVENT ASSIGNMENT'!$K$2:$K$101,0),"")))>0,SUMIFS('TIPS DATA'!$H$2:$H$101,'TIPS DATA'!$A$2:$A$101,$B$10,'TIPS DATA'!$C$2:$C$101,$E$10,'TIPS DATA'!$D$2:$D$101,INDEX('EVENT ASSIGNMENT'!$C$2:$C$101,IFERROR(MATCH(TEXT($B$10,"yyyymmdd")&"|"&$E$10&"|2",'EVENT ASSIGNMENT'!$K$2:$K$101,0),""))),SUMIFS('TIPS DATA'!$H$2:$H$101,'TIPS DATA'!$A$2:$A$101,$B$10,'TIPS DATA'!$C$2:$C$101,$E$10,'TIPS DATA'!$E$2:$E$101,INDEX('EVENT ASSIGNMENT'!$D$2:$D$101,IFERROR(MATCH(TEXT($B$10,"yyyymmdd")&"|"&$E$10&"|2",'EVENT ASSIGNMENT'!$K$2:$K$101,0),""))))) -> 154.32
A20: =IFERROR(MATCH(TEXT($B$10,"yyyymmdd")&"|"&$E$10&"|3",'EVENT ASSIGNMENT'!$K$2:$K$101,0),"") -> 3 | B20: =IF(IFERROR(MATCH(TEXT($B$10,"yyyymmdd")&"|"&$E$10&"|3",'EVENT ASSIGNMENT'!$K$2:$K$101,0),"")="","",IFERROR(INDEX('EVENT ASSIGNMENT'!$D$2:$D$101,IFERROR(MATCH(TEXT($B$10,"yyyymmdd")&"|"&$E$10&"|3",'EVENT ASSIGNMENT'!$K$2:$K$101,0),"")),"")) -> MBP MINI MELTS (NE) | C20: =IF(OR(IFERROR(MATCH(TEXT($B$10,"yyyymmdd")&"|"&$E$10&"|3",'EVENT ASSIGNMENT'!$K$2:$K$101,0),"")="",B20=""),"",IFERROR(INDEX('CONTRACT CALC'!$G$13:$G$112,IFERROR(MATCH(TEXT($B$10,"yyyymmdd")&"|"&$E$10&"|3",'EVENT ASSIGNMENT'!$K$2:$K$101,0),""))*INDEX('CONTRACT CALC'!$F$13:$F$112,IFERROR(MATCH(TEXT($B$10,"yyyymmdd")&"|"&$E$10&"|3",'EVENT ASSIGNMENT'!$K$2:$K$101,0),"")),"")) -> 2330 | D20: =IF(OR(IFERROR(MATCH(TEXT($B$10,"yyyymmdd")&"|"&$E$10&"|3",'EVENT ASSIGNMENT'!$K$2:$K$101,0),"")="",B20=""),"",IFERROR(INDEX('CONTRACT CALC'!$I$13:$I$112,IFERROR(MATCH(TEXT($B$10,"yyyymmdd")&"|"&$E$10&"|3",'EVENT ASSIGNMENT'!$K$2:$K$101,0),""))*INDEX('CONTRACT CALC'!$F$13:$F$112,IFERROR(MATCH(TEXT($B$10,"yyyymmdd")&"|"&$E$10&"|3",'EVENT ASSIGNMENT'!$K$2:$K$101,0),"")),"")) -> 2330 | E20: =IF(D20="","",D20*'CONTRACT CALC'!$B$4) -> 233 | F20: =IF(OR(IFERROR(MATCH(TEXT($B$10,"yyyymmdd")&"|"&$E$10&"|3",'EVENT ASSIGNMENT'!$K$2:$K$101,0),"")="",B20=""),"",IFERROR(INDEX('CONTRACT CALC'!$H$13:$H$112,IFERROR(MATCH(TEXT($B$10,"yyyymmdd")&"|"&$E$10&"|3",'EVENT ASSIGNMENT'!$K$2:$K$101,0),""))*INDEX('CONTRACT CALC'!$F$13:$F$112,IFERROR(MATCH(TEXT($B$10,"yyyymmdd")&"|"&$E$10&"|3",'EVENT ASSIGNMENT'!$K$2:$K$101,0),"")),"")) -> 0 | G20: =IF(F20="","",F20*'CONTRACT CALC'!$B$5) -> 0 | H20: =IF(B20="","",N(E20)+N(G20)) -> 233 | I20: =IF(OR(IFERROR(MATCH(TEXT($B$10,"yyyymmdd")&"|"&$E$10&"|3",'EVENT ASSIGNMENT'!$K$2:$K$101,0),"")="",B20=""),"",IF(COUNTIFS('TIPS DATA'!$A$2:$A$101,$B$10,'TIPS DATA'!$C$2:$C$101,$E$10,'TIPS DATA'!$D$2:$D$101,INDEX('EVENT ASSIGNMENT'!$C$2:$C$101,IFERROR(MATCH(TEXT($B$10,"yyyymmdd")&"|"&$E$10&"|3",'EVENT ASSIGNMENT'!$K$2:$K$101,0),"")))>0,SUMIFS('TIPS DATA'!$H$2:$H$101,'TIPS DATA'!$A$2:$A$101,$B$10,'TIPS DATA'!$C$2:$C$101,$E$10,'TIPS DATA'!$D$2:$D$101,INDEX('EVENT ASSIGNMENT'!$C$2:$C$101,IFERROR(MATCH(TEXT($B$10,"yyyymmdd")&"|"&$E$10&"|3",'EVENT ASSIGNMENT'!$K$2:$K$101,0),""))),SUMIFS('TIPS DATA'!$H$2:$H$101,'TIPS DATA'!$A$2:$A$101,$B$10,'TIPS DATA'!$C$2:$C$101,$E$10,'TIPS DATA'!$E$2:$E$101,INDEX('EVENT ASSIGNMENT'!$D$2:$D$101,IFERROR(MATCH(TEXT($B$10,"yyyymmdd")&"|"&$E$10&"|3",'EVENT ASSIGNMENT'!$K$2:$K$101,0),""))))) -> 189
A21: =IFERROR(MATCH(TEXT($B$10,"yyyymmdd")&"|"&$E$10&"|4",'EVENT ASSIGNMENT'!$K$2:$K$101,0),"") -> 4 | B21: =IF(IFERROR(MATCH(TEXT($B$10,"yyyymmdd")&"|"&$E$10&"|4",'EVENT ASSIGNMENT'!$K$2:$K$101,0),"")="","",IFERROR(INDEX('EVENT ASSIGNMENT'!$D$2:$D$101,IFERROR(MATCH(TEXT($B$10,"yyyymmdd")&"|"&$E$10&"|4",'EVENT ASSIGNMENT'!$K$2:$K$101,0),"")),"")) -> MBP TRAILER N CONCOURSE | C21: =IF(OR(IFERROR(MATCH(TEXT($B$10,"yyyymmdd")&"|"&$E$10&"|4",'EVENT ASSIGNMENT'!$K$2:$K$101,0),"")="",B21=""),"",IFERROR(INDEX('CONTRACT CALC'!$G$13:$G$112,IFERROR(MATCH(TEXT($B$10,"yyyymmdd")&"|"&$E$10&"|4",'EVENT ASSIGNMENT'!$K$2:$K$101,0),""))*INDEX('CONTRACT CALC'!$F$13:$F$112,IFERROR(MATCH(TEXT($B$10,"yyyymmdd")&"|"&$E$10&"|4",'EVENT ASSIGNMENT'!$K$2:$K$101,0),"")),"")) -> 7626 | D21: =IF(OR(IFERROR(MATCH(TEXT($B$10,"yyyymmdd")&"|"&$E$10&"|4",'EVENT ASSIGNMENT'!$K$2:$K$101,0),"")="",B21=""),"",IFERROR(INDEX('CONTRACT CALC'!$I$13:$I$112,IFERROR(MATCH(TEXT($B$10,"yyyymmdd")&"|"&$E$10&"|4",'EVENT ASSIGNMENT'!$K$2:$K$101,0),""))*INDEX('CONTRACT CALC'!$F$13:$F$112,IFERROR(MATCH(TEXT($B$10,"yyyymmdd")&"|"&$E$10&"|4",'EVENT ASSIGNMENT'!$K$2:$K$101,0),"")),"")) -> 688 | E21: =IF(D21="","",D21*'CONTRACT CALC'!$B$4) -> 68.8 | F21: =IF(OR(IFERROR(MATCH(TEXT($B$10,"yyyymmdd")&"|"&$E$10&"|4",'EVENT ASSIGNMENT'!$K$2:$K$101,0),"")="",B21=""),"",IFERROR(INDEX('CONTRACT CALC'!$H$13:$H$112,IFERROR(MATCH(TEXT($B$10,"yyyymmdd")&"|"&$E$10&"|4",'EVENT ASSIGNMENT'!$K$2:$K$101,0),""))*INDEX('CONTRACT CALC'!$F$13:$F$112,IFERROR(MATCH(TEXT($B$10,"yyyymmdd")&"|"&$E$10&"|4",'EVENT ASSIGNMENT'!$K$2:$K$101,0),"")),"")) -> 6938 | G21: =IF(F21="","",F21*'CONTRACT CALC'!$B$5) -> 555.04 | H21: =IF(B21="","",N(E21)+N(G21)) -> 623.84 | I21: =IF(OR(IFERROR(MATCH(TEXT($B$10,"yyyymmdd")&"|"&$E$10&"|4",'EVENT ASSIGNMENT'!$K$2:$K$101,0),"")="",B21=""),"",IF(COUNTIFS('TIPS DATA'!$A$2:$A$101,$B$10,'TIPS DATA'!$C$2:$C$101,$E$10,'TIPS DATA'!$D$2:$D$101,INDEX('EVENT ASSIGNMENT'!$C$2:$C$101,IFERROR(MATCH(TEXT($B$10,"yyyymmdd")&"|"&$E$10&"|4",'EVENT ASSIGNMENT'!$K$2:$K$101,0),"")))>0,SUMIFS('TIPS DATA'!$H$2:$H$101,'TIPS DATA'!$A$2:$A$101,$B$10,'TIPS DATA'!$C$2:$C$101,$E$10,'TIPS DATA'!$D$2:$D$101,INDEX('EVENT ASSIGNMENT'!$C$2:$C$101,IFERROR(MATCH(TEXT($B$10,"yyyymmdd")&"|"&$E$10&"|4",'EVENT ASSIGNMENT'!$K$2:$K$101,0),""))),SUMIFS('TIPS DATA'!$H$2:$H$101,'TIPS DATA'!$A$2:$A$101,$B$10,'TIPS DATA'!$C$2:$C$101,$E$10,'TIPS DATA'!$E$2:$E$101,INDEX('EVENT ASSIGNMENT'!$D$2:$D$101,IFERROR(MATCH(TEXT($B$10,"yyyymmdd")&"|"&$E$10&"|4",'EVENT ASSIGNMENT'!$K$2:$K$101,0),""))))) -> 670.54
A22: =IFERROR(MATCH(TEXT($B$10,"yyyymmdd")&"|"&$E$10&"|5",'EVENT ASSIGNMENT'!$K$2:$K$101,0),"") -> 5 | B22: =IF(IFERROR(MATCH(TEXT($B$10,"yyyymmdd")&"|"&$E$10&"|5",'EVENT ASSIGNMENT'!$K$2:$K$101,0),"")="","",IFERROR(INDEX('EVENT ASSIGNMENT'!$D$2:$D$101,IFERROR(MATCH(TEXT($B$10,"yyyymmdd")&"|"&$E$10&"|5",'EVENT ASSIGNMENT'!$K$2:$K$101,0),"")),"")) -> NE SPECIALTY DAWG O.G. | C22: =IF(OR(IFERROR(MATCH(TEXT($B$10,"yyyymmdd")&"|"&$E$10&"|5",'EVENT ASSIGNMENT'!$K$2:$K$101,0),"")="",B22=""),"",IFERROR(INDEX('CONTRACT CALC'!$G$13:$G$112,IFERROR(MATCH(TEXT($B$10,"yyyymmdd")&"|"&$E$10&"|5",'EVENT ASSIGNMENT'!$K$2:$K$101,0),""))*INDEX('CONTRACT CALC'!$F$13:$F$112,IFERROR(MATCH(TEXT($B$10,"yyyymmdd")&"|"&$E$10&"|5",'EVENT ASSIGNMENT'!$K$2:$K$101,0),"")),"")) -> 6745 | D22: =IF(OR(IFERROR(MATCH(TEXT($B$10,"yyyymmdd")&"|"&$E$10&"|5",'EVENT ASSIGNMENT'!$K$2:$K$101,0),"")="",B22=""),"",IFERROR(INDEX('CONTRACT CALC'!$I$13:$I$112,IFERROR(MATCH(TEXT($B$10,"yyyymmdd")&"|"&$E$10&"|5",'EVENT ASSIGNMENT'!$K$2:$K$101,0),""))*INDEX('CONTRACT CALC'!$F$13:$F$112,IFERROR(MATCH(TEXT($B$10,"yyyymmdd")&"|"&$E$10&"|5",'EVENT ASSIGNMENT'!$K$2:$K$101,0),"")),"")) -> 5005 | E22: =IF(D22="","",D22*'CONTRACT CALC'!$B$4) -> 500.5 | F22: =IF(OR(IFERROR(MATCH(TEXT($B$10,"yyyymmdd")&"|"&$E$10&"|5",'EVENT ASSIGNMENT'!$K$2:$K$101,0),"")="",B22=""),"",IFERROR(INDEX('CONTRACT CALC'!$H$13:$H$112,IFERROR(MATCH(TEXT($B$10,"yyyymmdd")&"|"&$E$10&"|5",'EVENT ASSIGNMENT'!$K$2:$K$101,0),""))*INDEX('CONTRACT CALC'!$F$13:$F$112,IFERROR(MATCH(TEXT($B$10,"yyyymmdd")&"|"&$E$10&"|5",'EVENT ASSIGNMENT'!$K$2:$K$101,0),"")),"")) -> 1740 | G22: =IF(F22="","",F22*'CONTRACT CALC'!$B$5) -> 139.2 | H22: =IF(B22="","",N(E22)+N(G22)) -> 639.7 | I22: =IF(OR(IFERROR(MATCH(TEXT($B$10,"yyyymmdd")&"|"&$E$10&"|5",'EVENT ASSIGNMENT'!$K$2:$K$101,0),"")="",B22=""),"",IF(COUNTIFS('TIPS DATA'!$A$2:$A$101,$B$10,'TIPS DATA'!$C$2:$C$101,$E$10,'TIPS DATA'!$D$2:$D$101,INDEX('EVENT ASSIGNMENT'!$C$2:$C$101,IFERROR(MATCH(TEXT($B$10,"yyyymmdd")&"|"&$E$10&"|5",'EVENT ASSIGNMENT'!$K$2:$K$101,0),"")))>0,SUMIFS('TIPS DATA'!$H$2:$H$101,'TIPS DATA'!$A$2:$A$101,$B$10,'TIPS DATA'!$C$2:$C$101,$E$10,'TIPS DATA'!$D$2:$D$101,INDEX('EVENT ASSIGNMENT'!$C$2:$C$101,IFERROR(MATCH(TEXT($B$10,"yyyymmdd")&"|"&$E$10&"|5",'EVENT ASSIGNMENT'!$K$2:$K$101,0),""))),SUMIFS('TIPS DATA'!$H$2:$H$101,'TIPS DATA'!$A$2:$A$101,$B$10,'TIPS DATA'!$C$2:$C$101,$E$10,'TIPS DATA'!$E$2:$E$101,INDEX('EVENT ASSIGNMENT'!$D$2:$D$101,IFERROR(MATCH(TEXT($B$10,"yyyymmdd")&"|"&$E$10&"|5",'EVENT ASSIGNMENT'!$K$2:$K$101,0),""))))) -> 502.12
A23: =IFERROR(MATCH(TEXT($B$10,"yyyymmdd")&"|"&$E$10&"|6",'EVENT ASSIGNMENT'!$K$2:$K$101,0),"") | B23: =IF(IFERROR(MATCH(TEXT($B$10,"yyyymmdd")&"|"&$E$10&"|6",'EVENT ASSIGNMENT'!$K$2:$K$101,0),"")="","",IFERROR(INDEX('EVENT ASSIGNMENT'!$D$2:$D$101,IFERROR(MATCH(TEXT($B$10,"yyyymmdd")&"|"&$E$10&"|6",'EVENT ASSIGNMENT'!$K$2:$K$101,0),"")),"")) | C23: =IF(OR(IFERROR(MATCH(TEXT($B$10,"yyyymmdd")&"|"&$E$10&"|6",'EVENT ASSIGNMENT'!$K$2:$K$101,0),"")="",B23=""),"",IFERROR(INDEX('CONTRACT CALC'!$G$13:$G$112,IFERROR(MATCH(TEXT($B$10,"yyyymmdd")&"|"&$E$10&"|6",'EVENT ASSIGNMENT'!$K$2:$K$101,0),""))*INDEX('CONTRACT CALC'!$F$13:$F$112,IFERROR(MATCH(TEXT($B$10,"yyyymmdd")&"|"&$E$10&"|6",'EVENT ASSIGNMENT'!$K$2:$K$101,0),"")),"")) | D23: =IF(OR(IFERROR(MATCH(TEXT($B$10,"yyyymmdd")&"|"&$E$10&"|6",'EVENT ASSIGNMENT'!$K$2:$K$101,0),"")="",B23=""),"",IFERROR(INDEX('CONTRACT CALC'!$I$13:$I$112,IFERROR(MATCH(TEXT($B$10,"yyyymmdd")&"|"&$E$10&"|6",'EVENT ASSIGNMENT'!$K$2:$K$101,0),""))*INDEX('CONTRACT CALC'!$F$13:$F$112,IFERROR(MATCH(TEXT($B$10,"yyyymmdd")&"|"&$E$10&"|6",'EVENT ASSIGNMENT'!$K$2:$K$101,0),"")),"")) | E23: =IF(D23="","",D23*'CONTRACT CALC'!$B$4) | F23: =IF(OR(IFERROR(MATCH(TEXT($B$10,"yyyymmdd")&"|"&$E$10&"|6",'EVENT ASSIGNMENT'!$K$2:$K$101,0),"")="",B23=""),"",IFERROR(INDEX('CONTRACT CALC'!$H$13:$H$112,IFERROR(MATCH(TEXT($B$10,"yyyymmdd")&"|"&$E$10&"|6",'EVENT ASSIGNMENT'!$K$2:$K$101,0),""))*INDEX('CONTRACT CALC'!$F$13:$F$112,IFERROR(MATCH(TEXT($B$10,"yyyymmdd")&"|"&$E$10&"|6",'EVENT ASSIGNMENT'!$K$2:$K$101,0),"")),"")) | G23: =IF(F23="","",F23*'CONTRACT CALC'!$B$5) | H23: =IF(B23="","",N(E23)+N(G23)) | I23: =IF(OR(IFERROR(MATCH(TEXT($B$10,"yyyymmdd")&"|"&$E$10&"|6",'EVENT ASSIGNMENT'!$K$2:$K$101,0),"")="",B23=""),"",IF(COUNTIFS('TIPS DATA'!$A$2:$A$101,$B$10,'TIPS DATA'!$C$2:$C$101,$E$10,'TIPS DATA'!$D$2:$D$101,INDEX('EVENT ASSIGNMENT'!$C$2:$C$101,IFERROR(MATCH(TEXT($B$10,"yyyymmdd")&"|"&$E$10&"|6",'EVENT ASSIGNMENT'!$K$2:$K$101,0),"")))>0,SUMIFS('TIPS DATA'!$H$2:$H$101,'TIPS DATA'!$A$2:$A$101,$B$10,'TIPS DATA'!$C$2:$C$101,$E$10,'TIPS DATA'!$D$2:$D$101,INDEX('EVENT ASSIGNMENT'!$C$2:$C$101,IFERROR(MATCH(TEXT($B$10,"yyyymmdd")&"|"&$E$10&"|6",'EVENT ASSIGNMENT'!$K$2:$K$101,0),""))),SUMIFS('TIPS DATA'!$H$2:$H$101,'TIPS DATA'!$A$2:$A$101,$B$10,'TIPS DATA'!$C$2:$C$101,$E$10,'TIPS DATA'!$E$2:$E$101,INDEX('EVENT ASSIGNMENT'!$D$2:$D$101,IFERROR(MATCH(TEXT($B$10,"yyyymmdd")&"|"&$E$10&"|6",'EVENT ASSIGNMENT'!$K$2:$K$101,0),"")))))
A24: =IFERROR(MATCH(TEXT($B$10,"yyyymmdd")&"|"&$E$10&"|7",'EVENT ASSIGNMENT'!$K$2:$K$101,0),"") | B24: =IF(IFERROR(MATCH(TEXT($B$10,"yyyymmdd")&"|"&$E$10&"|7",'EVENT ASSIGNMENT'!$K$2:$K$101,0),"")="","",IFERROR(INDEX('EVENT ASSIGNMENT'!$D$2:$D$101,IFERROR(MATCH(TEXT($B$10,"yyyymmdd")&"|"&$E$10&"|7",'EVENT ASSIGNMENT'!$K$2:$K$101,0),"")),"")) | C24: =IF(OR(IFERROR(MATCH(TEXT($B$10,"yyyymmdd")&"|"&$E$10&"|7",'EVENT ASSIGNMENT'!$K$2:$K$101,0),"")="",B24=""),"",IFERROR(INDEX('CONTRACT CALC'!$G$13:$G$112,IFERROR(MATCH(TEXT($B$10,"yyyymmdd")&"|"&$E$10&"|7",'EVENT ASSIGNMENT'!$K$2:$K$101,0),""))*INDEX('CONTRACT CALC'!$F$13:$F$112,IFERROR(MATCH(TEXT($B$10,"yyyymmdd")&"|"&$E$10&"|7",'EVENT ASSIGNMENT'!$K$2:$K$101,0),"")),"")) | D24: =IF(OR(IFERROR(MATCH(TEXT($B$10,"yyyymmdd")&"|"&$E$10&"|7",'EVENT ASSIGNMENT'!$K$2:$K$101,0),"")="",B24=""),"",IFERROR(INDEX('CONTRACT CALC'!$I$13:$I$112,IFERROR(MATCH(TEXT($B$10,"yyyymmdd")&"|"&$E$10&"|7",'EVENT ASSIGNMENT'!$K$2:$K$101,0),""))*INDEX('CONTRACT CALC'!$F$13:$F$112,IFERROR(MATCH(TEXT($B$10,"yyyymmdd")&"|"&$E$10&"|7",'EVENT ASSIGNMENT'!$K$2:$K$101,0),"")),"")) | E24: =IF(D24="","",D24*'CONTRACT CALC'!$B$4) | F24: =IF(OR(IFERROR(MATCH(TEXT($B$10,"yyyymmdd")&"|"&$E$10&"|7",'EVENT ASSIGNMENT'!$K$2:$K$101,0),"")="",B24=""),"",IFERROR(INDEX('CONTRACT CALC'!$H$13:$H$112,IFERROR(MATCH(TEXT($B$10,"yyyymmdd")&"|"&$E$10&"|7",'EVENT ASSIGNMENT'!$K$2:$K$101,0),""))*INDEX('CONTRACT CALC'!$F$13:$F$112,IFERROR(MATCH(TEXT($B$10,"yyyymmdd")&"|"&$E$10&"|7",'EVENT ASSIGNMENT'!$K$2:$K$101,0),"")),"")) | G24: =IF(F24="","",F24*'CONTRACT CALC'!$B$5) | H24: =IF(B24="","",N(E24)+N(G24)) | I24: =IF(OR(IFERROR(MATCH(TEXT($B$10,"yyyymmdd")&"|"&$E$10&"|7",'EVENT ASSIGNMENT'!$K$2:$K$101,0),"")="",B24=""),"",IF(COUNTIFS('TIPS DATA'!$A$2:$A$101,$B$10,'TIPS DATA'!$C$2:$C$101,$E$10,'TIPS DATA'!$D$2:$D$101,INDEX('EVENT ASSIGNMENT'!$C$2:$C$101,IFERROR(MATCH(TEXT($B$10,"yyyymmdd")&"|"&$E$10&"|7",'EVENT ASSIGNMENT'!$K$2:$K$101,0),"")))>0,SUMIFS('TIPS DATA'!$H$2:$H$101,'TIPS DATA'!$A$2:$A$101,$B$10,'TIPS DATA'!$C$2:$C$101,$E$10,'TIPS DATA'!$D$2:$D$101,INDEX('EVENT ASSIGNMENT'!$C$2:$C$101,IFERROR(MATCH(TEXT($B$10,"yyyymmdd")&"|"&$E$10&"|7",'EVENT ASSIGNMENT'!$K$2:$K$101,0),""))),SUMIFS('TIPS DATA'!$H$2:$H$101,'TIPS DATA'!$A$2:$A$101,$B$10,'TIPS DATA'!$C$2:$C$101,$E$10,'TIPS DATA'!$E$2:$E$101,INDEX('EVENT ASSIGNMENT'!$D$2:$D$101,IFERROR(MATCH(TEXT($B$10,"yyyymmdd")&"|"&$E$10&"|7",'EVENT ASSIGNMENT'!$K$2:$K$101,0),"")))))
A25: =IFERROR(MATCH(TEXT($B$10,"yyyymmdd")&"|"&$E$10&"|8",'EVENT ASSIGNMENT'!$K$2:$K$101,0),"") | B25: =IF(IFERROR(MATCH(TEXT($B$10,"yyyymmdd")&"|"&$E$10&"|8",'EVENT ASSIGNMENT'!$K$2:$K$101,0),"")="","",IFERROR(INDEX('EVENT ASSIGNMENT'!$D$2:$D$101,IFERROR(MATCH(TEXT($B$10,"yyyymmdd")&"|"&$E$10&"|8",'EVENT ASSIGNMENT'!$K$2:$K$101,0),"")),"")) | C25: =IF(OR(IFERROR(MATCH(TEXT($B$10,"yyyymmdd")&"|"&$E$10&"|8",'EVENT ASSIGNMENT'!$K$2:$K$101,0),"")="",B25=""),"",IFERROR(INDEX('CONTRACT CALC'!$G$13:$G$112,IFERROR(MATCH(TEXT($B$10,"yyyymmdd")&"|"&$E$10&"|8",'EVENT ASSIGNMENT'!$K$2:$K$101,0),""))*INDEX('CONTRACT CALC'!$F$13:$F$112,IFERROR(MATCH(TEXT($B$10,"yyyymmdd")&"|"&$E$10&"|8",'EVENT ASSIGNMENT'!$K$2:$K$101,0),"")),"")) | D25: =IF(OR(IFERROR(MATCH(TEXT($B$10,"yyyymmdd")&"|"&$E$10&"|8",'EVENT ASSIGNMENT'!$K$2:$K$101,0),"")="",B25=""),"",IFERROR(INDEX('CONTRACT CALC'!$I$13:$I$112,IFERROR(MATCH(TEXT($B$10,"yyyymmdd")&"|"&$E$10&"|8",'EVENT ASSIGNMENT'!$K$2:$K$101,0),""))*INDEX('CONTRACT CALC'!$F$13:$F$112,IFERROR(MATCH(TEXT($B$10,"yyyymmdd")&"|"&$E$10&"|8",'EVENT ASSIGNMENT'!$K$2:$K$101,0),"")),"")) | E25: =IF(D25="","",D25*'CONTRACT CALC'!$B$4) | F25: =IF(OR(IFERROR(MATCH(TEXT($B$10,"yyyymmdd")&"|"&$E$10&"|8",'EVENT ASSIGNMENT'!$K$2:$K$101,0),"")="",B25=""),"",IFERROR(INDEX('CONTRACT CALC'!$H$13:$H$112,IFERROR(MATCH(TEXT($B$10,"yyyymmdd")&"|"&$E$10&"|8",'EVENT ASSIGNMENT'!$K$2:$K$101,0),""))*INDEX('CONTRACT CALC'!$F$13:$F$112,IFERROR(MATCH(TEXT($B$10,"yyyymmdd")&"|"&$E$10&"|8",'EVENT ASSIGNMENT'!$K$2:$K$101,0),"")),"")) | G25: =IF(F25="","",F25*'CONTRACT CALC'!$B$5) | H25: =IF(B25="","",N(E25)+N(G25)) | I25: =IF(OR(IFERROR(MATCH(TEXT($B$10,"yyyymmdd")&"|"&$E$10&"|8",'EVENT ASSIGNMENT'!$K$2:$K$101,0),"")="",B25=""),"",IF(COUNTIFS('TIPS DATA'!$A$2:$A$101,$B$10,'TIPS DATA'!$C$2:$C$101,$E$10,'TIPS DATA'!$D$2:$D$101,INDEX('EVENT ASSIGNMENT'!$C$2:$C$101,IFERROR(MATCH(TEXT($B$10,"yyyymmdd")&"|"&$E$10&"|8",'EVENT ASSIGNMENT'!$K$2:$K$101,0),"")))>0,SUMIFS('TIPS DATA'!$H$2:$H$101,'TIPS DATA'!$A$2:$A$101,$B$10,'TIPS DATA'!$C$2:$C$101,$E$10,'TIPS DATA'!$D$2:$D$101,INDEX('EVENT ASSIGNMENT'!$C$2:$C$101,IFERROR(MATCH(TEXT($B$10,"yyyymmdd")&"|"&$E$10&"|8",'EVENT ASSIGNMENT'!$K$2:$K$101,0),""))),SUMIFS('TIPS DATA'!$H$2:$H$101,'TIPS DATA'!$A$2:$A$101,$B$10,'TIPS DATA'!$C$2:$C$101,$E$10,'TIPS DATA'!$E$2:$E$101,INDEX('EVENT ASSIGNMENT'!$D$2:$D$101,IFERROR(MATCH(TEXT($B$10,"yyyymmdd")&"|"&$E$10&"|8",'EVENT ASSIGNMENT'!$K$2:$K$101,0),"")))))
A26: =IFERROR(MATCH(TEXT($B$10,"yyyymmdd")&"|"&$E$10&"|9",'EVENT ASSIGNMENT'!$K$2:$K$101,0),"") | B26: =IF(IFERROR(MATCH(TEXT($B$10,"yyyymmdd")&"|"&$E$10&"|9",'EVENT ASSIGNMENT'!$K$2:$K$101,0),"")="","",IFERROR(INDEX('EVENT ASSIGNMENT'!$D$2:$D$101,IFERROR(MATCH(TEXT($B$10,"yyyymmdd")&"|"&$E$10&"|9",'EVENT ASSIGNMENT'!$K$2:$K$101,0),"")),"")) | C26: =IF(OR(IFERROR(MATCH(TEXT($B$10,"yyyymmdd")&"|"&$E$10&"|9",'EVENT ASSIGNMENT'!$K$2:$K$101,0),"")="",B26=""),"",IFERROR(INDEX('CONTRACT CALC'!$G$13:$G$112,IFERROR(MATCH(TEXT($B$10,"yyyymmdd")&"|"&$E$10&"|9",'EVENT ASSIGNMENT'!$K$2:$K$101,0),""))*INDEX('CONTRACT CALC'!$F$13:$F$112,IFERROR(MATCH(TEXT($B$10,"yyyymmdd")&"|"&$E$10&"|9",'EVENT ASSIGNMENT'!$K$2:$K$101,0),"")),"")) | D26: =IF(OR(IFERROR(MATCH(TEXT($B$10,"yyyymmdd")&"|"&$E$10&"|9",'EVENT ASSIGNMENT'!$K$2:$K$101,0),"")="",B26=""),"",IFERROR(INDEX('CONTRACT CALC'!$I$13:$I$112,IFERROR(MATCH(TEXT($B$10,"yyyymmdd")&"|"&$E$10&"|9",'EVENT ASSIGNMENT'!$K$2:$K$101,0),""))*INDEX('CONTRACT CALC'!$F$13:$F$112,IFERROR(MATCH(TEXT($B$10,"yyyymmdd")&"|"&$E$10&"|9",'EVENT ASSIGNMENT'!$K$2:$K$101,0),"")),"")) | E26: =IF(D26="","",D26*'CONTRACT CALC'!$B$4) | F26: =IF(OR(IFERROR(MATCH(TEXT($B$10,"yyyymmdd")&"|"&$E$10&"|9",'EVENT ASSIGNMENT'!$K$2:$K$101,0),"")="",B26=""),"",IFERROR(INDEX('CONTRACT CALC'!$H$13:$H$112,IFERROR(MATCH(TEXT($B$10,"yyyymmdd")&"|"&$E$10&"|9",'EVENT ASSIGNMENT'!$K$2:$K$101,0),""))*INDEX('CONTRACT CALC'!$F$13:$F$112,IFERROR(MATCH(TEXT($B$10,"yyyymmdd")&"|"&$E$10&"|9",'EVENT ASSIGNMENT'!$K$2:$K$101,0),"")),"")) | G26: =IF(F26="","",F26*'CONTRACT CALC'!$B$5) | H26: =IF(B26="","",N(E26)+N(G26)) | I26: =IF(OR(IFERROR(MATCH(TEXT($B$10,"yyyymmdd")&"|"&$E$10&"|9",'EVENT ASSIGNMENT'!$K$2:$K$101,0),"")="",B26=""),"",IF(COUNTIFS('TIPS DATA'!$A$2:$A$101,$B$10,'TIPS DATA'!$C$2:$C$101,$E$10,'TIPS DATA'!$D$2:$D$101,INDEX('EVENT ASSIGNMENT'!$C$2:$C$101,IFERROR(MATCH(TEXT($B$10,"yyyymmdd")&"|"&$E$10&"|9",'EVENT ASSIGNMENT'!$K$2:$K$101,0),"")))>0,SUMIFS('TIPS DATA'!$H$2:$H$101,'TIPS DATA'!$A$2:$A$101,$B$10,'TIPS DATA'!$C$2:$C$101,$E$10,'TIPS DATA'!$D$2:$D$101,INDEX('EVENT ASSIGNMENT'!$C$2:$C$101,IFERROR(MATCH(TEXT($B$10,"yyyymmdd")&"|"&$E$10&"|9",'EVENT ASSIGNMENT'!$K$2:$K$101,0),""))),SUMIFS('TIPS DATA'!$H$2:$H$101,'TIPS DATA'!$A$2:$A$101,$B$10,'TIPS DATA'!$C$2:$C$101,$E$10,'TIPS DATA'!$E$2:$E$101,INDEX('EVENT ASSIGNMENT'!$D$2:$D$101,IFERROR(MATCH(TEXT($B$10,"yyyymmdd")&"|"&$E$10&"|9",'EVENT ASSIGNMENT'!$K$2:$K$101,0),"")))))
A27: =IFERROR(MATCH(TEXT($B$10,"yyyymmdd")&"|"&$E$10&"|10",'EVENT ASSIGNMENT'!$K$2:$K$101,0),"") | B27: =IF(IFERROR(MATCH(TEXT($B$10,"yyyymmdd")&"|"&$E$10&"|10",'EVENT ASSIGNMENT'!$K$2:$K$101,0),"")="","",IFERROR(INDEX('EVENT ASSIGNMENT'!$D$2:$D$101,IFERROR(MATCH(TEXT($B$10,"yyyymmdd")&"|"&$E$10&"|10",'EVENT ASSIGNMENT'!$K$2:$K$101,0),"")),"")) | C27: =IF(OR(IFERROR(MATCH(TEXT($B$10,"yyyymmdd")&"|"&$E$10&"|10",'EVENT ASSIGNMENT'!$K$2:$K$101,0),"")="",B27=""),"",IFERROR(INDEX('CONTRACT CALC'!$G$13:$G$112,IFERROR(MATCH(TEXT($B$10,"yyyymmdd")&"|"&$E$10&"|10",'EVENT ASSIGNMENT'!$K$2:$K$101,0),""))*INDEX('CONTRACT CALC'!$F$13:$F$112,IFERROR(MATCH(TEXT($B$10,"yyyymmdd")&"|"&$E$10&"|10",'EVENT ASSIGNMENT'!$K$2:$K$101,0),"")),"")) | D27: =IF(OR(IFERROR(MATCH(TEXT($B$10,"yyyymmdd")&"|"&$E$10&"|10",'EVENT ASSIGNMENT'!$K$2:$K$101,0),"")="",B27=""),"",IFERROR(INDEX('CONTRACT CALC'!$I$13:$I$112,IFERROR(MATCH(TEXT($B$10,"yyyymmdd")&"|"&$E$10&"|10",'EVENT ASSIGNMENT'!$K$2:$K$101,0),""))*INDEX('CONTRACT CALC'!$F$13:$F$112,IFERROR(MATCH(TEXT($B$10,"yyyymmdd")&"|"&$E$10&"|10",'EVENT ASSIGNMENT'!$K$2:$K$101,0),"")),"")) | E27: =IF(D27="","",D27*'CONTRACT CALC'!$B$4) | F27: =IF(OR(IFERROR(MATCH(TEXT($B$10,"yyyymmdd")&"|"&$E$10&"|10",'EVENT ASSIGNMENT'!$K$2:$K$101,0),"")="",B27=""),"",IFERROR(INDEX('CONTRACT CALC'!$H$13:$H$112,IFERROR(MATCH(TEXT($B$10,"yyyymmdd")&"|"&$E$10&"|10",'EVENT ASSIGNMENT'!$K$2:$K$101,0),""))*INDEX('CONTRACT CALC'!$F$13:$F$112,IFERROR(MATCH(TEXT($B$10,"yyyymmdd")&"|"&$E$10&"|10",'EVENT ASSIGNMENT'!$K$2:$K$101,0),"")),"")) | G27: =IF(F27="","",F27*'CONTRACT CALC'!$B$5) | H27: =IF(B27="","",N(E27)+N(G27)) | I27: =IF(OR(IFERROR(MATCH(TEXT($B$10,"yyyymmdd")&"|"&$E$10&"|10",'EVENT ASSIGNMENT'!$K$2:$K$101,0),"")="",B27=""),"",IF(COUNTIFS('TIPS DATA'!$A$2:$A$101,$B$10,'TIPS DATA'!$C$2:$C$101,$E$10,'TIPS DATA'!$D$2:$D$101,INDEX('EVENT ASSIGNMENT'!$C$2:$C$101,IFERROR(MATCH(TEXT($B$10,"yyyymmdd")&"|"&$E$10&"|10",'EVENT ASSIGNMENT'!$K$2:$K$101,0),"")))>0,SUMIFS('TIPS DATA'!$H$2:$H$101,'TIPS DATA'!$A$2:$A$101,$B$10,'TIPS DATA'!$C$2:$C$101,$E$10,'TIPS DATA'!$D$2:$D$101,INDEX('EVENT ASSIGNMENT'!$C$2:$C$101,IFERROR(MATCH(TEXT($B$10,"yyyymmdd")&"|"&$E$10&"|10",'EVENT ASSIGNMENT'!$K$2:$K$101,0),""))),SUMIFS('TIPS DATA'!$H$2:$H$101,'TIPS DATA'!$A$2:$A$101,$B$10,'TIPS DATA'!$C$2:$C$101,$E$10,'TIPS DATA'!$E$2:$E$101,INDEX('EVENT ASSIGNMENT'!$D$2:$D$101,IFERROR(MATCH(TEXT($B$10,"yyyymmdd")&"|"&$E$10&"|10",'EVENT ASSIGNMENT'!$K$2:$K$101,0),"")))))
A28: =IFERROR(MATCH(TEXT($B$10,"yyyymmdd")&"|"&$E$10&"|11",'EVENT ASSIGNMENT'!$K$2:$K$101,0),"") | B28: =IF(IFERROR(MATCH(TEXT($B$10,"yyyymmdd")&"|"&$E$10&"|11",'EVENT ASSIGNMENT'!$K$2:$K$101,0),"")="","",IFERROR(INDEX('EVENT ASSIGNMENT'!$D$2:$D$101,IFERROR(MATCH(TEXT($B$10,"yyyymmdd")&"|"&$E$10&"|11",'EVENT ASSIGNMENT'!$K$2:$K$101,0),"")),"")) | C28: =IF(OR(IFERROR(MATCH(TEXT($B$10,"yyyymmdd")&"|"&$E$10&"|11",'EVENT ASSIGNMENT'!$K$2:$K$101,0),"")="",B28=""),"",IFERROR(INDEX('CONTRACT CALC'!$G$13:$G$112,IFERROR(MATCH(TEXT($B$10,"yyyymmdd")&"|"&$E$10&"|11",'EVENT ASSIGNMENT'!$K$2:$K$101,0),""))*INDEX('CONTRACT CALC'!$F$13:$F$112,IFERROR(MATCH(TEXT($B$10,"yyyymmdd")&"|"&$E$10&"|11",'EVENT ASSIGNMENT'!$K$2:$K$101,0),"")),"")) | D28: =IF(OR(IFERROR(MATCH(TEXT($B$10,"yyyymmdd")&"|"&$E$10&"|11",'EVENT ASSIGNMENT'!$K$2:$K$101,0),"")="",B28=""),"",IFERROR(INDEX('CONTRACT CALC'!$I$13:$I$112,IFERROR(MATCH(TEXT($B$10,"yyyymmdd")&"|"&$E$10&"|11",'EVENT ASSIGNMENT'!$K$2:$K$101,0),""))*INDEX('CONTRACT CALC'!$F$13:$F$112,IFERROR(MATCH(TEXT($B$10,"yyyymmdd")&"|"&$E$10&"|11",'EVENT ASSIGNMENT'!$K$2:$K$101,0),"")),"")) | E28: =IF(D28="","",D28*'CONTRACT CALC'!$B$4) | F28: =IF(OR(IFERROR(MATCH(TEXT($B$10,"yyyymmdd")&"|"&$E$10&"|11",'EVENT ASSIGNMENT'!$K$2:$K$101,0),"")="",B28=""),"",IFERROR(INDEX('CONTRACT CALC'!$H$13:$H$112,IFERROR(MATCH(TEXT($B$10,"yyyymmdd")&"|"&$E$10&"|11",'EVENT ASSIGNMENT'!$K$2:$K$101,0),""))*INDEX('CONTRACT CALC'!$F$13:$F$112,IFERROR(MATCH(TEXT($B$10,"yyyymmdd")&"|"&$E$10&"|11",'EVENT ASSIGNMENT'!$K$2:$K$101,0),"")),"")) | G28: =IF(F28="","",F28*'CONTRACT CALC'!$B$5) | H28: =IF(B28="","",N(E28)+N(G28)) | I28: =IF(OR(IFERROR(MATCH(TEXT($B$10,"yyyymmdd")&"|"&$E$10&"|11",'EVENT ASSIGNMENT'!$K$2:$K$101,0),"")="",B28=""),"",IF(COUNTIFS('TIPS DATA'!$A$2:$A$101,$B$10,'TIPS DATA'!$C$2:$C$101,$E$10,'TIPS DATA'!$D$2:$D$101,INDEX('EVENT ASSIGNMENT'!$C$2:$C$101,IFERROR(MATCH(TEXT($B$10,"yyyymmdd")&"|"&$E$10&"|11",'EVENT ASSIGNMENT'!$K$2:$K$101,0),"")))>0,SUMIFS('TIPS DATA'!$H$2:$H$101,'TIPS DATA'!$A$2:$A$101,$B$10,'TIPS DATA'!$C$2:$C$101,$E$10,'TIPS DATA'!$D$2:$D$101,INDEX('EVENT ASSIGNMENT'!$C$2:$C$101,IFERROR(MATCH(TEXT($B$10,"yyyymmdd")&"|"&$E$10&"|11",'EVENT ASSIGNMENT'!$K$2:$K$101,0),""))),SUMIFS('TIPS DATA'!$H$2:$H$101,'TIPS DATA'!$A$2:$A$101,$B$10,'TIPS DATA'!$C$2:$C$101,$E$10,'TIPS DATA'!$E$2:$E$101,INDEX('EVENT ASSIGNMENT'!$D$2:$D$101,IFERROR(MATCH(TEXT($B$10,"yyyymmdd")&"|"&$E$10&"|11",'EVENT ASSIGNMENT'!$K$2:$K$101,0),"")))))
A29: =IFERROR(MATCH(TEXT($B$10,"yyyymmdd")&"|"&$E$10&"|12",'EVENT ASSIGNMENT'!$K$2:$K$101,0),"") | B29: =IF(IFERROR(MATCH(TEXT($B$10,"yyyymmdd")&"|"&$E$10&"|12",'EVENT ASSIGNMENT'!$K$2:$K$101,0),"")="","",IFERROR(INDEX('EVENT ASSIGNMENT'!$D$2:$D$101,IFERROR(MATCH(TEXT($B$10,"yyyymmdd")&"|"&$E$10&"|12",'EVENT ASSIGNMENT'!$K$2:$K$101,0),"")),"")) | C29: =IF(OR(IFERROR(MATCH(TEXT($B$10,"yyyymmdd")&"|"&$E$10&"|12",'EVENT ASSIGNMENT'!$K$2:$K$101,0),"")="",B29=""),"",IFERROR(INDEX('CONTRACT CALC'!$G$13:$G$112,IFERROR(MATCH(TEXT($B$10,"yyyymmdd")&"|"&$E$10&"|12",'EVENT ASSIGNMENT'!$K$2:$K$101,0),""))*INDEX('CONTRACT CALC'!$F$13:$F$112,IFERROR(MATCH(TEXT($B$10,"yyyymmdd")&"|"&$E$10&"|12",'EVENT ASSIGNMENT'!$K$2:$K$101,0),"")),"")) | D29: =IF(OR(IFERROR(MATCH(TEXT($B$10,"yyyymmdd")&"|"&$E$10&"|12",'EVENT ASSIGNMENT'!$K$2:$K$101,0),"")="",B29=""),"",IFERROR(INDEX('CONTRACT CALC'!$I$13:$I$112,IFERROR(MATCH(TEXT($B$10,"yyyymmdd")&"|"&$E$10&"|12",'EVENT ASSIGNMENT'!$K$2:$K$101,0),""))*INDEX('CONTRACT CALC'!$F$13:$F$112,IFERROR(MATCH(TEXT($B$10,"yyyymmdd")&"|"&$E$10&"|12",'EVENT ASSIGNMENT'!$K$2:$K$101,0),"")),"")) | E29: =IF(D29="","",D29*'CONTRACT CALC'!$B$4) | F29: =IF(OR(IFERROR(MATCH(TEXT($B$10,"yyyymmdd")&"|"&$E$10&"|12",'EVENT ASSIGNMENT'!$K$2:$K$101,0),"")="",B29=""),"",IFERROR(INDEX('CONTRACT CALC'!$H$13:$H$112,IFERROR(MATCH(TEXT($B$10,"yyyymmdd")&"|"&$E$10&"|12",'EVENT ASSIGNMENT'!$K$2:$K$101,0),""))*INDEX('CONTRACT CALC'!$F$13:$F$112,IFERROR(MATCH(TEXT($B$10,"yyyymmdd")&"|"&$E$10&"|12",'EVENT ASSIGNMENT'!$K$2:$K$101,0),"")),"")) | G29: =IF(F29="","",F29*'CONTRACT CALC'!$B$5) | H29: =IF(B29="","",N(E29)+N(G29)) | I29: =IF(OR(IFERROR(MATCH(TEXT($B$10,"yyyymmdd")&"|"&$E$10&"|12",'EVENT ASSIGNMENT'!$K$2:$K$101,0),"")="",B29=""),"",IF(COUNTIFS('TIPS DATA'!$A$2:$A$101,$B$10,'TIPS DATA'!$C$2:$C$101,$E$10,'TIPS DATA'!$D$2:$D$101,INDEX('EVENT ASSIGNMENT'!$C$2:$C$101,IFERROR(MATCH(TEXT($B$10,"yyyymmdd")&"|"&$E$10&"|12",'EVENT ASSIGNMENT'!$K$2:$K$101,0),"")))>0,SUMIFS('TIPS DATA'!$H$2:$H$101,'TIPS DATA'!$A$2:$A$101,$B$10,'TIPS DATA'!$C$2:$C$101,$E$10,'TIPS DATA'!$D$2:$D$101,INDEX('EVENT ASSIGNMENT'!$C$2:$C$101,IFERROR(MATCH(TEXT($B$10,"yyyymmdd")&"|"&$E$10&"|12",'EVENT ASSIGNMENT'!$K$2:$K$101,0),""))),SUMIFS('TIPS DATA'!$H$2:$H$101,'TIPS DATA'!$A$2:$A$101,$B$10,'TIPS DATA'!$C$2:$C$101,$E$10,'TIPS DATA'!$E$2:$E$101,INDEX('EVENT ASSIGNMENT'!$D$2:$D$101,IFERROR(MATCH(TEXT($B$10,"yyyymmdd")&"|"&$E$10&"|12",'EVENT ASSIGNMENT'!$K$2:$K$101,0),"")))))
A30: =IFERROR(MATCH(TEXT($B$10,"yyyymmdd")&"|"&$E$10&"|23",'EVENT ASSIGNMENT'!$K$2:$K$101,0),"") | B30: =IF(IFERROR(MATCH(TEXT($B$10,"yyyymmdd")&"|"&$E$10&"|23",'EVENT ASSIGNMENT'!$K$2:$K$101,0),"")="","",IFERROR(INDEX('EVENT ASSIGNMENT'!$D$2:$D$101,IFERROR(MATCH(TEXT($B$10,"yyyymmdd")&"|"&$E$10&"|23",'EVENT ASSIGNMENT'!$K$2:$K$101,0),"")),"")) | C30: =IF(OR(IFERROR(MATCH(TEXT($B$10,"yyyymmdd")&"|"&$E$10&"|23",'EVENT ASSIGNMENT'!$K$2:$K$101,0),"")="",B30=""),"",IFERROR(INDEX('CONTRACT CALC'!$G$13:$G$112,IFERROR(MATCH(TEXT($B$10,"yyyymmdd")&"|"&$E$10&"|23",'EVENT ASSIGNMENT'!$K$2:$K$101,0),""))*INDEX('CONTRACT CALC'!$F$13:$F$112,IFERROR(MATCH(TEXT($B$10,"yyyymmdd")&"|"&$E$10&"|23",'EVENT ASSIGNMENT'!$K$2:$K$101,0),"")),"")) | D30: =IF(OR(IFERROR(MATCH(TEXT($B$10,"yyyymmdd")&"|"&$E$10&"|23",'EVENT ASSIGNMENT'!$K$2:$K$101,0),"")="",B30=""),"",IFERROR(INDEX('CONTRACT CALC'!$I$13:$I$112,IFERROR(MATCH(TEXT($B$10,"yyyymmdd")&"|"&$E$10&"|23",'EVENT ASSIGNMENT'!$K$2:$K$101,0),""))*INDEX('CONTRACT CALC'!$F$13:$F$112,IFERROR(MATCH(TEXT($B$10,"yyyymmdd")&"|"&$E$10&"|23",'EVENT ASSIGNMENT'!$K$2:$K$101,0),"")),"")) | E30: =IF(D30="","",D30*'CONTRACT CALC'!$B$4) | F30: =IF(OR(IFERROR(MATCH(TEXT($B$10,"yyyymmdd")&"|"&$E$10&"|23",'EVENT ASSIGNMENT'!$K$2:$K$101,0),"")="",B30=""),"",IFERROR(INDEX('CONTRACT CALC'!$H$13:$H$112,IFERROR(MATCH(TEXT($B$10,"yyyymmdd")&"|"&$E$10&"|23",'EVENT ASSIGNMENT'!$K$2:$K$101,0),""))*INDEX('CONTRACT CALC'!$F$13:$F$112,IFERROR(MATCH(TEXT($B$10,"yyyymmdd")&"|"&$E$10&"|23",'EVENT ASSIGNMENT'!$K$2:$K$101,0),"")),"")) | G30: =IF(F30="","",F30*'CONTRACT CALC'!$B$5) | H30: =IF(B30="","",N(E30)+N(G30)) | I30: =IF(OR(IFERROR(MATCH(TEXT($B$10,"yyyymmdd")&"|"&$E$10&"|23",'EVENT ASSIGNMENT'!$K$2:$K$101,0),"")="",B30=""),"",IF(COUNTIFS('TIPS DATA'!$A$2:$A$101,$B$10,'TIPS DATA'!$C$2:$C$101,$E$10,'TIPS DATA'!$D$2:$D$101,INDEX('EVENT ASSIGNMENT'!$C$2:$C$101,IFERROR(MATCH(TEXT($B$10,"yyyymmdd")&"|"&$E$10&"|23",'EVENT ASSIGNMENT'!$K$2:$K$101,0),"")))>0,SUMIFS('TIPS DATA'!$H$2:$H$101,'TIPS DATA'!$A$2:$A$101,$B$10,'TIPS DATA'!$C$2:$C$101,$E$10,'TIPS DATA'!$D$2:$D$101,INDEX('EVENT ASSIGNMENT'!$C$2:$C$101,IFERROR(MATCH(TEXT($B$10,"yyyymmdd")&"|"&$E$10&"|23",'EVENT ASSIGNMENT'!$K$2:$K$101,0),""))),SUMIFS('TIPS DATA'!$H$2:$H$101,'TIPS DATA'!$A$2:$A$101,$B$10,'TIPS DATA'!$C$2:$C$101,$E$10,'TIPS DATA'!$E$2:$E$101,INDEX('EVENT ASSIGNMENT'!$D$2:$D$101,IFERROR(MATCH(TEXT($B$10,"yyyymmdd")&"|"&$E$10&"|23",'EVENT ASSIGNMENT'!$K$2:$K$101,0),"")))))
A31: =IFERROR(MATCH(TEXT($B$10,"yyyymmdd")&"|"&$E$10&"|24",'EVENT ASSIGNMENT'!$K$2:$K$101,0),"") | B31: =IF(IFERROR(MATCH(TEXT($B$10,"yyyymmdd")&"|"&$E$10&"|24",'EVENT ASSIGNMENT'!$K$2:$K$101,0),"")="","",IFERROR(INDEX('EVENT ASSIGNMENT'!$D$2:$D$101,IFERROR(MATCH(TEXT($B$10,"yyyymmdd")&"|"&$E$10&"|24",'EVENT ASSIGNMENT'!$K$2:$K$101,0),"")),"")) | C31: =IF(OR(IFERROR(MATCH(TEXT($B$10,"yyyymmdd")&"|"&$E$10&"|24",'EVENT ASSIGNMENT'!$K$2:$K$101,0),"")="",B31=""),"",IFERROR(INDEX('CONTRACT CALC'!$G$13:$G$112,IFERROR(MATCH(TEXT($B$10,"yyyymmdd")&"|"&$E$10&"|24",'EVENT ASSIGNMENT'!$K$2:$K$101,0),""))*INDEX('CONTRACT CALC'!$F$13:$F$112,IFERROR(MATCH(TEXT($B$10,"yyyymmdd")&"|"&$E$10&"|24",'EVENT ASSIGNMENT'!$K$2:$K$101,0),"")),"")) | D31: =IF(OR(IFERROR(MATCH(TEXT($B$10,"yyyymmdd")&"|"&$E$10&"|24",'EVENT ASSIGNMENT'!$K$2:$K$101,0),"")="",B31=""),"",IFERROR(INDEX('CONTRACT CALC'!$I$13:$I$112,IFERROR(MATCH(TEXT($B$10,"yyyymmdd")&"|"&$E$10&"|24",'EVENT ASSIGNMENT'!$K$2:$K$101,0),""))*INDEX('CONTRACT CALC'!$F$13:$F$112,IFERROR(MATCH(TEXT($B$10,"yyyymmdd")&"|"&$E$10&"|24",'EVENT ASSIGNMENT'!$K$2:$K$101,0),"")),"")) | E31: =IF(D31="","",D31*'CONTRACT CALC'!$B$4) | F31: =IF(OR(IFERROR(MATCH(TEXT($B$10,"yyyymmdd")&"|"&$E$10&"|24",'EVENT ASSIGNMENT'!$K$2:$K$101,0),"")="",B31=""),"",IFERROR(INDEX('CONTRACT CALC'!$H$13:$H$112,IFERROR(MATCH(TEXT($B$10,"yyyymmdd")&"|"&$E$10&"|24",'EVENT ASSIGNMENT'!$K$2:$K$101,0),""))*INDEX('CONTRACT CALC'!$F$13:$F$112,IFERROR(MATCH(TEXT($B$10,"yyyymmdd")&"|"&$E$10&"|24",'EVENT ASSIGNMENT'!$K$2:$K$101,0),"")),"")) | G31: =IF(F31="","",F31*'CONTRACT CALC'!$B$5) | H31: =IF(B31="","",N(E31)+N(G31)) | I31: =IF(OR(IFERROR(MATCH(TEXT($B$10,"yyyymmdd")&"|"&$E$10&"|24",'EVENT ASSIGNMENT'!$K$2:$K$101,0),"")="",B31=""),"",IF(COUNTIFS('TIPS DATA'!$A$2:$A$101,$B$10,'TIPS DATA'!$C$2:$C$101,$E$10,'TIPS DATA'!$D$2:$D$101,INDEX('EVENT ASSIGNMENT'!$C$2:$C$101,IFERROR(MATCH(TEXT($B$10,"yyyymmdd")&"|"&$E$10&"|24",'EVENT ASSIGNMENT'!$K$2:$K$101,0),"")))>0,SUMIFS('TIPS DATA'!$H$2:$H$101,'TIPS DATA'!$A$2:$A$101,$B$10,'TIPS DATA'!$C$2:$C$101,$E$10,'TIPS DATA'!$D$2:$D$101,INDEX('EVENT ASSIGNMENT'!$C$2:$C$101,IFERROR(MATCH(TEXT($B$10,"yyyymmdd")&"|"&$E$10&"|24",'EVENT ASSIGNMENT'!$K$2:$K$101,0),""))),SUMIFS('TIPS DATA'!$H$2:$H$101,'TIPS DATA'!$A$2:$A$101,$B$10,'TIPS DATA'!$C$2:$C$101,$E$10,'TIPS DATA'!$E$2:$E$101,INDEX('EVENT ASSIGNMENT'!$D$2:$D$101,IFERROR(MATCH(TEXT($B$10,"yyyymmdd")&"|"&$E$10&"|24",'EVENT ASSIGNMENT'!$K$2:$K$101,0),"")))))
A32: =IFERROR(MATCH(TEXT($B$10,"yyyymmdd")&"|"&$E$10&"|25",'EVENT ASSIGNMENT'!$K$2:$K$101,0),"") | B32: =IF(IFERROR(MATCH(TEXT($B$10,"yyyymmdd")&"|"&$E$10&"|25",'EVENT ASSIGNMENT'!$K$2:$K$101,0),"")="","",IFERROR(INDEX('EVENT ASSIGNMENT'!$D$2:$D$101,IFERROR(MATCH(TEXT($B$10,"yyyymmdd")&"|"&$E$10&"|25",'EVENT ASSIGNMENT'!$K$2:$K$101,0),"")),"")) | C32: =IF(OR(IFERROR(MATCH(TEXT($B$10,"yyyymmdd")&"|"&$E$10&"|25",'EVENT ASSIGNMENT'!$K$2:$K$101,0),"")="",B32=""),"",IFERROR(INDEX('CONTRACT CALC'!$G$13:$G$112,IFERROR(MATCH(TEXT($B$10,"yyyymmdd")&"|"&$E$10&"|25",'EVENT ASSIGNMENT'!$K$2:$K$101,0),""))*INDEX('CONTRACT CALC'!$F$13:$F$112,IFERROR(MATCH(TEXT($B$10,"yyyymmdd")&"|"&$E$10&"|25",'EVENT ASSIGNMENT'!$K$2:$K$101,0),"")),"")) | D32: =IF(OR(IFERROR(MATCH(TEXT($B$10,"yyyymmdd")&"|"&$E$10&"|25",'EVENT ASSIGNMENT'!$K$2:$K$101,0),"")="",B32=""),"",IFERROR(INDEX('CONTRACT CALC'!$I$13:$I$112,IFERROR(MATCH(TEXT($B$10,"yyyymmdd")&"|"&$E$10&"|25",'EVENT ASSIGNMENT'!$K$2:$K$101,0),""))*INDEX('CONTRACT CALC'!$F$13:$F$112,IFERROR(MATCH(TEXT($B$10,"yyyymmdd")&"|"&$E$10&"|25",'EVENT ASSIGNMENT'!$K$2:$K$101,0),"")),"")) | E32: =IF(D32="","",D32*'CONTRACT CALC'!$B$4) | F32: =IF(OR(IFERROR(MATCH(TEXT($B$10,"yyyymmdd")&"|"&$E$10&"|25",'EVENT ASSIGNMENT'!$K$2:$K$101,0),"")="",B32=""),"",IFERROR(INDEX('CONTRACT CALC'!$H$13:$H$112,IFERROR(MATCH(TEXT($B$10,"yyyymmdd")&"|"&$E$10&"|25",'EVENT ASSIGNMENT'!$K$2:$K$101,0),""))*INDEX('CONTRACT CALC'!$F$13:$F$112,IFERROR(MATCH(TEXT($B$10,"yyyymmdd")&"|"&$E$10&"|25",'EVENT ASSIGNMENT'!$K$2:$K$101,0),"")),"")) | G32: =IF(F32="","",F32*'CONTRACT CALC'!$B$5) | H32: =IF(B32="","",N(E32)+N(G32)) | I32: =IF(OR(IFERROR(MATCH(TEXT($B$10,"yyyymmdd")&"|"&$E$10&"|25",'EVENT ASSIGNMENT'!$K$2:$K$101,0),"")="",B32=""),"",IF(COUNTIFS('TIPS DATA'!$A$2:$A$101,$B$10,'TIPS DATA'!$C$2:$C$101,$E$10,'TIPS DATA'!$D$2:$D$101,INDEX('EVENT ASSIGNMENT'!$C$2:$C$101,IFERROR(MATCH(TEXT($B$10,"yyyymmdd")&"|"&$E$10&"|25",'EVENT ASSIGNMENT'!$K$2:$K$101,0),"")))>0,SUMIFS('TIPS DATA'!$H$2:$H$101,'TIPS DATA'!$A$2:$A$101,$B$10,'TIPS DATA'!$C$2:$C$101,$E$10,'TIPS DATA'!$D$2:$D$101,INDEX('EVENT ASSIGNMENT'!$C$2:$C$101,IFERROR(MATCH(TEXT($B$10,"yyyymmdd")&"|"&$E$10&"|25",'EVENT ASSIGNMENT'!$K$2:$K$101,0),""))),SUMIFS('TIPS DATA'!$H$2:$H$101,'TIPS DATA'!$A$2:$A$101,$B$10,'TIPS DATA'!$C$2:$C$101,$E$10,'TIPS DATA'!$E$2:$E$101,INDEX('EVENT ASSIGNMENT'!$D$2:$D$101,IFERROR(MATCH(TEXT($B$10,"yyyymmdd")&"|"&$E$10&"|25",'EVENT ASSIGNMENT'!$K$2:$K$101,0),"")))))
B33: TOTAL | C33: =SUM(C18:C32) -> 48024 | D33: =SUM(D18:D32) -> 32245 | E33: =SUM(E18:E32) -> 3224.5 | F33: =SUM(F18:F32) -> 15779 | G33: =SUM(G18:G32) -> 1262.32 | H33: =SUM(H18:H32) -> 4486.82 | I33: =SUM(I18:I32) -> 3421.74
B34: Location rows are filtered from EVENT ASSIGNMENT / CONTRACT CALC by Event Date + Payee. Location Total = Contractual Donation + Gratuities; commission rates are shown explicitly by sales category above.
G35: SUPPLEMENTAL PAYOUT:
B36: SETTLEMENT NOTES | G36: Sales Incentive | I36: =IFERROR(SUMIFS('SUPPLEMENTAL DATA'!$C$2:$C$101,'SUPPLEMENTAL DATA'!$A$2:$A$101,$B$10,'SUPPLEMENTAL DATA'!$B$2:$B$101,$E$10),0) -> 0
G37: Culinary - Cook Fee | I37: =IFERROR(SUMIFS('SUPPLEMENTAL DATA'!$D$2:$D$101,'SUPPLEMENTAL DATA'!$A$2:$A$101,$B$10,'SUPPLEMENTAL DATA'!$B$2:$B$101,$E$10),0) -> 0
G38: Minimum Donation | I38: =IFERROR(SUMIFS('SUPPLEMENTAL DATA'!$E$2:$E$101,'SUPPLEMENTAL DATA'!$A$2:$A$101,$B$10,'SUPPLEMENTAL DATA'!$B$2:$B$101,$E$10),0) -> 0
G39: Bonus (Other) | I39: =IFERROR(SUMIFS('SUPPLEMENTAL DATA'!$F$2:$F$101,'SUPPLEMENTAL DATA'!$A$2:$A$101,$B$10,'SUPPLEMENTAL DATA'!$B$2:$B$101,$E$10),0) -> 0
G40: Deductible POS Shortages | I40: =IFERROR(SUMIFS('SUPPLEMENTAL DATA'!$G$2:$G$101,'SUPPLEMENTAL DATA'!$A$2:$A$101,$B$10,'SUPPLEMENTAL DATA'!$B$2:$B$101,$E$10),0) -> 0
G41: Uniform / Staffing / Cleaning Fees | I41: =IFERROR(SUMIFS('SUPPLEMENTAL DATA'!$H$2:$H$101,'SUPPLEMENTAL DATA'!$A$2:$A$101,$B$10,'SUPPLEMENTAL DATA'!$B$2:$B$101,$E$10),0) -> 0
I42: =SUM(I36:I41) -> 0
B45: INTERNAL AUTHORIZATION CHECK REQUEST | E45: INTERNAL - ACCOUNTING GL ENTRY - SUMMARY
B46: Abigail Tenorio | C46: =TODAY() -> 46283 | E46: Group Commission | F46: 241 | 36127 | GL:611225 | G46: =H33 -> 4486.82
B47: Concessions Manager | E47: Gratuities | F47: 241 | 36127 | GL:212113 | G47: =I33 -> 3421.74
...

Sheet MSR RAW
A1: | Price Level - CATEGORIES - MSR Data Export | R1: University of New Mexico (2LEVY@UNM)
U2: 7.6250%
A3: Event:UNM FOOTBALL GAME 1 - 9/5 (252) Start Date:09/05/26 5:00:00 PM End Date:09/05/26 11:55:51 PM Discount Source:Default Price Level Detail Level:Summary
A4: Product | F4: Tax | W4: gap
A5: Code | D5: Name | E5: Standard Price | F5: Inclusive | H5: Exclusive | J5: SC | M5: Discount | O5: Quantity | Q5: Gross Amt | T5: Net
A6: Department: 36127 - CONCESSIONS
B7: Location: FB 100 - TRAILER N CONCOURSE
C8: Total: | F8: 0.00 | G8: 0.11 | I8: 0 | L8: 0.00 | N8: 226.00 | P8: 0.11 | S8: 0.00
C9: 312115 - N/A BEVERAGE SALES - TAXABLE Total: | F9: 0.00 | G9: 165.23 | I9: 0 | L9: 328.00 | N9: 380.00 | P9: 2,332.23 | S9: 2,167.00
C10: 313000 - FOOD SALES - TAXABLE Total: | F10: 0.00 | G10: 244.84 | I10: 0 | L10: 0.00 | N10: 234.00 | P10: 3,455.84 | S10: 3,211.00
C11: 313004 - LIQUOR SALES - TAXABLE Total: | F11: 0.00 | G11: 25.62 | I11: 0 | L11: 0.00 | N11: 21.00 | P11: 361.62 | S11: 336.00
C12: 313082 - BEER PACKAGED SALES Total: | F12: 0.00 | G12: 74.76 | I12: 0 | L12: -10.00 | N12: 74.00 | P12: 1,055.26 | S12: 980.50
B13: FB 100 - TRAILER N CONCOURSE Total: | F13: 0.00 | G13: 510.57 | I13: 0 | L13: 318.00 | N13: 935.00 | P13: 7,205.07 | S13: 6,694.50
B14: Location: FB 100B - MBP TRAILER N CONCOURSE
C15: Total: | F15: 0.00 | G15: 0.18 | I15: 0 | L15: 0.00 | N15: 242.00 | P15: 0.18 | S15: 0.00
C16: 312115 - N/A BEVERAGE SALES - TAXABLE Total: | F16: 0.00 | G16: 52.46 | I16: 0 | L16: 344.00 | N16: 172.00 | P16: 740.46 | S16: 688.00
C17: 313004 - LIQUOR SALES - TAXABLE Total: | F17: 0.00 | G17: 173.24 | I17: 0 | L17: 0.00 | N17: 142.00 | P17: 2,445.24 | S17: 2,272.00
C18: 313082 - BEER PACKAGED SALES Total: | F18: 0.00 | G18: 355.78 | I18: 0 | L18: 0.00 | N18: 365.00 | P18: 5,021.78 | S18: 4,666.00
B19: FB 100B - MBP TRAILER N CONCOURSE Total: | F19: 0.00 | G19: 581.66 | I19: 0 | L19: 344.00 | N19: 921.00 | P19: 8,207.66 | S19: 7,626.00
B20: Location: FB 101 - STADIUM SIPS SHACK SW
C21: Total: | F21: 0.00 | G21: 0.35 | I21: 0 | L21: 0.00 | N21: 319.00 | P21: 0.35 | S21: 0.00
C22: 312115 - N/A BEVERAGE SALES - TAXABLE Total: | F22: 0.00 | G22: 122.61 | I22: 0 | L22: 558.00 | N22: 279.00 | P22: 1,730.61 | S22: 1,608.00
C23: 313000 - FOOD SALES - TAXABLE Total: | F23: 0.00 | G23: 34.92 | I23: 0 | L23: 1.00 | N23: 129.00 | P23: 492.92 | S23: 458.00
C24: 313004 - LIQUOR SALES - TAXABLE Total: | F24: 0.00 | G24: 134.20 | I24: 0 | L24: 0.00 | N24: 110.00 | P24: 1,894.20 | S24: 1,760.00
C25: 313082 - BEER PACKAGED SALES Total: | F25: 0.00 | G25: 353.84 | I25: 0 | L25: 0.00 | N25: 351.00 | P25: 4,994.34 | S25: 4,640.50
C26: FF-312114 - N/A BEV SALE DISC. FAN FRIENDLY (CC36636) Total: | F26: 0.00 | G26: 58.26 | I26: 0 | L26: 0.00 | N26: 191.00 | P26: 822.26 | S26: 764.00
C27: FF-313076 - FOOD SALES DISC. FAN FRIENDLY (CC36636) Total: | F27: 0.00 | G27: 31.42 | I27: 0 | L27: 0.00 | N27: 103.00 | P27: 443.42 | S27: 412.00
B28: FB 101 - STADIUM SIPS SHACK SW Total: | F28: 0.00 | G28: 735.59 | I28: 0 | L28: 559.00 | N28: 1,482.00 | P28: 10,378.09 | S28: 9,642.50
B29: Location: FB 102 - TOWER SOUTH
C30: Total: | F30: 0.00 | G30: 0.30 | I30: 0 | L30: 0.00 | N30: 286.00 | P30: 0.30 | S30: 0.00
C31: 312115 - N/A BEVERAGE SALES - TAXABLE Total: | F31: 0.00 | G31: 97.75 | I31: 0 | L31: 308.00 | N31: 180.00 | P31: 1,379.75 | S31: 1,282.00
C32: 313000 - FOOD SALES - TAXABLE Total: | F32: 0.00 | G32: 155.70 | I32: 0 | L32: 57.00 | N32: 379.00 | P32: 2,197.70 | S32: 2,042.00
C33: 313004 - LIQUOR SALES - TAXABLE Total: | F33: 0.00 | G33: 37.82 | I33: 0 | L33: 0.00 | N33: 31.00 | P33: 533.82 | S33: 496.00
C34: 313082 - BEER PACKAGED SALES Total: | F34: 0.00 | G34: 141.33 | I34: 0 | L34: 0.00 | N34: 143.00 | P34: 1,994.83 | S34: 1,853.50
C35: FF-312114 - N/A BEV SALE DISC. FAN FRIENDLY (CC36636) Total: | F35: 0.00 | G35: 66.49 | I35: 0 | L35: 0.00 | N35: 218.00 | P35: 938.49 | S35: 872.00
C36: FF-313076 - FOOD SALES DISC. FAN FRIENDLY (CC36636) Total: | F36: 0.00 | G36: 56.12 | I36: 0 | L36: 368.00 | N36: 184.00 | P36: 792.12 | S36: 736.00
B37: FB 102 - TOWER SOUTH Total: | F37: 0.00 | G37: 555.51 | I37: 0 | L37: 733.00 | N37: 1,421.00 | P37: 7,837.01 | S37: 7,281.50
B38: Location: FB 103 - TOWER NORTH
C39: Total: | F39: 0.00 | G39: 0.29 | I39: 0 | L39: 0.00 | N39: 338.00 | P39: 0.29 | S39: 0.00
C40: 312115 - N/A BEVERAGE SALES - TAXABLE Total: | F40: 0.00 | G40: 92.11 | I40: 0 | L40: 288.00 | N40: 168.00 | P40: 1,300.11 | S40: 1,208.00
...

Sheet CATEGORY MAP
A1: MyVenue Product Code | B1: Contract Class | C1: Description / Rule
A2: 312115 | B2: FOOD/NON-ALC | C2: N/A BEVERAGE SALES - TAXABLE
A3: 313000 | B3: FOOD/NON-ALC | C3: FOOD SALES - TAXABLE
A4: 313004 | B4: ALCOHOL | C4: LIQUOR SALES - TAXABLE
A5: 313082 | B5: ALCOHOL | C5: BEER PACKAGED SALES
A6: 313096 | B6: ALCOHOL | C6: WINE SALES - TAXABLE
A7: FF-312114 | B7: FOOD/NON-ALC | C7: Fan Friendly N/A beverage discount
A8: FF-313076 | B8: FOOD/NON-ALC | C8: Fan Friendly food discount
A9: 353008 | B9: FOOD/NON-ALC | C9: Subcontract income (food%)

Sheet MSR DATA
A1: Raw Row | B1: Event | C1: Department | D1: Location | E1: Product Code | F1: Product Name | G1: Contract Class | H1: Gross Amt | I1: Net
A2: 2 | B2: =IF('MSR RAW'!$A$3="","",'MSR RAW'!$A$3) -> Event:UNM FOOTBALL GAME 1 - 9/5 (252) Start Date:09/05/26 5:00:00 PM End Date:09/05/26 11:55:51 PM Discount Source:Default Price Level Detail Level:Summary | C2: =IF(LEFT(TRIM('MSR RAW'!A2),11)="Department:",TRIM('MSR RAW'!A2),"") | D2: =IF(LEFT(TRIM('MSR RAW'!B2),9)="Location:",TRIM(MID('MSR RAW'!B2,10,999)),"") | E2: =IF(AND(ISNUMBER(SEARCH(" - ",TRIM('MSR RAW'!C2))),RIGHT(TRIM('MSR RAW'!C2),6)="Total:"),LEFT(TRIM('MSR RAW'!C2),SEARCH(" - ",TRIM('MSR RAW'!C2))-1),"") | F2: =IF(E2="","",TRIM(MID(TRIM('MSR RAW'!C2),SEARCH(" - ",TRIM('MSR RAW'!C2))+3,LEN(TRIM('MSR RAW'!C2))-SEARCH(" - ",TRIM('MSR RAW'!C2))-9))) | G2: =IF(E2="","",IFERROR(VLOOKUP(E2,'CATEGORY MAP'!$A$2:$B$20,2,FALSE()),"REVIEW")) | H2: =IF(E2="","",IFERROR(VALUE(SUBSTITUTE('MSR RAW'!P2,",","")),0)) | I2: =IF(E2="","",IFERROR(VALUE(SUBSTITUTE('MSR RAW'!S2,",","")),0))
A3: 3 | B3: =IF('MSR RAW'!$A$3="","",'MSR RAW'!$A$3) -> Event:UNM FOOTBALL GAME 1 - 9/5 (252) Start Date:09/05/26 5:00:00 PM End Date:09/05/26 11:55:51 PM Discount Source:Default Price Level Detail Level:Summary | C3: =IF(LEFT(TRIM('MSR RAW'!A3),11)="Department:",TRIM('MSR RAW'!A3),C2) | D3: =IF(LEFT(TRIM('MSR RAW'!B3),9)="Location:",TRIM(MID('MSR RAW'!B3,10,999)),D2) | E3: =IF(AND(ISNUMBER(SEARCH(" - ",TRIM('MSR RAW'!C3))),RIGHT(TRIM('MSR RAW'!C3),6)="Total:"),LEFT(TRIM('MSR RAW'!C3),SEARCH(" - ",TRIM('MSR RAW'!C3))-1),"") | F3: =IF(E3="","",TRIM(MID(TRIM('MSR RAW'!C3),SEARCH(" - ",TRIM('MSR RAW'!C3))+3,LEN(TRIM('MSR RAW'!C3))-SEARCH(" - ",TRIM('MSR RAW'!C3))-9))) | G3: =IF(E3="","",IFERROR(VLOOKUP(E3,'CATEGORY MAP'!$A$2:$B$20,2,FALSE()),"REVIEW")) | H3: =IF(E3="","",IFERROR(VALUE(SUBSTITUTE('MSR RAW'!P3,",","")),0)) | I3: =IF(E3="","",IFERROR(VALUE(SUBSTITUTE('MSR RAW'!S3,",","")),0))
A4: 4 | B4: =IF('MSR RAW'!$A$3="","",'MSR RAW'!$A$3) -> Event:UNM FOOTBALL GAME 1 - 9/5 (252) Start Date:09/05/26 5:00:00 PM End Date:09/05/26 11:55:51 PM Discount Source:Default Price Level Detail Level:Summary | C4: =IF(LEFT(TRIM('MSR RAW'!A4),11)="Department:",TRIM('MSR RAW'!A4),C3) | D4: =IF(LEFT(TRIM('MSR RAW'!B4),9)="Location:",TRIM(MID('MSR RAW'!B4,10,999)),D3) | E4: =IF(AND(ISNUMBER(SEARCH(" - ",TRIM('MSR RAW'!C4))),RIGHT(TRIM('MSR RAW'!C4),6)="Total:"),LEFT(TRIM('MSR RAW'!C4),SEARCH(" - ",TRIM('MSR RAW'!C4))-1),"") | F4: =IF(E4="","",TRIM(MID(TRIM('MSR RAW'!C4),SEARCH(" - ",TRIM('MSR RAW'!C4))+3,LEN(TRIM('MSR RAW'!C4))-SEARCH(" - ",TRIM('MSR RAW'!C4))-9))) | G4: =IF(E4="","",IFERROR(VLOOKUP(E4,'CATEGORY MAP'!$A$2:$B$20,2,FALSE()),"REVIEW")) | H4: =IF(E4="","",IFERROR(VALUE(SUBSTITUTE('MSR RAW'!P4,",","")),0)) | I4: =IF(E4="","",IFERROR(VALUE(SUBSTITUTE('MSR RAW'!S4,",","")),0))
A5: 5 | B5: =IF('MSR RAW'!$A$3="","",'MSR RAW'!$A$3) -> Event:UNM FOOTBALL GAME 1 - 9/5 (252) Start Date:09/05/26 5:00:00 PM End Date:09/05/26 11:55:51 PM Discount Source:Default Price Level Detail Level:Summary | C5: =IF(LEFT(TRIM('MSR RAW'!A5),11)="Department:",TRIM('MSR RAW'!A5),C4) | D5: =IF(LEFT(TRIM('MSR RAW'!B5),9)="Location:",TRIM(MID('MSR RAW'!B5,10,999)),D4) | E5: =IF(AND(ISNUMBER(SEARCH(" - ",TRIM('MSR RAW'!C5))),RIGHT(TRIM('MSR RAW'!C5),6)="Total:"),LEFT(TRIM('MSR RAW'!C5),SEARCH(" - ",TRIM('MSR RAW'!C5))-1),"") | F5: =IF(E5="","",TRIM(MID(TRIM('MSR RAW'!C5),SEARCH(" - ",TRIM('MSR RAW'!C5))+3,LEN(TRIM('MSR RAW'!C5))-SEARCH(" - ",TRIM('MSR RAW'!C5))-9))) | G5: =IF(E5="","",IFERROR(VLOOKUP(E5,'CATEGORY MAP'!$A$2:$B$20,2,FALSE()),"REVIEW")) | H5: =IF(E5="","",IFERROR(VALUE(SUBSTITUTE('MSR RAW'!P5,",","")),0)) | I5: =IF(E5="","",IFERROR(VALUE(SUBSTITUTE('MSR RAW'!S5,",","")),0))
A6: 6 | B6: =IF('MSR RAW'!$A$3="","",'MSR RAW'!$A$3) -> Event:UNM FOOTBALL GAME 1 - 9/5 (252) Start Date:09/05/26 5:00:00 PM End Date:09/05/26 11:55:51 PM Discount Source:Default Price Level Detail Level:Summary | C6: =IF(LEFT(TRIM('MSR RAW'!A6),11)="Department:",TRIM('MSR RAW'!A6),C5) -> Department: 36127 - CONCESSIONS | D6: =IF(LEFT(TRIM('MSR RAW'!B6),9)="Location:",TRIM(MID('MSR RAW'!B6,10,999)),D5) | E6: =IF(AND(ISNUMBER(SEARCH(" - ",TRIM('MSR RAW'!C6))),RIGHT(TRIM('MSR RAW'!C6),6)="Total:"),LEFT(TRIM('MSR RAW'!C6),SEARCH(" - ",TRIM('MSR RAW'!C6))-1),"") | F6: =IF(E6="","",TRIM(MID(TRIM('MSR RAW'!C6),SEARCH(" - ",TRIM('MSR RAW'!C6))+3,LEN(TRIM('MSR RAW'!C6))-SEARCH(" - ",TRIM('MSR RAW'!C6))-9))) | G6: =IF(E6="","",IFERROR(VLOOKUP(E6,'CATEGORY MAP'!$A$2:$B$20,2,FALSE()),"REVIEW")) | H6: =IF(E6="","",IFERROR(VALUE(SUBSTITUTE('MSR RAW'!P6,",","")),0)) | I6: =IF(E6="","",IFERROR(VALUE(SUBSTITUTE('MSR RAW'!S6,",","")),0))
A7: 7 | B7: =IF('MSR RAW'!$A$3="","",'MSR RAW'!$A$3) -> Event:UNM FOOTBALL GAME 1 - 9/5 (252) Start Date:09/05/26 5:00:00 PM End Date:09/05/26 11:55:51 PM Discount Source:Default Price Level Detail Level:Summary | C7: =IF(LEFT(TRIM('MSR RAW'!A7),11)="Department:",TRIM('MSR RAW'!A7),C6) -> Department: 36127 - CONCESSIONS | D7: =IF(LEFT(TRIM('MSR RAW'!B7),9)="Location:",TRIM(MID('MSR RAW'!B7,10,999)),D6) -> FB 100 - TRAILER N CONCOURSE | E7: =IF(AND(ISNUMBER(SEARCH(" - ",TRIM('MSR RAW'!C7))),RIGHT(TRIM('MSR RAW'!C7),6)="Total:"),LEFT(TRIM('MSR RAW'!C7),SEARCH(" - ",TRIM('MSR RAW'!C7))-1),"") | F7: =IF(E7="","",TRIM(MID(TRIM('MSR RAW'!C7),SEARCH(" - ",TRIM('MSR RAW'!C7))+3,LEN(TRIM('MSR RAW'!C7))-SEARCH(" - ",TRIM('MSR RAW'!C7))-9))) | G7: =IF(E7="","",IFERROR(VLOOKUP(E7,'CATEGORY MAP'!$A$2:$B$20,2,FALSE()),"REVIEW")) | H7: =IF(E7="","",IFERROR(VALUE(SUBSTITUTE('MSR RAW'!P7,",","")),0)) | I7: =IF(E7="","",IFERROR(VALUE(SUBSTITUTE('MSR RAW'!S7,",","")),0))
A8: 8 | B8: =IF('MSR RAW'!$A$3="","",'MSR RAW'!$A$3) -> Event:UNM FOOTBALL GAME 1 - 9/5 (252) Start Date:09/05/26 5:00:00 PM End Date:09/05/26 11:55:51 PM Discount Source:Default Price Level Detail Level:Summary | C8: =IF(LEFT(TRIM('MSR RAW'!A8),11)="Department:",TRIM('MSR RAW'!A8),C7) -> Department: 36127 - CONCESSIONS | D8: =IF(LEFT(TRIM('MSR RAW'!B8),9)="Location:",TRIM(MID('MSR RAW'!B8,10,999)),D7) -> FB 100 - TRAILER N CONCOURSE | E8: =IF(AND(ISNUMBER(SEARCH(" - ",TRIM('MSR RAW'!C8))),RIGHT(TRIM('MSR RAW'!C8),6)="Total:"),LEFT(TRIM('MSR RAW'!C8),SEARCH(" - ",TRIM('MSR RAW'!C8))-1),"") | F8: =IF(E8="","",TRIM(MID(TRIM('MSR RAW'!C8),SEARCH(" - ",TRIM('MSR RAW'!C8))+3,LEN(TRIM('MSR RAW'!C8))-SEARCH(" - ",TRIM('MSR RAW'!C8))-9))) | G8: =IF(E8="","",IFERROR(VLOOKUP(E8,'CATEGORY MAP'!$A$2:$B$20,2,FALSE()),"REVIEW")) | H8: =IF(E8="","",IFERROR(VALUE(SUBSTITUTE('MSR RAW'!P8,",","")),0)) | I8: =IF(E8="","",IFERROR(VALUE(SUBSTITUTE('MSR RAW'!S8,",","")),0))
A9: 9 | B9: =IF('MSR RAW'!$A$3="","",'MSR RAW'!$A$3) -> Event:UNM FOOTBALL GAME 1 - 9/5 (252) Start Date:09/05/26 5:00:00 PM End Date:09/05/26 11:55:51 PM Discount Source:Default Price Level Detail Level:Summary | C9: =IF(LEFT(TRIM('MSR RAW'!A9),11)="Department:",TRIM('MSR RAW'!A9),C8) -> Department: 36127 - CONCESSIONS | D9: =IF(LEFT(TRIM('MSR RAW'!B9),9)="Location:",TRIM(MID('MSR RAW'!B9,10,999)),D8) -> FB 100 - TRAILER N CONCOURSE | E9: =IF(AND(ISNUMBER(SEARCH(" - ",TRIM('MSR RAW'!C9))),RIGHT(TRIM('MSR RAW'!C9),6)="Total:"),LEFT(TRIM('MSR RAW'!C9),SEARCH(" - ",TRIM('MSR RAW'!C9))-1),"") -> 312115 | F9: =IF(E9="","",TRIM(MID(TRIM('MSR RAW'!C9),SEARCH(" - ",TRIM('MSR RAW'!C9))+3,LEN(TRIM('MSR RAW'!C9))-SEARCH(" - ",TRIM('MSR RAW'!C9))-9))) -> N/A BEVERAGE SALES - TAXABLE | G9: =IF(E9="","",IFERROR(VLOOKUP(E9,'CATEGORY MAP'!$A$2:$B$20,2,FALSE()),"REVIEW")) -> FOOD/NON-ALC | H9: =IF(E9="","",IFERROR(VALUE(SUBSTITUTE('MSR RAW'!P9,",","")),0)) -> 2332.23 | I9: =IF(E9="","",IFERROR(VALUE(SUBSTITUTE('MSR RAW'!S9,",","")),0)) -> 2167
A10: 10 | B10: =IF('MSR RAW'!$A$3="","",'MSR RAW'!$A$3) -> Event:UNM FOOTBALL GAME 1 - 9/5 (252) Start Date:09/05/26 5:00:00 PM End Date:09/05/26 11:55:51 PM Discount Source:Default Price Level Detail Level:Summary | C10: =IF(LEFT(TRIM('MSR RAW'!A10),11)="Department:",TRIM('MSR RAW'!A10),C9) -> Department: 36127 - CONCESSIONS | D10: =IF(LEFT(TRIM('MSR RAW'!B10),9)="Location:",TRIM(MID('MSR RAW'!B10,10,999)),D9) -> FB 100 - TRAILER N CONCOURSE | E10: =IF(AND(ISNUMBER(SEARCH(" - ",TRIM('MSR RAW'!C10))),RIGHT(TRIM('MSR RAW'!C10),6)="Total:"),LEFT(TRIM('MSR RAW'!C10),SEARCH(" - ",TRIM('MSR RAW'!C10))-1),"") -> 313000 | F10: =IF(E10="","",TRIM(MID(TRIM('MSR RAW'!C10),SEARCH(" - ",TRIM('MSR RAW'!C10))+3,LEN(TRIM('MSR RAW'!C10))-SEARCH(" - ",TRIM('MSR RAW'!C10))-9))) -> FOOD SALES - TAXABLE | G10: =IF(E10="","",IFERROR(VLOOKUP(E10,'CATEGORY MAP'!$A$2:$B$20,2,FALSE()),"REVIEW")) -> FOOD/NON-ALC | H10: =IF(E10="","",IFERROR(VALUE(SUBSTITUTE('MSR RAW'!P10,",","")),0)) -> 3455.84 | I10: =IF(E10="","",IFERROR(VALUE(SUBSTITUTE('MSR RAW'!S10,",","")),0)) -> 3211
A11: 11 | B11: =IF('MSR RAW'!$A$3="","",'MSR RAW'!$A$3) -> Event:UNM FOOTBALL GAME 1 - 9/5 (252) Start Date:09/05/26 5:00:00 PM End Date:09/05/26 11:55:51 PM Discount Source:Default Price Level Detail Level:Summary | C11: =IF(LEFT(TRIM('MSR RAW'!A11),11)="Department:",TRIM('MSR RAW'!A11),C10) -> Department: 36127 - CONCESSIONS | D11: =IF(LEFT(TRIM('MSR RAW'!B11),9)="Location:",TRIM(MID('MSR RAW'!B11,10,999)),D10) -> FB 100 - TRAILER N CONCOURSE | E11: =IF(AND(ISNUMBER(SEARCH(" - ",TRIM('MSR RAW'!C11))),RIGHT(TRIM('MSR RAW'!C11),6)="Total:"),LEFT(TRIM('MSR RAW'!C11),SEARCH(" - ",TRIM('MSR RAW'!C11))-1),"") -> 313004 | F11: =IF(E11="","",TRIM(MID(TRIM('MSR RAW'!C11),SEARCH(" - ",TRIM('MSR RAW'!C11))+3,LEN(TRIM('MSR RAW'!C11))-SEARCH(" - ",TRIM('MSR RAW'!C11))-9))) -> LIQUOR SALES - TAXABLE | G11: =IF(E11="","",IFERROR(VLOOKUP(E11,'CATEGORY MAP'!$A$2:$B$20,2,FALSE()),"REVIEW")) -> ALCOHOL | H11: =IF(E11="","",IFERROR(VALUE(SUBSTITUTE('MSR RAW'!P11,",","")),0)) -> 361.62 | I11: =IF(E11="","",IFERROR(VALUE(SUBSTITUTE('MSR RAW'!S11,",","")),0)) -> 336
A12: 12 | B12: =IF('MSR RAW'!$A$3="","",'MSR RAW'!$A$3) -> Event:UNM FOOTBALL GAME 1 - 9/5 (252) Start Date:09/05/26 5:00:00 PM End Date:09/05/26 11:55:51 PM Discount Source:Default Price Level Detail Level:Summary | C12: =IF(LEFT(TRIM('MSR RAW'!A12),11)="Department:",TRIM('MSR RAW'!A12),C11) -> Department: 36127 - CONCESSIONS | D12: =IF(LEFT(TRIM('MSR RAW'!B12),9)="Location:",TRIM(MID('MSR RAW'!B12,10,999)),D11) -> FB 100 - TRAILER N CONCOURSE | E12: =IF(AND(ISNUMBER(SEARCH(" - ",TRIM('MSR RAW'!C12))),RIGHT(TRIM('MSR RAW'!C12),6)="Total:"),LEFT(TRIM('MSR RAW'!C12),SEARCH(" - ",TRIM('MSR RAW'!C12))-1),"") -> 313082 | F12: =IF(E12="","",TRIM(MID(TRIM('MSR RAW'!C12),SEARCH(" - ",TRIM('MSR RAW'!C12))+3,LEN(TRIM('MSR RAW'!C12))-SEARCH(" - ",TRIM('MSR RAW'!C12))-9))) -> BEER PACKAGED SALES | G12: =IF(E12="","",IFERROR(VLOOKUP(E12,'CATEGORY MAP'!$A$2:$B$20,2,FALSE()),"REVIEW")) -> ALCOHOL | H12: =IF(E12="","",IFERROR(VALUE(SUBSTITUTE('MSR RAW'!P12,",","")),0)) -> 1055.26 | I12: =IF(E12="","",IFERROR(VALUE(SUBSTITUTE('MSR RAW'!S12,",","")),0)) -> 980.5
