Workbook

Sheet SET-UP & SUMMARY
A1: SUMMARY - NPO PAYOUT - AP
A3: PAYOUT EVENT DETAILS - SETUP
A4: Event Date: | B4: 46270
A5: Event Day of Week: | B5: =B4
A6: Event Description: | B6: Football
A10: SUMMARY REPORT — ASSIGNMENT-DRIVEN
A11: NPO | B11: ASSIGNMENT SALES | C11: CONTRACT DONATION | D11: TIPS | E11: TOTAL PAYOUT*
A12: ARVC | B12: =SUMIFS('CONTRACT CALC'!$J$13:$J$112,'CONTRACT CALC'!$B$13:$B$112,A12) | C12: =SUMIFS('CONTRACT CALC'!$K$13:$K$112,'CONTRACT CALC'!$B$13:$B$112,A12) | D12: =SUMIFS('TIPS DATA'!$H$2:$H$101,'TIPS DATA'!$C$2:$C$101,A12) | E12: =C12+D12
A13: AIRFORCE | B13: =SUMIFS('CONTRACT CALC'!$J$13:$J$112,'CONTRACT CALC'!$B$13:$B$112,A13) | C13: =SUMIFS('CONTRACT CALC'!$K$13:$K$112,'CONTRACT CALC'!$B$13:$B$112,A13) | D13: =SUMIFS('TIPS DATA'!$H$2:$H$101,'TIPS DATA'!$C$2:$C$101,A13) | E13: =C13+D13
A14: UNITED FIT | B14: =SUMIFS('CONTRACT CALC'!$J$13:$J$112,'CONTRACT CALC'!$B$13:$B$112,A14) | C14: =SUMIFS('CONTRACT CALC'!$K$13:$K$112,'CONTRACT CALC'!$B$13:$B$112,A14) | D14: =SUMIFS('TIPS DATA'!$H$2:$H$101,'TIPS DATA'!$C$2:$C$101,A14) | E14: =C14+D14
A15: DCVA | B15: =SUMIFS('CONTRACT CALC'!$J$13:$J$112,'CONTRACT CALC'!$B$13:$B$112,A15) | C15: =SUMIFS('CONTRACT CALC'!$K$13:$K$112,'CONTRACT CALC'!$B$13:$B$112,A15) | D15: =SUMIFS('TIPS DATA'!$H$2:$H$101,'TIPS DATA'!$C$2:$C$101,A15) | E15: =C15+D15
A16: DEL N CHEER | B16: =SUMIFS('CONTRACT CALC'!$J$13:$J$112,'CONTRACT CALC'!$B$13:$B$112,A16) | C16: =SUMIFS('CONTRACT CALC'!$K$13:$K$112,'CONTRACT CALC'!$B$13:$B$112,A16) | D16: =SUMIFS('TIPS DATA'!$H$2:$H$101,'TIPS DATA'!$C$2:$C$101,A16) | E16: =C16+D16
A17: RIO GRANDE RGHS | B17: =SUMIFS('CONTRACT CALC'!$J$13:$J$112,'CONTRACT CALC'!$B$13:$B$112,A17) | C17: =SUMIFS('CONTRACT CALC'!$K$13:$K$112,'CONTRACT CALC'!$B$13:$B$112,A17) | D17: =SUMIFS('TIPS DATA'!$H$2:$H$101,'TIPS DATA'!$C$2:$C$101,A17) | E17: =C17+D17
A18: VICTORY OUTREACH | B18: =SUMIFS('CONTRACT CALC'!$J$13:$J$112,'CONTRACT CALC'!$B$13:$B$112,A18) | C18: =SUMIFS('CONTRACT CALC'!$K$13:$K$112,'CONTRACT CALC'!$B$13:$B$112,A18) | D18: =SUMIFS('TIPS DATA'!$H$2:$H$101,'TIPS DATA'!$C$2:$C$101,A18) | E18: =C18+D18
A19: TOTAL | B19: =SUM(B12:B18) | C19: =SUM(C12:C18) | D19: =SUM(D12:D18) | E19: =SUM(E12:E18)
A21: VENDOR PAYOUT = one reusable statement. NPO MASTER = vendor identity (SAP/BSS/Alias). SUPPLEMENTAL DATA = optional saved bonus/fees by Event+Payee. Yellow cells on VENDOR PAYOUT are this document’s personal adjustments for review/PDF. CATEGORY MAP is required for food vs alcohol classification.
A23: SETUP - STAND LOCATIONS
A24: STAND ID | B24: STAND DESCRIPTION
A25: BASEBALL | B25: TRAILER | C25: baseball
A26: 207 - PREM | B26: DESSERT CART | C26: PIT
A27: PREM 000 | B27: PREMIUM BANQUET | C27: PIT
A28: FB 100 | B28: TRAILER N CONCOURSE | C28: FB
A29: FB 100B | B29: MBP TRAILER N CONCOURSE | C29: FB
A30: FB 101 | B30: STADIUM SIPS SHACK SW | C30: FB
A31: FB 102 | B31: TOWER SOUTH | C31: FB
A32: FB 103 | B32: TOWER NORTH | C32: FB
A33: FB 104 | B33: RED RALLY NORTH WEST | C33: FB
A34: FB 105 | B34: NW SPECIALTY DAWG 2.0 | C34: FB
A35: FB 106 | B35: RED RALLY NORTH EAST | C35: FB
A36: FB 107 | B36: NE SPECIALTY DAWG O.G. | C36: FB
... A80: PIT CU1 | B80: CULINARY SUPPORT | C80: PIT

Sheet NPO MASTER
A1: Alias (Payee Key) | B1: Legal / Full Name | C1: SAP ID | D1: BSS ID | E1: Primary Contact | F1: Phone | G1: Email | H1: Check Payable To | I1: Active | J1: Standing Notes | L1: PURPOSE
A2: ARVC | B2: Albuquerque Rugby Volleyball Club | H2: ARVC | I2: Y | L2: One row per NPO/vendor group. Alias must match EVENT ASSIGNMENT NPO and VENDOR PAYOUT Payee. SAP/BSS fill the settlement header automatically. Standing Notes are permanent group info — not event-specific settlement notes.
A3: AIRFORCE | B3: Air Force Association / Support Group | H3: AIRFORCE | I3: Y
A4: UNITED FIT | B4: United Fitness / Booster Group | H4: UNITED FIT | I4: Y
A5: DCVA | B5: Duke City Volleyball Association | H5: DCVA | I5: Y
A6: DEL N CHEER | B6: Del Norte Cheer | H6: DEL N CHEER | I6: Y
A7: RIO GRANDE RGHS | B7: Rio Grande High School | H7: RIO GRANDE RGHS | I7: Y
A8: VICTORY OUTREACH | B8: Victory Outreach Albuquerque | H8: VICTORY OUTREACH | I8: Y

Sheet VENDOR PAYOUT
C2: SETTLEMENT STATEMENT
C3: LEVY • UNM ATHLETICS
B5: =$E$10 | G5: TOTAL PAYABLE
B6: ='SET-UP & SUMMARY'!B6 | G6: =SUM(H28,I28,H31,H32,H33,H34,H35,H36)
B7: =IFERROR(VLOOKUP($E$10,'NPO MASTER'!$A$2:$B$50,2,FALSE),"")
B9: EVENT DATE | C9: INVOICE | E9: PAYEE / NPO | G9: SAP ID | H9: BSS ID
B10: 46270 | C10: =CONCATENATE("UNM-",TEXT(B10,"MMDDYY-"),E10) | E10: ARVC | G10: =IFERROR(VLOOKUP($E$10,'NPO MASTER'!$A$2:$D$50,3,FALSE),"") | H10: =IFERROR(VLOOKUP($E$10,'NPO MASTER'!$A$2:$D$50,4,FALSE),"")
B11: Review flow: select Event + Payee → confirm locations/commission → edit yellow THIS STATEMENT bonus/notes → Export PDF → zero yellow supplemental before next Payee (or copy into SUPPLEMENTAL DATA to remember). SAP/BSS come from NPO MASTER. Sales always from source/calc — never type those.
B12: SALES COMMISSION (DONATION TO NPO): POS SALES | E12: NON-CALCULATED SALES DATA
B13: FOOD / NON-ALCOHOLIC | C13: ALCOHOL | D13: GROUP NET | E13: SALES TAX | F13: GROSS SALES
B14: =D28 | C14: =F28 | D14: =C28 | E14: =D28 | F14: =E28
B16: LOCATION SERVICE DETAIL
A17: # | B17: SERVICE AREA | C17: NET SALES | D17: FOOD / NON-ALC NET SALES | E17: 10% FOOD / NON-ALC COMMISSION | F17: ALCOHOL NET SALES | G17: 8% ALCOHOL COMMISSION | H17: TOTAL COMMISSION | I17: GRATUITIES
A18: =IFERROR(MATCH(TEXT($B$10,"yyyymmdd")&"|"&$E$10&"|1",'EVENT ASSIGNMENT'!$K$2:$K$101,0),"") | B18: =IF(IFERROR(MATCH(TEXT($B$10,"yyyymmdd")&"|"&$E$10&"|1",'EVENT ASSIGNMENT'!$K$2:$K$101,0),"")="","",IFERROR(INDEX('EVENT ASSIGNMENT'!$D$2:$D$101,IFERROR(MATCH(TEXT($B$10,"yyyymmdd")&"|"&$E$10&"|1",'EVENT ASSIGNMENT'!$K$2:$K$101,0),"")),"")) | C18: =IF(OR(IFERROR(MATCH(TEXT($B$10,"yyyymmdd")&"|"&$E$10&"|1",'EVENT ASSIGNMENT'!$K$2:$K$101,0),"")="",B18=""),"",IFERROR(INDEX('CONTRACT CALC'!$G$13:$G$112,IFERROR(MATCH(TEXT($B$10,"yyyymmdd")&"|"&$E$10&"|1",'EVENT ASSIGNMENT'!$K$2:$K$101,0),""))*INDEX('CONTRACT CALC'!$F$13:$F$112,IFERROR(MATCH(TEXT($B$10,"yyyymmdd")&"|"&$E$10&"|1",'EVENT ASSIGNMENT'!$K$2:$K$101,0),"")),"")) | D18: =IF(OR(IFERROR(MATCH(TEXT($B$10,"yyyymmdd")&"|"&$E$10&"|1",'EVENT ASSIGNMENT'!$K$2:$K$101,0),"")="",B18=""),"",IFERROR(INDEX('CONTRACT CALC'!$I$13:$I$112,IFERROR(MATCH(TEXT($B$10,"yyyymmdd")&"|"&$E$10&"|1",'EVENT ASSIGNMENT'!$K$2:$K$101,0),""))*INDEX('CONTRACT CALC'!$F$13:$F$112,IFERROR(MATCH(TEXT($B$10,"yyyymmdd")&"|"&$E$10&"|1",'EVENT ASSIGNMENT'!$K$2:$K$101,0),"")),"")) | E18: =IF(D18="","",D18*'CONTRACT CALC'!$B$4) | F18: =IF(OR(IFERROR(MATCH(TEXT($B$10,"yyyymmdd")&"|"&$E$10&"|1",'EVENT ASSIGNMENT'!$K$2:$K$101,0),"")="",B18=""),"",IFERROR(INDEX('CONTRACT CALC'!$H$13:$H$112,IFERROR(MATCH(TEXT($B$10,"yyyymmdd")&"|"&$E$10&"|1",'EVENT ASSIGNMENT'!$K$2:$K$101,0),""))*INDEX('CONTRACT CALC'!$F$13:$F$112,IFERROR(MATCH(TEXT($B$10,"yyyymmdd")&"|"&$E$10&"|1",'EVENT ASSIGNMENT'!$K$2:$K$101,0),"")),"")) | G18: =IF(F18="","",F18*'CONTRACT CALC'!$B$5) | H18: =IF(B18="","",N(E18)+N(G18)) | I18: =IF(OR(IFERROR(MATCH(TEXT($B$10,"yyyymmdd")&"|"&$E$10&"|1",'EVENT ASSIGNMENT'!$K$2:$K$101,0),"")="",B18=""),"",IF(COUNTIFS('TIPS DATA'!$A$2:$A$101,$B$10,'TIPS DATA'!$C$2:$C$101,$E$10,'TIPS DATA'!$D$2:$D$101,INDEX('EVENT ASSIGNMENT'!$C$2:$C$101,IFERROR(MATCH(TEXT($B$10,"yyyymmdd")&"|"&$E$10&"|1",'EVENT ASSIGNMENT'!$K$2:$K$101,0),"")))>0,SUMIFS('TIPS DATA'!$H$2:$H$101,'TIPS DATA'!$A$2:$A$101,$B$10,'TIPS DATA'!$C$2:$C$101,$E$10,'TIPS DATA'!$D$2:$D$101,INDEX('EVENT ASSIGNMENT'!$C$2:$C$101,IFERROR(MATCH(TEXT($B$10,"yyyymmdd")&"|"&$E$10&"|1",'EVENT ASSIGNMENT'!$K$2:$K$101,0),""))),SUMIFS('TIPS DATA'!$H$2:$H$101,'TIPS DATA'!$A$2:$A$101,$B$10,'TIPS DATA'!$C$2:$C$101,$E$10,'TIPS DATA'!$E$2:$E$101,INDEX('EVENT ASSIGNMENT'!$D$2:$D$101,IFERROR(MATCH(TEXT($B$10,"yyyymmdd")&"|"&$E$10&"|1",'EVENT ASSIGNMENT'!$K$2:$K$101,0),"")))))
A19: =IFERROR(MATCH(TEXT($B$10,"yyyymmdd")&"|"&$E$10&"|2",'EVENT ASSIGNMENT'!$K$2:$K$101,0),"") | B19: =IF(IFERROR(MATCH(TEXT($B$10,"yyyymmdd")&"|"&$E$10&"|2",'EVENT ASSIGNMENT'!$K$2:$K$101,0),"")="","",IFERROR(INDEX('EVENT ASSIGNMENT'!$D$2:$D$101,IFERROR(MATCH(TEXT($B$10,"yyyymmdd")&"|"&$E$10&"|2",'EVENT ASSIGNMENT'!$K$2:$K$101,0),"")),"")) | C19: =IF(OR(IFERROR(MATCH(TEXT($B$10,"yyyymmdd")&"|"&$E$10&"|2",'EVENT ASSIGNMENT'!$K$2:$K$101,0),"")="",B19=""),"",IFERROR(INDEX('CONTRACT CALC'!$G$13:$G$112,IFERROR(MATCH(TEXT($B$10,"yyyymmdd")&"|"&$E$10&"|2",'EVENT ASSIGNMENT'!$K$2:$K$101,0),""))*INDEX('CONTRACT CALC'!$F$13:$F$112,IFERROR(MATCH(TEXT($B$10,"yyyymmdd")&"|"&$E$10&"|2",'EVENT ASSIGNMENT'!$K$2:$K$101,0),"")),"")) | D19: =IF(OR(IFERROR(MATCH(TEXT($B$10,"yyyymmdd")&"|"&$E$10&"|2",'EVENT ASSIGNMENT'!$K$2:$K$101,0),"")="",B19=""),"",IFERROR(INDEX('CONTRACT CALC'!$I$13:$I$112,IFERROR(MATCH(TEXT($B$10,"yyyymmdd")&"|"&$E$10&"|2",'EVENT ASSIGNMENT'!$K$2:$K$101,0),""))*INDEX('CONTRACT CALC'!$F$13:$F$112,IFERROR(MATCH(TEXT($B$10,"yyyymmdd")&"|"&$E$10&"|2",'EVENT ASSIGNMENT'!$K$2:$K$101,0),"")),"")) | E19: =IF(D19="","",D19*'CONTRACT CALC'!$B$4) | F19: =IF(OR(IFERROR(MATCH(TEXT($B$10,"yyyymmdd")&"|"&$E$10&"|2",'EVENT ASSIGNMENT'!$K$2:$K$101,0),"")="",B19=""),"",IFERROR(INDEX('CONTRACT CALC'!$H$13:$H$112,IFERROR(MATCH(TEXT($B$10,"yyyymmdd")&"|"&$E$10&"|2",'EVENT ASSIGNMENT'!$K$2:$K$101,0),""))*INDEX('CONTRACT CALC'!$F$13:$F$112,IFERROR(MATCH(TEXT($B$10,"yyyymmdd")&"|"&$E$10&"|2",'EVENT ASSIGNMENT'!$K$2:$K$101,0),"")),"")) | G19: =IF(F19="","",F19*'CONTRACT CALC'!$B$5) | H19: =IF(B19="","",N(E19)+N(G19)) | I19: =IF(OR(IFERROR(MATCH(TEXT($B$10,"yyyymmdd")&"|"&$E$10&"|2",'EVENT ASSIGNMENT'!$K$2:$K$101,0),"")="",B19=""),"",IF(COUNTIFS('TIPS DATA'!$A$2:$A$101,$B$10,'TIPS DATA'!$C$2:$C$101,$E$10,'TIPS DATA'!$D$2:$D$101,INDEX('EVENT ASSIGNMENT'!$C$2:$C$101,IFERROR(MATCH(TEXT($B$10,"yyyymmdd")&"|"&$E$10&"|2",'EVENT ASSIGNMENT'!$K$2:$K$101,0),"")))>0,SUMIFS('TIPS DATA'!$H$2:$H$101,'TIPS DATA'!$A$2:$A$101,$B$10,'TIPS DATA'!$C$2:$C$101,$E$10,'TIPS DATA'!$D$2:$D$101,INDEX('EVENT ASSIGNMENT'!$C$2:$C$101,IFERROR(MATCH(TEXT($B$10,"yyyymmdd")&"|"&$E$10&"|2",'EVENT ASSIGNMENT'!$K$2:$K$101,0),""))),SUMIFS('TIPS DATA'!$H$2:$H$101,'TIPS DATA'!$A$2:$A$101,$B$10,'TIPS DATA'!$C$2:$C$101,$E$10,'TIPS DATA'!$E$2:$E$101,INDEX('EVENT ASSIGNMENT'!$D$2:$D$101,IFERROR(MATCH(TEXT($B$10,"yyyymmdd")&"|"&$E$10&"|2",'EVENT ASSIGNMENT'!$K$2:$K$101,0),"")))))
A20: =IFERROR(MATCH(TEXT($B$10,"yyyymmdd")&"|"&$E$10&"|3",'EVENT ASSIGNMENT'!$K$2:$K$101,0),"") | B20: =IF(IFERROR(MATCH(TEXT($B$10,"yyyymmdd")&"|"&$E$10&"|3",'EVENT ASSIGNMENT'!$K$2:$K$101,0),"")="","",IFERROR(INDEX('EVENT ASSIGNMENT'!$D$2:$D$101,IFERROR(MATCH(TEXT($B$10,"yyyymmdd")&"|"&$E$10&"|3",'EVENT ASSIGNMENT'!$K$2:$K$101,0),"")),"")) | C20: =IF(OR(IFERROR(MATCH(TEXT($B$10,"yyyymmdd")&"|"&$E$10&"|3",'EVENT ASSIGNMENT'!$K$2:$K$101,0),"")="",B20=""),"",IFERROR(INDEX('CONTRACT CALC'!$G$13:$G$112,IFERROR(MATCH(TEXT($B$10,"yyyymmdd")&"|"&$E$10&"|3",'EVENT ASSIGNMENT'!$K$2:$K$101,0),""))*INDEX('CONTRACT CALC'!$F$13:$F$112,IFERROR(MATCH(TEXT($B$10,"yyyymmdd")&"|"&$E$10&"|3",'EVENT ASSIGNMENT'!$K$2:$K$101,0),"")),"")) | D20: =IF(OR(IFERROR(MATCH(TEXT($B$10,"yyyymmdd")&"|"&$E$10&"|3",'EVENT ASSIGNMENT'!$K$2:$K$101,0),"")="",B20=""),"",IFERROR(INDEX('CONTRACT CALC'!$I$13:$I$112,IFERROR(MATCH(TEXT($B$10,"yyyymmdd")&"|"&$E$10&"|3",'EVENT ASSIGNMENT'!$K$2:$K$101,0),""))*INDEX('CONTRACT CALC'!$F$13:$F$112,IFERROR(MATCH(TEXT($B$10,"yyyymmdd")&"|"&$E$10&"|3",'EVENT ASSIGNMENT'!$K$2:$K$101,0),"")),"")) | E20: =IF(D20="","",D20*'CONTRACT CALC'!$B$4) | F20: =IF(OR(IFERROR(MATCH(TEXT($B$10,"yyyymmdd")&"|"&$E$10&"|3",'EVENT ASSIGNMENT'!$K$2:$K$101,0),"")="",B20=""),"",IFERROR(INDEX('CONTRACT CALC'!$H$13:$H$112,IFERROR(MATCH(TEXT($B$10,"yyyymmdd")&"|"&$E$10&"|3",'EVENT ASSIGNMENT'!$K$2:$K$101,0),""))*INDEX('CONTRACT CALC'!$F$13:$F$112,IFERROR(MATCH(TEXT($B$10,"yyyymmdd")&"|"&$E$10&"|3",'EVENT ASSIGNMENT'!$K$2:$K$101,0),"")),"")) | G20: =IF(F20="","",F20*'CONTRACT CALC'!$B$5) | H20: =IF(B20="","",N(E20)+N(G20)) | I20: =IF(OR(IFERROR(MATCH(TEXT($B$10,"yyyymmdd")&"|"&$E$10&"|3",'EVENT ASSIGNMENT'!$K$2:$K$101,0),"")="",B20=""),"",IF(COUNTIFS('TIPS DATA'!$A$2:$A$101,$B$10,'TIPS DATA'!$C$2:$C$101,$E$10,'TIPS DATA'!$D$2:$D$101,INDEX('EVENT ASSIGNMENT'!$C$2:$C$101,IFERROR(MATCH(TEXT($B$10,"yyyymmdd")&"|"&$E$10&"|3",'EVENT ASSIGNMENT'!$K$2:$K$101,0),"")))>0,SUMIFS('TIPS DATA'!$H$2:$H$101,'TIPS DATA'!$A$2:$A$101,$B$10,'TIPS DATA'!$C$2:$C$101,$E$10,'TIPS DATA'!$D$2:$D$101,INDEX('EVENT ASSIGNMENT'!$C$2:$C$101,IFERROR(MATCH(TEXT($B$10,"yyyymmdd")&"|"&$E$10&"|3",'EVENT ASSIGNMENT'!$K$2:$K$101,0),""))),SUMIFS('TIPS DATA'!$H$2:$H$101,'TIPS DATA'!$A$2:$A$101,$B$10,'TIPS DATA'!$C$2:$C$101,$E$10,'TIPS DATA'!$E$2:$E$101,INDEX('EVENT ASSIGNMENT'!$D$2:$D$101,IFERROR(MATCH(TEXT($B$10,"yyyymmdd")&"|"&$E$10&"|3",'EVENT ASSIGNMENT'!$K$2:$K$101,0),"")))))
A21: =IFERROR(MATCH(TEXT($B$10,"yyyymmdd")&"|"&$E$10&"|4",'EVENT ASSIGNMENT'!$K$2:$K$101,0),"") | B21: =IF(IFERROR(MATCH(TEXT($B$10,"yyyymmdd")&"|"&$E$10&"|4",'EVENT ASSIGNMENT'!$K$2:$K$101,0),"")="","",IFERROR(INDEX('EVENT ASSIGNMENT'!$D$2:$D$101,IFERROR(MATCH(TEXT($B$10,"yyyymmdd")&"|"&$E$10&"|4",'EVENT ASSIGNMENT'!$K$2:$K$101,0),"")),"")) | C21: =IF(OR(IFERROR(MATCH(TEXT($B$10,"yyyymmdd")&"|"&$E$10&"|4",'EVENT ASSIGNMENT'!$K$2:$K$101,0),"")="",B21=""),"",IFERROR(INDEX('CONTRACT CALC'!$G$13:$G$112,IFERROR(MATCH(TEXT($B$10,"yyyymmdd")&"|"&$E$10&"|4",'EVENT ASSIGNMENT'!$K$2:$K$101,0),""))*INDEX('CONTRACT CALC'!$F$13:$F$112,IFERROR(MATCH(TEXT($B$10,"yyyymmdd")&"|"&$E$10&"|4",'EVENT ASSIGNMENT'!$K$2:$K$101,0),"")),"")) | D21: =IF(OR(IFERROR(MATCH(TEXT($B$10,"yyyymmdd")&"|"&$E$10&"|4",'EVENT ASSIGNMENT'!$K$2:$K$101,0),"")="",B21=""),"",IFERROR(INDEX('CONTRACT CALC'!$I$13:$I$112,IFERROR(MATCH(TEXT($B$10,"yyyymmdd")&"|"&$E$10&"|4",'EVENT ASSIGNMENT'!$K$2:$K$101,0),""))*INDEX('CONTRACT CALC'!$F$13:$F$112,IFERROR(MATCH(TEXT($B$10,"yyyymmdd")&"|"&$E$10&"|4",'EVENT ASSIGNMENT'!$K$2:$K$101,0),"")),"")) | E21: =IF(D21="","",D21*'CONTRACT CALC'!$B$4) | F21: =IF(OR(IFERROR(MATCH(TEXT($B$10,"yyyymmdd")&"|"&$E$10&"|4",'EVENT ASSIGNMENT'!$K$2:$K$101,0),"")="",B21=""),"",IFERROR(INDEX('CONTRACT CALC'!$H$13:$H$112,IFERROR(MATCH(TEXT($B$10,"yyyymmdd")&"|"&$E$10&"|4",'EVENT ASSIGNMENT'!$K$2:$K$101,0),""))*INDEX('CONTRACT CALC'!$F$13:$F$112,IFERROR(MATCH(TEXT($B$10,"yyyymmdd")&"|"&$E$10&"|4",'EVENT ASSIGNMENT'!$K$2:$K$101,0),"")),"")) | G21: =IF(F21="","",F21*'CONTRACT CALC'!$B$5) | H21: =IF(B21="","",N(E21)+N(G21)) | I21: =IF(OR(IFERROR(MATCH(TEXT($B$10,"yyyymmdd")&"|"&$E$10&"|4",'EVENT ASSIGNMENT'!$K$2:$K$101,0),"")="",B21=""),"",IF(COUNTIFS('TIPS DATA'!$A$2:$A$101,$B$10,'TIPS DATA'!$C$2:$C$101,$E$10,'TIPS DATA'!$D$2:$D$101,INDEX('EVENT ASSIGNMENT'!$C$2:$C$101,IFERROR(MATCH(TEXT($B$10,"yyyymmdd")&"|"&$E$10&"|4",'EVENT ASSIGNMENT'!$K$2:$K$101,0),"")))>0,SUMIFS('TIPS DATA'!$H$2:$H$101,'TIPS DATA'!$A$2:$A$101,$B$10,'TIPS DATA'!$C$2:$C$101,$E$10,'TIPS DATA'!$D$2:$D$101,INDEX('EVENT ASSIGNMENT'!$C$2:$C$101,IFERROR(MATCH(TEXT($B$10,"yyyymmdd")&"|"&$E$10&"|4",'EVENT ASSIGNMENT'!$K$2:$K$101,0),""))),SUMIFS('TIPS DATA'!$H$2:$H$101,'TIPS DATA'!$A$2:$A$101,$B$10,'TIPS DATA'!$C$2:$C$101,$E$10,'TIPS DATA'!$E$2:$E$101,INDEX('EVENT ASSIGNMENT'!$D$2:$D$101,IFERROR(MATCH(TEXT($B$10,"yyyymmdd")&"|"&$E$10&"|4",'EVENT ASSIGNMENT'!$K$2:$K$101,0),"")))))
A22: =IFERROR(MATCH(TEXT($B$10,"yyyymmdd")&"|"&$E$10&"|5",'EVENT ASSIGNMENT'!$K$2:$K$101,0),"") | B22: =IF(IFERROR(MATCH(TEXT($B$10,"yyyymmdd")&"|"&$E$10&"|5",'EVENT ASSIGNMENT'!$K$2:$K$101,0),"")="","",IFERROR(INDEX('EVENT ASSIGNMENT'!$D$2:$D$101,IFERROR(MATCH(TEXT($B$10,"yyyymmdd")&"|"&$E$10&"|5",'EVENT ASSIGNMENT'!$K$2:$K$101,0),"")),"")) | C22: =IF(OR(IFERROR(MATCH(TEXT($B$10,"yyyymmdd")&"|"&$E$10&"|5",'EVENT ASSIGNMENT'!$K$2:$K$101,0),"")="",B22=""),"",IFERROR(INDEX('CONTRACT CALC'!$G$13:$G$112,IFERROR(MATCH(TEXT($B$10,"yyyymmdd")&"|"&$E$10&"|5",'EVENT ASSIGNMENT'!$K$2:$K$101,0),""))*INDEX('CONTRACT CALC'!$F$13:$F$112,IFERROR(MATCH(TEXT($B$10,"yyyymmdd")&"|"&$E$10&"|5",'EVENT ASSIGNMENT'!$K$2:$K$101,0),"")),"")) | D22: =IF(OR(IFERROR(MATCH(TEXT($B$10,"yyyymmdd")&"|"&$E$10&"|5",'EVENT ASSIGNMENT'!$K$2:$K$101,0),"")="",B22=""),"",IFERROR(INDEX('CONTRACT CALC'!$I$13:$I$112,IFERROR(MATCH(TEXT($B$10,"yyyymmdd")&"|"&$E$10&"|5",'EVENT ASSIGNMENT'!$K$2:$K$101,0),""))*INDEX('CONTRACT CALC'!$F$13:$F$112,IFERROR(MATCH(TEXT($B$10,"yyyymmdd")&"|"&$E$10&"|5",'EVENT ASSIGNMENT'!$K$2:$K$101,0),"")),"")) | E22: =IF(D22="","",D22*'CONTRACT CALC'!$B$4) | F22: =IF(OR(IFERROR(MATCH(TEXT($B$10,"yyyymmdd")&"|"&$E$10&"|5",'EVENT ASSIGNMENT'!$K$2:$K$101,0),"")="",B22=""),"",IFERROR(INDEX('CONTRACT CALC'!$H$13:$H$112,IFERROR(MATCH(TEXT($B$10,"yyyymmdd")&"|"&$E$10&"|5",'EVENT ASSIGNMENT'!$K$2:$K$101,0),""))*INDEX('CONTRACT CALC'!$F$13:$F$112,IFERROR(MATCH(TEXT($B$10,"yyyymmdd")&"|"&$E$10&"|5",'EVENT ASSIGNMENT'!$K$2:$K$101,0),"")),"")) | G22: =IF(F22="","",F22*'CONTRACT CALC'!$B$5) | H22: =IF(B22="","",N(E22)+N(G22)) | I22: =IF(OR(IFERROR(MATCH(TEXT($B$10,"yyyymmdd")&"|"&$E$10&"|5",'EVENT ASSIGNMENT'!$K$2:$K$101,0),"")="",B22=""),"",IF(COUNTIFS('TIPS DATA'!$A$2:$A$101,$B$10,'TIPS DATA'!$C$2:$C$101,$E$10,'TIPS DATA'!$D$2:$D$101,INDEX('EVENT ASSIGNMENT'!$C$2:$C$101,IFERROR(MATCH(TEXT($B$10,"yyyymmdd")&"|"&$E$10&"|5",'EVENT ASSIGNMENT'!$K$2:$K$101,0),"")))>0,SUMIFS('TIPS DATA'!$H$2:$H$101,'TIPS DATA'!$A$2:$A$101,$B$10,'TIPS DATA'!$C$2:$C$101,$E$10,'TIPS DATA'!$D$2:$D$101,INDEX('EVENT ASSIGNMENT'!$C$2:$C$101,IFERROR(MATCH(TEXT($B$10,"yyyymmdd")&"|"&$E$10&"|5",'EVENT ASSIGNMENT'!$K$2:$K$101,0),""))),SUMIFS('TIPS DATA'!$H$2:$H$101,'TIPS DATA'!$A$2:$A$101,$B$10,'TIPS DATA'!$C$2:$C$101,$E$10,'TIPS DATA'!$E$2:$E$101,INDEX('EVENT ASSIGNMENT'!$D$2:$D$101,IFERROR(MATCH(TEXT($B$10,"yyyymmdd")&"|"&$E$10&"|5",'EVENT ASSIGNMENT'!$K$2:$K$101,0),"")))))
A23: =IFERROR(MATCH(TEXT($B$10,"yyyymmdd")&"|"&$E$10&"|6",'EVENT ASSIGNMENT'!$K$2:$K$101,0),"") | B23: =IF(IFERROR(MATCH(TEXT($B$10,"yyyymmdd")&"|"&$E$10&"|6",'EVENT ASSIGNMENT'!$K$2:$K$101,0),"")="","",IFERROR(INDEX('EVENT ASSIGNMENT'!$D$2:$D$101,IFERROR(MATCH(TEXT($B$10,"yyyymmdd")&"|"&$E$10&"|6",'EVENT ASSIGNMENT'!$K$2:$K$101,0),"")),"")) | C23: =IF(OR(IFERROR(MATCH(TEXT($B$10,"yyyymmdd")&"|"&$E$10&"|6",'EVENT ASSIGNMENT'!$K$2:$K$101,0),"")="",B23=""),"",IFERROR(INDEX('CONTRACT CALC'!$G$13:$G$112,IFERROR(MATCH(TEXT($B$10,"yyyymmdd")&"|"&$E$10&"|6",'EVENT ASSIGNMENT'!$K$2:$K$101,0),""))*INDEX('CONTRACT CALC'!$F$13:$F$112,IFERROR(MATCH(TEXT($B$10,"yyyymmdd")&"|"&$E$10&"|6",'EVENT ASSIGNMENT'!$K$2:$K$101,0),"")),"")) | D23: =IF(OR(IFERROR(MATCH(TEXT($B$10,"yyyymmdd")&"|"&$E$10&"|6",'EVENT ASSIGNMENT'!$K$2:$K$101,0),"")="",B23=""),"",IFERROR(INDEX('CONTRACT CALC'!$I$13:$I$112,IFERROR(MATCH(TEXT($B$10,"yyyymmdd")&"|"&$E$10&"|6",'EVENT ASSIGNMENT'!$K$2:$K$101,0),""))*INDEX('CONTRACT CALC'!$F$13:$F$112,IFERROR(MATCH(TEXT($B$10,"yyyymmdd")&"|"&$E$10&"|6",'EVENT ASSIGNMENT'!$K$2:$K$101,0),"")),"")) | E23: =IF(D23="","",D23*'CONTRACT CALC'!$B$4) | F23: =IF(OR(IFERROR(MATCH(TEXT($B$10,"yyyymmdd")&"|"&$E$10&"|6",'EVENT ASSIGNMENT'!$K$2:$K$101,0),"")="",B23=""),"",IFERROR(INDEX('CONTRACT CALC'!$H$13:$H$112,IFERROR(MATCH(TEXT($B$10,"yyyymmdd")&"|"&$E$10&"|6",'EVENT ASSIGNMENT'!$K$2:$K$101,0),""))*INDEX('CONTRACT CALC'!$F$13:$F$112,IFERROR(MATCH(TEXT($B$10,"yyyymmdd")&"|"&$E$10&"|6",'EVENT ASSIGNMENT'!$K$2:$K$101,0),"")),"")) | G23: =IF(F23="","",F23*'CONTRACT CALC'!$B$5) | H23: =IF(B23="","",N(E23)+N(G23)) | I23: =IF(OR(IFERROR(MATCH(TEXT($B$10,"yyyymmdd")&"|"&$E$10&"|6",'EVENT ASSIGNMENT'!$K$2:$K$101,0),"")="",B23=""),"",IF(COUNTIFS('TIPS DATA'!$A$2:$A$101,$B$10,'TIPS DATA'!$C$2:$C$101,$E$10,'TIPS DATA'!$D$2:$D$101,INDEX('EVENT ASSIGNMENT'!$C$2:$C$101,IFERROR(MATCH(TEXT($B$10,"yyyymmdd")&"|"&$E$10&"|6",'EVENT ASSIGNMENT'!$K$2:$K$101,0),"")))>0,SUMIFS('TIPS DATA'!$H$2:$H$101,'TIPS DATA'!$A$2:$A$101,$B$10,'TIPS DATA'!$C$2:$C$101,$E$10,'TIPS DATA'!$D$2:$D$101,INDEX('EVENT ASSIGNMENT'!$C$2:$C$101,IFERROR(MATCH(TEXT($B$10,"yyyymmdd")&"|"&$E$10&"|6",'EVENT ASSIGNMENT'!$K$2:$K$101,0),""))),SUMIFS('TIPS DATA'!$H$2:$H$101,'TIPS DATA'!$A$2:$A$101,$B$10,'TIPS DATA'!$C$2:$C$101,$E$10,'TIPS DATA'!$E$2:$E$101,INDEX('EVENT ASSIGNMENT'!$D$2:$D$101,IFERROR(MATCH(TEXT($B$10,"yyyymmdd")&"|"&$E$10&"|6",'EVENT ASSIGNMENT'!$K$2:$K$101,0),"")))))
A24: =IFERROR(MATCH(TEXT($B$10,"yyyymmdd")&"|"&$E$10&"|7",'EVENT ASSIGNMENT'!$K$2:$K$101,0),"") | B24: =IF(IFERROR(MATCH(TEXT($B$10,"yyyymmdd")&"|"&$E$10&"|7",'EVENT ASSIGNMENT'!$K$2:$K$101,0),"")="","",IFERROR(INDEX('EVENT ASSIGNMENT'!$D$2:$D$101,IFERROR(MATCH(TEXT($B$10,"yyyymmdd")&"|"&$E$10&"|7",'EVENT ASSIGNMENT'!$K$2:$K$101,0),"")),"")) | C24: =IF(OR(IFERROR(MATCH(TEXT($B$10,"yyyymmdd")&"|"&$E$10&"|7",'EVENT ASSIGNMENT'!$K$2:$K$101,0),"")="",B24=""),"",IFERROR(INDEX('CONTRACT CALC'!$G$13:$G$112,IFERROR(MATCH(TEXT($B$10,"yyyymmdd")&"|"&$E$10&"|7",'EVENT ASSIGNMENT'!$K$2:$K$101,0),""))*INDEX('CONTRACT CALC'!$F$13:$F$112,IFERROR(MATCH(TEXT($B$10,"yyyymmdd")&"|"&$E$10&"|7",'EVENT ASSIGNMENT'!$K$2:$K$101,0),"")),"")) | D24: =IF(OR(IFERROR(MATCH(TEXT($B$10,"yyyymmdd")&"|"&$E$10&"|7",'EVENT ASSIGNMENT'!$K$2:$K$101,0),"")="",B24=""),"",IFERROR(INDEX('CONTRACT CALC'!$I$13:$I$112,IFERROR(MATCH(TEXT($B$10,"yyyymmdd")&"|"&$E$10&"|7",'EVENT ASSIGNMENT'!$K$2:$K$101,0),""))*INDEX('CONTRACT CALC'!$F$13:$F$112,IFERROR(MATCH(TEXT($B$10,"yyyymmdd")&"|"&$E$10&"|7",'EVENT ASSIGNMENT'!$K$2:$K$101,0),"")),"")) | E24: =IF(D24="","",D24*'CONTRACT CALC'!$B$4) | F24: =IF(OR(IFERROR(MATCH(TEXT($B$10,"yyyymmdd")&"|"&$E$10&"|7",'EVENT ASSIGNMENT'!$K$2:$K$101,0),"")="",B24=""),"",IFERROR(INDEX('CONTRACT CALC'!$H$13:$H$112,IFERROR(MATCH(TEXT($B$10,"yyyymmdd")&"|"&$E$10&"|7",'EVENT ASSIGNMENT'!$K$2:$K$101,0),""))*INDEX('CONTRACT CALC'!$F$13:$F$112,IFERROR(MATCH(TEXT($B$10,"yyyymmdd")&"|"&$E$10&"|7",'EVENT ASSIGNMENT'!$K$2:$K$101,0),"")),"")) | G24: =IF(F24="","",F24*'CONTRACT CALC'!$B$5) | H24: =IF(B24="","",N(E24)+N(G24)) | I24: =IF(OR(IFERROR(MATCH(TEXT($B$10,"yyyymmdd")&"|"&$E$10&"|7",'EVENT ASSIGNMENT'!$K$2:$K$101,0),"")="",B24=""),"",IF(COUNTIFS('TIPS DATA'!$A$2:$A$101,$B$10,'TIPS DATA'!$C$2:$C$101,$E$10,'TIPS DATA'!$D$2:$D$101,INDEX('EVENT ASSIGNMENT'!$C$2:$C$101,IFERROR(MATCH(TEXT($B$10,"yyyymmdd")&"|"&$E$10&"|7",'EVENT ASSIGNMENT'!$K$2:$K$101,0),"")))>0,SUMIFS('TIPS DATA'!$H$2:$H$101,'TIPS DATA'!$A$2:$A$101,$B$10,'TIPS DATA'!$C$2:$C$101,$E$10,'TIPS DATA'!$D$2:$D$101,INDEX('EVENT ASSIGNMENT'!$C$2:$C$101,IFERROR(MATCH(TEXT($B$10,"yyyymmdd")&"|"&$E$10&"|7",'EVENT ASSIGNMENT'!$K$2:$K$101,0),""))),SUMIFS('TIPS DATA'!$H$2:$H$101,'TIPS DATA'!$A$2:$A$101,$B$10,'TIPS DATA'!$C$2:$C$101,$E$10,'TIPS DATA'!$E$2:$E$101,INDEX('EVENT ASSIGNMENT'!$D$2:$D$101,IFERROR(MATCH(TEXT($B$10,"yyyymmdd")&"|"&$E$10&"|7",'EVENT ASSIGNMENT'!$K$2:$K$101,0),"")))))
A25: =IFERROR(MATCH(TEXT($B$10,"yyyymmdd")&"|"&$E$10&"|8",'EVENT ASSIGNMENT'!$K$2:$K$101,0),"") | B25: =IF(IFERROR(MATCH(TEXT($B$10,"yyyymmdd")&"|"&$E$10&"|8",'EVENT ASSIGNMENT'!$K$2:$K$101,0),"")="","",IFERROR(INDEX('EVENT ASSIGNMENT'!$D$2:$D$101,IFERROR(MATCH(TEXT($B$10,"yyyymmdd")&"|"&$E$10&"|8",'EVENT ASSIGNMENT'!$K$2:$K$101,0),"")),"")) | C25: =IF(OR(IFERROR(MATCH(TEXT($B$10,"yyyymmdd")&"|"&$E$10&"|8",'EVENT ASSIGNMENT'!$K$2:$K$101,0),"")="",B25=""),"",IFERROR(INDEX('CONTRACT CALC'!$G$13:$G$112,IFERROR(MATCH(TEXT($B$10,"yyyymmdd")&"|"&$E$10&"|8",'EVENT ASSIGNMENT'!$K$2:$K$101,0),""))*INDEX('CONTRACT CALC'!$F$13:$F$112,IFERROR(MATCH(TEXT($B$10,"yyyymmdd")&"|"&$E$10&"|8",'EVENT ASSIGNMENT'!$K$2:$K$101,0),"")),"")) | D25: =IF(OR(IFERROR(MATCH(TEXT($B$10,"yyyymmdd")&"|"&$E$10&"|8",'EVENT ASSIGNMENT'!$K$2:$K$101,0),"")="",B25=""),"",IFERROR(INDEX('CONTRACT CALC'!$I$13:$I$112,IFERROR(MATCH(TEXT($B$10,"yyyymmdd")&"|"&$E$10&"|8",'EVENT ASSIGNMENT'!$K$2:$K$101,0),""))*INDEX('CONTRACT CALC'!$F$13:$F$112,IFERROR(MATCH(TEXT($B$10,"yyyymmdd")&"|"&$E$10&"|8",'EVENT ASSIGNMENT'!$K$2:$K$101,0),"")),"")) | E25: =IF(D25="","",D25*'CONTRACT CALC'!$B$4) | F25: =IF(OR(IFERROR(MATCH(TEXT($B$10,"yyyymmdd")&"|"&$E$10&"|8",'EVENT ASSIGNMENT'!$K$2:$K$101,0),"")="",B25=""),"",IFERROR(INDEX('CONTRACT CALC'!$H$13:$H$112,IFERROR(MATCH(TEXT($B$10,"yyyymmdd")&"|"&$E$10&"|8",'EVENT ASSIGNMENT'!$K$2:$K$101,0),""))*INDEX('CONTRACT CALC'!$F$13:$F$112,IFERROR(MATCH(TEXT($B$10,"yyyymmdd")&"|"&$E$10&"|8",'EVENT ASSIGNMENT'!$K$2:$K$101,0),"")),"")) | G25: =IF(F25="","",F25*'CONTRACT CALC'!$B$5) | H25: =IF(B25="","",N(E25)+N(G25)) | I25: =IF(OR(IFERROR(MATCH(TEXT($B$10,"yyyymmdd")&"|"&$E$10&"|8",'EVENT ASSIGNMENT'!$K$2:$K$101,0),"")="",B25=""),"",IF(COUNTIFS('TIPS DATA'!$A$2:$A$101,$B$10,'TIPS DATA'!$C$2:$C$101,$E$10,'TIPS DATA'!$D$2:$D$101,INDEX('EVENT ASSIGNMENT'!$C$2:$C$101,IFERROR(MATCH(TEXT($B$10,"yyyymmdd")&"|"&$E$10&"|8",'EVENT ASSIGNMENT'!$K$2:$K$101,0),"")))>0,SUMIFS('TIPS DATA'!$H$2:$H$101,'TIPS DATA'!$A$2:$A$101,$B$10,'TIPS DATA'!$C$2:$C$101,$E$10,'TIPS DATA'!$D$2:$D$101,INDEX('EVENT ASSIGNMENT'!$C$2:$C$101,IFERROR(MATCH(TEXT($B$10,"yyyymmdd")&"|"&$E$10&"|8",'EVENT ASSIGNMENT'!$K$2:$K$101,0),""))),SUMIFS('TIPS DATA'!$H$2:$H$101,'TIPS DATA'!$A$2:$A$101,$B$10,'TIPS DATA'!$C$2:$C$101,$E$10,'TIPS DATA'!$E$2:$E$101,INDEX('EVENT ASSIGNMENT'!$D$2:$D$101,IFERROR(MATCH(TEXT($B$10,"yyyymmdd")&"|"&$E$10&"|8",'EVENT ASSIGNMENT'!$K$2:$K$101,0),"")))))
A26: =IFERROR(MATCH(TEXT($B$10,"yyyymmdd")&"|"&$E$10&"|9",'EVENT ASSIGNMENT'!$K$2:$K$101,0),"") | B26: =IF(IFERROR(MATCH(TEXT($B$10,"yyyymmdd")&"|"&$E$10&"|9",'EVENT ASSIGNMENT'!$K$2:$K$101,0),"")="","",IFERROR(INDEX('EVENT ASSIGNMENT'!$D$2:$D$101,IFERROR(MATCH(TEXT($B$10,"yyyymmdd")&"|"&$E$10&"|9",'EVENT ASSIGNMENT'!$K$2:$K$101,0),"")),"")) | C26: =IF(OR(IFERROR(MATCH(TEXT($B$10,"yyyymmdd")&"|"&$E$10&"|9",'EVENT ASSIGNMENT'!$K$2:$K$101,0),"")="",B26=""),"",IFERROR(INDEX('CONTRACT CALC'!$G$13:$G$112,IFERROR(MATCH(TEXT($B$10,"yyyymmdd")&"|"&$E$10&"|9",'EVENT ASSIGNMENT'!$K$2:$K$101,0),""))*INDEX('CONTRACT CALC'!$F$13:$F$112,IFERROR(MATCH(TEXT($B$10,"yyyymmdd")&"|"&$E$10&"|9",'EVENT ASSIGNMENT'!$K$2:$K$101,0),"")),"")) | D26: =IF(OR(IFERROR(MATCH(TEXT($B$10,"yyyymmdd")&"|"&$E$10&"|9",'EVENT ASSIGNMENT'!$K$2:$K$101,0),"")="",B26=""),"",IFERROR(INDEX('CONTRACT CALC'!$I$13:$I$112,IFERROR(MATCH(TEXT($B$10,"yyyymmdd")&"|"&$E$10&"|9",'EVENT ASSIGNMENT'!$K$2:$K$101,0),""))*INDEX('CONTRACT CALC'!$F$13:$F$112,IFERROR(MATCH(TEXT($B$10,"yyyymmdd")&"|"&$E$10&"|9",'EVENT ASSIGNMENT'!$K$2:$K$101,0),"")),"")) | E26: =IF(D26="","",D26*'CONTRACT CALC'!$B$4) | F26: =IF(OR(IFERROR(MATCH(TEXT($B$10,"yyyymmdd")&"|"&$E$10&"|9",'EVENT ASSIGNMENT'!$K$2:$K$101,0),"")="",B26=""),"",IFERROR(INDEX('CONTRACT CALC'!$H$13:$H$112,IFERROR(MATCH(TEXT($B$10,"yyyymmdd")&"|"&$E$10&"|9",'EVENT ASSIGNMENT'!$K$2:$K$101,0),""))*INDEX('CONTRACT CALC'!$F$13:$F$112,IFERROR(MATCH(TEXT($B$10,"yyyymmdd")&"|"&$E$10&"|9",'EVENT ASSIGNMENT'!$K$2:$K$101,0),"")),"")) | G26: =IF(F26="","",F26*'CONTRACT CALC'!$B$5) | H26: =IF(B26="","",N(E26)+N(G26)) | I26: =IF(OR(IFERROR(MATCH(TEXT($B$10,"yyyymmdd")&"|"&$E$10&"|9",'EVENT ASSIGNMENT'!$K$2:$K$101,0),"")="",B26=""),"",IF(COUNTIFS('TIPS DATA'!$A$2:$A$101,$B$10,'TIPS DATA'!$C$2:$C$101,$E$10,'TIPS DATA'!$D$2:$D$101,INDEX('EVENT ASSIGNMENT'!$C$2:$C$101,IFERROR(MATCH(TEXT($B$10,"yyyymmdd")&"|"&$E$10&"|9",'EVENT ASSIGNMENT'!$K$2:$K$101,0),"")))>0,SUMIFS('TIPS DATA'!$H$2:$H$101,'TIPS DATA'!$A$2:$A$101,$B$10,'TIPS DATA'!$C$2:$C$101,$E$10,'TIPS DATA'!$D$2:$D$101,INDEX('EVENT ASSIGNMENT'!$C$2:$C$101,IFERROR(MATCH(TEXT($B$10,"yyyymmdd")&"|"&$E$10&"|9",'EVENT ASSIGNMENT'!$K$2:$K$101,0),""))),SUMIFS('TIPS DATA'!$H$2:$H$101,'TIPS DATA'!$A$2:$A$101,$B$10,'TIPS DATA'!$C$2:$C$101,$E$10,'TIPS DATA'!$E$2:$E$101,INDEX('EVENT ASSIGNMENT'!$D$2:$D$101,IFERROR(MATCH(TEXT($B$10,"yyyymmdd")&"|"&$E$10&"|9",'EVENT ASSIGNMENT'!$K$2:$K$101,0),"")))))
A27: =IFERROR(MATCH(TEXT($B$10,"yyyymmdd")&"|"&$E$10&"|10",'EVENT ASSIGNMENT'!$K$2:$K$101,0),"") | B27: =IF(IFERROR(MATCH(TEXT($B$10,"yyyymmdd")&"|"&$E$10&"|10",'EVENT ASSIGNMENT'!$K$2:$K$101,0),"")="","",IFERROR(INDEX('EVENT ASSIGNMENT'!$D$2:$D$101,IFERROR(MATCH(TEXT($B$10,"yyyymmdd")&"|"&$E$10&"|10",'EVENT ASSIGNMENT'!$K$2:$K$101,0),"")),"")) | C27: =IF(OR(IFERROR(MATCH(TEXT($B$10,"yyyymmdd")&"|"&$E$10&"|10",'EVENT ASSIGNMENT'!$K$2:$K$101,0),"")="",B27=""),"",IFERROR(INDEX('CONTRACT CALC'!$G$13:$G$112,IFERROR(MATCH(TEXT($B$10,"yyyymmdd")&"|"&$E$10&"|10",'EVENT ASSIGNMENT'!$K$2:$K$101,0),""))*INDEX('CONTRACT CALC'!$F$13:$F$112,IFERROR(MATCH(TEXT($B$10,"yyyymmdd")&"|"&$E$10&"|10",'EVENT ASSIGNMENT'!$K$2:$K$101,0),"")),"")) | D27: =IF(OR(IFERROR(MATCH(TEXT($B$10,"yyyymmdd")&"|"&$E$10&"|10",'EVENT ASSIGNMENT'!$K$2:$K$101,0),"")="",B27=""),"",IFERROR(INDEX('CONTRACT CALC'!$I$13:$I$112,IFERROR(MATCH(TEXT($B$10,"yyyymmdd")&"|"&$E$10&"|10",'EVENT ASSIGNMENT'!$K$2:$K$101,0),""))*INDEX('CONTRACT CALC'!$F$13:$F$112,IFERROR(MATCH(TEXT($B$10,"yyyymmdd")&"|"&$E$10&"|10",'EVENT ASSIGNMENT'!$K$2:$K$101,0),"")),"")) | E27: =IF(D27="","",D27*'CONTRACT CALC'!$B$4) | F27: =IF(OR(IFERROR(MATCH(TEXT($B$10,"yyyymmdd")&"|"&$E$10&"|10",'EVENT ASSIGNMENT'!$K$2:$K$101,0),"")="",B27=""),"",IFERROR(INDEX('CONTRACT CALC'!$H$13:$H$112,IFERROR(MATCH(TEXT($B$10,"yyyymmdd")&"|"&$E$10&"|10",'EVENT ASSIGNMENT'!$K$2:$K$101,0),""))*INDEX('CONTRACT CALC'!$F$13:$F$112,IFERROR(MATCH(TEXT($B$10,"yyyymmdd")&"|"&$E$10&"|10",'EVENT ASSIGNMENT'!$K$2:$K$101,0),"")),"")) | G27: =IF(F27="","",F27*'CONTRACT CALC'!$B$5) | H27: =IF(B27="","",N(E27)+N(G27)) | I27: =IF(OR(IFERROR(MATCH(TEXT($B$10,"yyyymmdd")&"|"&$E$10&"|10",'EVENT ASSIGNMENT'!$K$2:$K$101,0),"")="",B27=""),"",IF(COUNTIFS('TIPS DATA'!$A$2:$A$101,$B$10,'TIPS DATA'!$C$2:$C$101,$E$10,'TIPS DATA'!$D$2:$D$101,INDEX('EVENT ASSIGNMENT'!$C$2:$C$101,IFERROR(MATCH(TEXT($B$10,"yyyymmdd")&"|"&$E$10&"|10",'EVENT ASSIGNMENT'!$K$2:$K$101,0),"")))>0,SUMIFS('TIPS DATA'!$H$2:$H$101,'TIPS DATA'!$A$2:$A$101,$B$10,'TIPS DATA'!$C$2:$C$101,$E$10,'TIPS DATA'!$D$2:$D$101,INDEX('EVENT ASSIGNMENT'!$C$2:$C$101,IFERROR(MATCH(TEXT($B$10,"yyyymmdd")&"|"&$E$10&"|10",'EVENT ASSIGNMENT'!$K$2:$K$101,0),""))),SUMIFS('TIPS DATA'!$H$2:$H$101,'TIPS DATA'!$A$2:$A$101,$B$10,'TIPS DATA'!$C$2:$C$101,$E$10,'TIPS DATA'!$E$2:$E$101,INDEX('EVENT ASSIGNMENT'!$D$2:$D$101,IFERROR(MATCH(TEXT($B$10,"yyyymmdd")&"|"&$E$10&"|10",'EVENT ASSIGNMENT'!$K$2:$K$101,0),"")))))
B28: TOTAL | C28: =SUM(C18:C27) | D28: =SUM(D18:D27) | E28: =SUM(E18:E27) | F28: =SUM(F18:F27) | G28: =SUM(G18:G27) | H28: =SUM(H18:H27) | I28: =SUM(I18:I27)
B29: Max 10 locations per payee. Rows filter from EVENT ASSIGNMENT / CONTRACT CALC by Event Date + Payee. Location Total = Contractual Donation + Gratuities.
G30: SUPPLEMENTAL PAYOUT | H30: THIS STATEMENT (edit for PDF) | I30: SAVED REF (SUPPLEMENTAL DATA)
B31: SETTLEMENT NOTES (this document — edit freely before PDF) | G31: Sales Incentive | H31: 0 | I31: =IFERROR(SUMIFS('SUPPLEMENTAL DATA'!$C$2:$C$101,'SUPPLEMENTAL DATA'!$A$2:$A$101,$B$10,'SUPPLEMENTAL DATA'!$B$2:$B$101,$E$10),0)
G32: Culinary - Cook Fee | H32: 0 | I32: =IFERROR(SUMIFS('SUPPLEMENTAL DATA'!$D$2:$D$101,'SUPPLEMENTAL DATA'!$A$2:$A$101,$B$10,'SUPPLEMENTAL DATA'!$B$2:$B$101,$E$10),0)
G33: Minimum Donation | H33: 0 | I33: =IFERROR(SUMIFS('SUPPLEMENTAL DATA'!$E$2:$E$101,'SUPPLEMENTAL DATA'!$A$2:$A$101,$B$10,'SUPPLEMENTAL DATA'!$B$2:$B$101,$E$10),0)
G34: Bonus (Other) | H34: 0 | I34: =IFERROR(SUMIFS('SUPPLEMENTAL DATA'!$F$2:$F$101,'SUPPLEMENTAL DATA'!$A$2:$A$101,$B$10,'SUPPLEMENTAL DATA'!$B$2:$B$101,$E$10),0)
G35: Deductible POS Shortages | H35: 0 | I35: =IFERROR(SUMIFS('SUPPLEMENTAL DATA'!$G$2:$G$101,'SUPPLEMENTAL DATA'!$A$2:$A$101,$B$10,'SUPPLEMENTAL DATA'!$B$2:$B$101,$E$10),0)
G36: Uniform / Staffing / Cleaning Fees | H36: 0 | I36: =IFERROR(SUMIFS('SUPPLEMENTAL DATA'!$H$2:$H$101,'SUPPLEMENTAL DATA'!$A$2:$A$101,$B$10,'SUPPLEMENTAL DATA'!$B$2:$B$101,$E$10),0)
H37: Statement supplemental total → | I37: =SUM(H31:H36)
B38: Tip: yellow H31:H36 + notes = this statement only. Grey I31:I36 = saved for Event+Payee. After PDF, zero H31:H36 before the next vendor — or copy H into SUPPLEMENTAL DATA to remember.
B40: INTERNAL AUTHORIZATION CHECK REQUEST | E40: INTERNAL - ACCOUNTING GL ENTRY - SUMMARY
B41: Abigail Tenorio | C41: =TODAY() | E41: Group Commission | F41: 241 | 36127 | GL:611225 | G41: =H28
B42: Concessions Manager | E42: Gratuities | F42: 241 | 36127 | GL:212113 | G42: =I28
B43: Ray Velasquez | C43: =TODAY() | E43: Misc. (to be reclassed) | F43: 241 | 36127 | GL:673000 | G43: =SUM(H31:H35)
B44: Director of Operations | E44: Cleaning Fee - Expense | F44: 241 | 36127 | GL:674102 | G44: =H36
B45: Evan E. Gonzales | C45: =TODAY()
...

Sheet MSR RAW
A1: | Price Level - CATEGORIES - MSR Data Export | R1: University of New Mexico (2LEVY@UNM)
U2: 7.6250%
A3: Event:UNM FOOTBALL GAME 1 - 9/5 (252) Start Date:09/05/26 5:00:00 PM End Date:09/05/26 11:55:51 PM Discount Source:Default Price Level Detail Level:Summary
A4: Product | F4: Tax | W4: gap
A5: Code | D5: Name | E5: Standard Price | F5: Inclusive | H5: Exclusive | J5: SC | M5: Discount | O5: Quantity | Q5: Gross Amt | T5: Net
A6: Department: 36127 - CONCESSIONS
B7: Location: FB 100 - TRAILER N CONCOURSE
C8: Total: | F8: 0.00 | G8: 0.11 | I8: 0 | L8: 0.00 | N8: 226.00 | P8: 0.11 | S8: 0.00
C9: 312115 - N/A BEVERAGE SALES - TAXABLE Total: | F9: 0.00 | G9: 165.23 | I9: 0 | L9: 328.00 | N9: 380.00 | P9: 2,332.23 | S9: 2,167.00
C10: 313000 - FOOD SALES - TAXABLE Total: | F10: 0.00 | G10: 244.84 | I10: 0 | L10: 0.00 | N10: 234.00 | P10: 3,455.84 | S10: 3,211.00
C11: 313004 - LIQUOR SALES - TAXABLE Total: | F11: 0.00 | G11: 25.62 | I11: 0 | L11: 0.00 | N11: 21.00 | P11: 361.62 | S11: 336.00
C12: 313082 - BEER PACKAGED SALES Total: | F12: 0.00 | G12: 74.76 | I12: 0 | L12: -10.00 | N12: 74.00 | P12: 1,055.26 | S12: 980.50
B13: FB 100 - TRAILER N CONCOURSE Total: | F13: 0.00 | G13: 510.57 | I13: 0 | L13: 318.00 | N13: 935.00 | P13: 7,205.07 | S13: 6,694.50
B14: Location: FB 100B - MBP TRAILER N CONCOURSE
C15: Total: | F15: 0.00 | G15: 0.18 | I15: 0 | L15: 0.00 | N15: 242.00 | P15: 0.18 | S15: 0.00
C16: 312115 - N/A BEVERAGE SALES - TAXABLE Total: | F16: 0.00 | G16: 52.46 | I16: 0 | L16: 344.00 | N16: 172.00 | P16: 740.46 | S16: 688.00
C17: 313004 - LIQUOR SALES - TAXABLE Total: | F17: 0.00 | G17: 173.24 | I17: 0 | L17: 0.00 | N17: 142.00 | P17: 2,445.24 | S17: 2,272.00
C18: 313082 - BEER PACKAGED SALES Total: | F18: 0.00 | G18: 355.78 | I18: 0 | L18: 0.00 | N18: 365.00 | P18: 5,021.78 | S18: 4,666.00
B19: FB 100B - MBP TRAILER N CONCOURSE Total: | F19: 0.00 | G19: 581.66 | I19: 0 | L19: 344.00 | N19: 921.00 | P19: 8,207.66 | S19: 7,626.00
B20: Location: FB 101 - STADIUM SIPS SHACK SW
C21: Total: | F21: 0.00 | G21: 0.35 | I21: 0 | L21: 0.00 | N21: 319.00 | P21: 0.35 | S21: 0.00
C22: 312115 - N/A BEVERAGE SALES - TAXABLE Total: | F22: 0.00 | G22: 122.61 | I22: 0 | L22: 558.00 | N22: 279.00 | P22: 1,730.61 | S22: 1,608.00
C23: 313000 - FOOD SALES - TAXABLE Total: | F23: 0.00 | G23: 34.92 | I23: 0 | L23: 1.00 | N23: 129.00 | P23: 492.92 | S23: 458.00
C24: 313004 - LIQUOR SALES - TAXABLE Total: | F24: 0.00 | G24: 134.20 | I24: 0 | L24: 0.00 | N24: 110.00 | P24: 1,894.20 | S24: 1,760.00
C25: 313082 - BEER PACKAGED SALES Total: | F25: 0.00 | G25: 353.84 | I25: 0 | L25: 0.00 | N25: 351.00 | P25: 4,994.34 | S25: 4,640.50
C26: FF-312114 - N/A BEV SALE DISC. FAN FRIENDLY (CC36636) Total: | F26: 0.00 | G26: 58.26 | I26: 0 | L26: 0.00 | N26: 191.00 | P26: 822.26 | S26: 764.00
C27: FF-313076 - FOOD SALES DISC. FAN FRIENDLY (CC36636) Total: | F27: 0.00 | G27: 31.42 | I27: 0 | L27: 0.00 | N27: 103.00 | P27: 443.42 | S27: 412.00
B28: FB 101 - STADIUM SIPS SHACK SW Total: | F28: 0.00 | G28: 735.59 | I28: 0 | L28: 559.00 | N28: 1,482.00 | P28: 10,378.09 | S28: 9,642.50
B29: Location: FB 102 - TOWER SOUTH
C30: Total: | F30: 0.00 | G30: 0.30 | I30: 0 | L30: 0.00 | N30: 286.00 | P30: 0.30 | S30: 0.00
C31: 312115 - N/A BEVERAGE SALES - TAXABLE Total: | F31: 0.00 | G31: 97.75 | I31: 0 | L31: 308.00 | N31: 180.00 | P31: 1,379.75 | S31: 1,282.00
C32: 313000 - FOOD SALES - TAXABLE Total: | F32: 0.00 | G32: 155.70 | I32: 0 | L32: 57.00 | N32: 379.00 | P32: 2,197.70 | S32: 2,042.00
C33: 313004 - LIQUOR SALES - TAXABLE Total: | F33: 0.00 | G33: 37.82 | I33: 0 | L33: 0.00 | N33: 31.00 | P33: 533.82 | S33: 496.00
C34: 313082 - BEER PACKAGED SALES Total: | F34: 0.00 | G34: 141.33 | I34: 0 | L34: 0.00 | N34: 143.00 | P34: 1,994.83 | S34: 1,853.50
C35: FF-312114 - N/A BEV SALE DISC. FAN FRIENDLY (CC36636) Total: | F35: 0.00 | G35: 66.49 | I35: 0 | L35: 0.00 | N35: 218.00 | P35: 938.49 | S35: 872.00
C36: FF-313076 - FOOD SALES DISC. FAN FRIENDLY (CC36636) Total: | F36: 0.00 | G36: 56.12 | I36: 0 | L36: 368.00 | N36: 184.00 | P36: 792.12 | S36: 736.00
B37: FB 102 - TOWER SOUTH Total: | F37: 0.00 | G37: 555.51 | I37: 0 | L37: 733.00 | N37: 1,421.00 | P37: 7,837.01 | S37: 7,281.50
B38: Location: FB 103 - TOWER NORTH
C39: Total: | F39: 0.00 | G39: 0.29 | I39: 0 | L39: 0.00 | N39: 338.00 | P39: 0.29 | S39: 0.00
C40: 312115 - N/A BEVERAGE SALES - TAXABLE Total: | F40: 0.00 | G40: 92.11 | I40: 0 | L40: 288.00 | N40: 168.00 | P40: 1,300.11 | S40: 1,208.00
...

Sheet CATEGORY MAP
A1: MyVenue Product Code | B1: Contract Class | C1: Description / Rule | E1: REQUIRED
A2: 312115 | B2: FOOD/NON-ALC | C2: N/A BEVERAGE SALES - TAXABLE | E2: Maps MyVenue product codes → FOOD/NON-ALC vs ALCOHOL for CONTRACT CALC. Do not delete this sheet. Add new product codes here when MSR exports change. You can hide the tab if you want a cleaner workbook; keep the sheet in the file.
A3: 313000 | B3: FOOD/NON-ALC | C3: FOOD SALES - TAXABLE
A4: 313004 | B4: ALCOHOL | C4: LIQUOR SALES - TAXABLE
A5: 313082 | B5: ALCOHOL | C5: BEER PACKAGED SALES
A6: 313096 | B6: ALCOHOL | C6: WINE SALES - TAXABLE
A7: FF-312114 | B7: FOOD/NON-ALC | C7: Fan Friendly N/A beverage discount
A8: FF-313076 | B8: FOOD/NON-ALC | C8: Fan Friendly food discount
A9: 353008 | B9: FOOD/NON-ALC | C9: Subcontract income (food%)

Sheet MSR DATA
A1: Raw Row | B1: Event | C1: Department | D1: Location | E1: Product Code | F1: Product Name | G1: Contract Class | H1: Gross Amt | I1: Net
A2: 2 | B2: =IF('MSR RAW'!$A$3="","",'MSR RAW'!$A$3) | C2: =IF(LEFT(TRIM('MSR RAW'!A2),11)="Department:",TRIM('MSR RAW'!A2),"") | D2: =IF(LEFT(TRIM('MSR RAW'!B2),9)="Location:",TRIM(MID('MSR RAW'!B2,10,999)),"") | E2: =IF(AND(ISNUMBER(SEARCH(" - ",TRIM('MSR RAW'!C2))),RIGHT(TRIM('MSR RAW'!C2),6)="Total:"),LEFT(TRIM('MSR RAW'!C2),SEARCH(" - ",TRIM('MSR RAW'!C2))-1),"") | F2: =IF(E2="","",TRIM(MID(TRIM('MSR RAW'!C2),SEARCH(" - ",TRIM('MSR RAW'!C2))+3,LEN(TRIM('MSR RAW'!C2))-SEARCH(" - ",TRIM('MSR RAW'!C2))-9))) | G2: =IF(E2="","",IFERROR(VLOOKUP(E2,'CATEGORY MAP'!$A$2:$B$20,2,FALSE()),"REVIEW")) | H2: =IF(E2="","",IFERROR(VALUE(SUBSTITUTE('MSR RAW'!P2,",","")),0)) | I2: =IF(E2="","",IFERROR(VALUE(SUBSTITUTE('MSR RAW'!S2,",","")),0))
A3: 3 | B3: =IF('MSR RAW'!$A$3="","",'MSR RAW'!$A$3) | C3: =IF(LEFT(TRIM('MSR RAW'!A3),11)="Department:",TRIM('MSR RAW'!A3),C2) | D3: =IF(LEFT(TRIM('MSR RAW'!B3),9)="Location:",TRIM(MID('MSR RAW'!B3,10,999)),D2) | E3: =IF(AND(ISNUMBER(SEARCH(" - ",TRIM('MSR RAW'!C3))),RIGHT(TRIM('MSR RAW'!C3),6)="Total:"),LEFT(TRIM('MSR RAW'!C3),SEARCH(" - ",TRIM('MSR RAW'!C3))-1),"") | F3: =IF(E3="","",TRIM(MID(TRIM('MSR RAW'!C3),SEARCH(" - ",TRIM('MSR RAW'!C3))+3,LEN(TRIM('MSR RAW'!C3))-SEARCH(" - ",TRIM('MSR RAW'!C3))-9))) | G3: =IF(E3="","",IFERROR(VLOOKUP(E3,'CATEGORY MAP'!$A$2:$B$20,2,FALSE()),"REVIEW")) | H3: =IF(E3="","",IFERROR(VALUE(SUBSTITUTE('MSR RAW'!P3,",","")),0)) | I3: =IF(E3="","",IFERROR(VALUE(SUBSTITUTE('MSR RAW'!S3,",","")),0))
A4: 4 | B4: =IF('MSR RAW'!$A$3="","",'MSR RAW'!$A$3) | C4: =IF(LEFT(TRIM('MSR RAW'!A4),11)="Department:",TRIM('MSR RAW'!A4),C3) | D4: =IF(LEFT(TRIM('MSR RAW'!B4),9)="Location:",TRIM(MID('MSR RAW'!B4,10,999)),D3) | E4: =IF(AND(ISNUMBER(SEARCH(" - ",TRIM('MSR RAW'!C4))),RIGHT(TRIM('MSR RAW'!C4),6)="Total:"),LEFT(TRIM('MSR RAW'!C4),SEARCH(" - ",TRIM('MSR RAW'!C4))-1),"") | F4: =IF(E4="","",TRIM(MID(TRIM('MSR RAW'!C4),SEARCH(" - ",TRIM('MSR RAW'!C4))+3,LEN(TRIM('MSR RAW'!C4))-SEARCH(" - ",TRIM('MSR RAW'!C4))-9))) | G4: =IF(E4="","",IFERROR(VLOOKUP(E4,'CATEGORY MAP'!$A$2:$B$20,2,FALSE()),"REVIEW")) | H4: =IF(E4="","",IFERROR(VALUE(SUBSTITUTE('MSR RAW'!P4,",","")),0)) | I4: =IF(E4="","",IFERROR(VALUE(SUBSTITUTE('MSR RAW'!S4,",","")),0))
A5: 5 | B5: =IF('MSR RAW'!$A$3="","",'MSR RAW'!$A$3) | C5: =IF(LEFT(TRIM('MSR RAW'!A5),11)="Department:",TRIM('MSR RAW'!A5),C4) | D5: =IF(LEFT(TRIM('MSR RAW'!B5),9)="Location:",TRIM(MID('MSR RAW'!B5,10,999)),D4) | E5: =IF(AND(ISNUMBER(SEARCH(" - ",TRIM('MSR RAW'!C5))),RIGHT(TRIM('MSR RAW'!C5),6)="Total:"),LEFT(TRIM('MSR RAW'!C5),SEARCH(" - ",TRIM('MSR RAW'!C5))-1),"") | F5: =IF(E5="","",TRIM(MID(TRIM('MSR RAW'!C5),SEARCH(" - ",TRIM('MSR RAW'!C5))+3,LEN(TRIM('MSR RAW'!C5))-SEARCH(" - ",TRIM('MSR RAW'!C5))-9))) | G5: =IF(E5="","",IFERROR(VLOOKUP(E5,'CATEGORY MAP'!$A$2:$B$20,2,FALSE()),"REVIEW")) | H5: =IF(E5="","",IFERROR(VALUE(SUBSTITUTE('MSR RAW'!P5,",","")),0)) | I5: =IF(E5="","",IFERROR(VALUE(SUBSTITUTE('MSR RAW'!S5,",","")),0))
A6: 6 | B6: =IF('MSR RAW'!$A$3="","",'MSR RAW'!$A$3) | C6: =IF(LEFT(TRIM('MSR RAW'!A6),11)="Department:",TRIM('MSR RAW'!A6),C5) | D6: =IF(LEFT(TRIM('MSR RAW'!B6),9)="Location:",TRIM(MID('MSR RAW'!B6,10,999)),D5) | E6: =IF(AND(ISNUMBER(SEARCH(" - ",TRIM('MSR RAW'!C6))),RIGHT(TRIM('MSR RAW'!C6),6)="Total:"),LEFT(TRIM('MSR RAW'!C6),SEARCH(" - ",TRIM('MSR RAW'!C6))-1),"") | F6: =IF(E6="","",TRIM(MID(TRIM('MSR RAW'!C6),SEARCH(" - ",TRIM('MSR RAW'!C6))+3,LEN(TRIM('MSR RAW'!C6))-SEARCH(" - ",TRIM('MSR RAW'!C6))-9))) | G6: =IF(E6="","",IFERROR(VLOOKUP(E6,'CATEGORY MAP'!$A$2:$B$20,2,FALSE()),"REVIEW")) | H6: =IF(E6="","",IFERROR(VALUE(SUBSTITUTE('MSR RAW'!P6,",","")),0)) | I6: =IF(E6="","",IFERROR(VALUE(SUBSTITUTE('MSR RAW'!S6,",","")),0))
A7: 7 | B7: =IF('MSR RAW'!$A$3="","",'MSR RAW'!$A$3) | C7: =IF(LEFT(TRIM('MSR RAW'!A7),11)="Department:",TRIM('MSR RAW'!A7),C6) | D7: =IF(LEFT(TRIM('MSR RAW'!B7),9)="Location:",TRIM(MID('MSR RAW'!B7,10,999)),D6) | E7: =IF(AND(ISNUMBER(SEARCH(" - ",TRIM('MSR RAW'!C7))),RIGHT(TRIM('MSR RAW'!C7),6)="Total:"),LEFT(TRIM('MSR RAW'!C7),SEARCH(" - ",TRIM('MSR RAW'!C7))-1),"") | F7: =IF(E7="","",TRIM(MID(TRIM('MSR RAW'!C7),SEARCH(" - ",TRIM('MSR RAW'!C7))+3,LEN(TRIM('MSR RAW'!C7))-SEARCH(" - ",TRIM('MSR RAW'!C7))-9))) | G7: =IF(E7="","",IFERROR(VLOOKUP(E7,'CATEGORY MAP'!$A$2:$B$20,2,FALSE()),"REVIEW")) | H7: =IF(E7="","",IFERROR(VALUE(SUBSTITUTE('MSR RAW'!P7,",","")),0)) | I7: =IF(E7="","",IFERROR(VALUE(SUBSTITUTE('MSR RAW'!S7,",","")),0))
A8: 8 | B8: =IF('MSR RAW'!$A$3="","",'MSR RAW'!$A$3) | C8: =IF(LEFT(TRIM('MSR RAW'!A8),11)="Department:",TRIM('MSR RAW'!A8),C7) | D8: =IF(LEFT(TRIM('MSR RAW'!B8),9)="Location:",TRIM(MID('MSR RAW'!B8,10,999)),D7) | E8: =IF(AND(ISNUMBER(SEARCH(" - ",TRIM('MSR RAW'!C8))),RIGHT(TRIM('MSR RAW'!C8),6)="Total:"),LEFT(TRIM('MSR RAW'!C8),SEARCH(" - ",TRIM('MSR RAW'!C8))-1),"") | F8: =IF(E8="","",TRIM(MID(TRIM('MSR RAW'!C8),SEARCH(" - ",TRIM('MSR RAW'!C8))+3,LEN(TRIM('MSR RAW'!C8))-SEARCH(" - ",TRIM('MSR RAW'!C8))-9))) | G8: =IF(E8="","",IFERROR(VLOOKUP(E8,'CATEGORY MAP'!$A$2:$B$20,2,FALSE()),"REVIEW")) | H8: =IF(E8="","",IFERROR(VALUE(SUBSTITUTE('MSR RAW'!P8,",","")),0)) | I8: =IF(E8="","",IFERROR(VALUE(SUBSTITUTE('MSR RAW'!S8,",","")),0))
A9: 9 | B9: =IF('MSR RAW'!$A$3="","",'MSR RAW'!$A$3) | C9: =IF(LEFT(TRIM('MSR RAW'!A9),11)="Department:",TRIM('MSR RAW'!A9),C8) | D9: =IF(LEFT(TRIM('MSR RAW'!B9),9)="Location:",TRIM(MID('MSR RAW'!B9,10,999)),D8) | E9: =IF(AND(ISNUMBER(SEARCH(" - ",TRIM('MSR RAW'!C9))),RIGHT(TRIM('MSR RAW'!C9),6)="Total:"),LEFT(TRIM('MSR RAW'!C9),SEARCH(" - ",TRIM('MSR RAW'!C9))-1),"") | F9: =IF(E9="","",TRIM(MID(TRIM('MSR RAW'!C9),SEARCH(" - ",TRIM('MSR RAW'!C9))+3,LEN(TRIM('MSR RAW'!C9))-SEARCH(" - ",TRIM('MSR RAW'!C9))-9))) | G9: =IF(E9="","",IFERROR(VLOOKUP(E9,'CATEGORY MAP'!$A$2:$B$20,2,FALSE()),"REVIEW")) | H9: =IF(E9="","",IFERROR(VALUE(SUBSTITUTE('MSR RAW'!P9,",","")),0)) | I9: =IF(E9="","",IFERROR(VALUE(SUBSTITUTE('MSR RAW'!S9,",","")),0))
A10: 10 | B10: =IF('MSR RAW'!$A$3="","",'MSR RAW'!$A$3) | C10: =IF(LEFT(TRIM('MSR RAW'!A10),11)="Department:",TRIM('MSR RAW'!A10),C9) | D10: =IF(LEFT(TRIM('MSR RAW'!B10),9)="Location:",TRIM(MID('MSR RAW'!B10,10,999)),D9) | E10: =IF(AND(ISNUMBER(SEARCH(" - ",TRIM('MSR RAW'!C10))),RIGHT(TRIM('MSR RAW'!C10),6)="Total:"),LEFT(TRIM('MSR RAW'!C10),SEARCH(" - ",TRIM('MSR RAW'!C10))-1),"") | F10: =IF(E10="","",TRIM(MID(TRIM('MSR RAW'!C10),SEARCH(" - ",TRIM('MSR RAW'!C10))+3,LEN(TRIM('MSR RAW'!C10))-SEARCH(" - ",TRIM('MSR RAW'!C10))-9))) | G10: =IF(E10="","",IFERROR(VLOOKUP(E10,'CATEGORY MAP'!$A$2:$B$20,2,FALSE()),"REVIEW")) | H10: =IF(E10="","",IFERROR(VALUE(SUBSTITUTE('MSR RAW'!P10,",","")),0)) | I10: =IF(E10="","",IFERROR(VALUE(SUBSTITUTE('MSR RAW'!S10,",","")),0))
A11: 11 | B11: =IF('MSR RAW'!$A$3="","",'MSR RAW'!$A$3) | C11: =IF(LEFT(TRIM('MSR RAW'!A11),11)="Department:",TRIM('MSR RAW'!A11),C10) | D11: =IF(LEFT(TRIM('MSR RAW'!B11),9)="Location:",TRIM(MID('MSR RAW'!B11,10,999)),D10) | E11: =IF(AND(ISNUMBER(SEARCH(" - ",TRIM('MSR RAW'!C11))),RIGHT(TRIM('MSR RAW'!C11),6)="Total:"),LEFT(TRIM('MSR RAW'!C11),SEARCH(" - ",TRIM('MSR RAW'!C11))-1),"") | F11: =IF(E11="","",TRIM(MID(TRIM('MSR RAW'!C11),SEARCH(" - ",TRIM('MSR RAW'!C11))+3,LEN(TRIM('MSR RAW'!C11))-SEARCH(" - ",TRIM('MSR RAW'!C11))-9))) | G11: =IF(E11="","",IFERROR(VLOOKUP(E11,'CATEGORY MAP'!$A$2:$B$20,2,FALSE()),"REVIEW")) | H11: =IF(E11="","",IFERROR(VALUE(SUBSTITUTE('MSR RAW'!P11,",","")),0)) | I11: =IF(E11="","",IFERROR(VALUE(SUBSTITUTE('MSR RAW'!S11,",","")),0))
A12: 12 | B12: =IF('MSR RAW'!$A$3="","",'MSR RAW'!$A$3) | C12: =IF(LEFT(TRIM('MSR RAW'!A12),11)="Department:",TRIM('MSR RAW'!A12),C11) | D12: =IF(LEFT(TRIM('MSR RAW'!B12),9)="Location:",TRIM(MID('MSR RAW'!B12,10,999)),D11) | E12: =IF(AND(ISNUMBER(SEARCH(" - ",TRIM('MSR RAW'!C12))),RIGHT(TRIM('MSR RAW'!C12),6)="Total:"),LEFT(TRIM('MSR RAW'!C12),SEARCH(" - ",TRIM('MSR RAW'!C12))-1),"") | F12: =IF(E12="","",TRIM(MID(TRIM('MSR RAW'!C12),SEARCH(" - ",TRIM('MSR RAW'!C12))+3,LEN(TRIM('MSR RAW'!C12))-SEARCH(" - ",TRIM('MSR RAW'!C12))-9))) | G12: =IF(E12="","",IFERROR(VLOOKUP(E12,'CATEGORY MAP'!$A$2:$B$20,2,FALSE()),"REVIEW")) | H12: =IF(E12="","",IFERROR(VALUE(SUBSTITUTE('MSR RAW'!P12,",","")),0)) | I12: =IF(E12="","",IFERROR(VALUE(SUBSTITUTE('MSR RAW'!S12,",","")),0))
A13: 13 | B13: =IF('MSR RAW'!$A$3="","",'MSR RAW'!$A$3) | C13: =IF(LEFT(TRIM('MSR RAW'!A13),11)="Department:",TRIM('MSR RAW'!A13),C12) | D13: =IF(LEFT(TRIM('MSR RAW'!B13),9)="Location:",TRIM(MID('MSR RAW'!B13,10,999)),D12) | E13: =IF(AND(ISNUMBER(SEARCH(" - ",TRIM('MSR RAW'!C13))),RIGHT(TRIM('MSR RAW'!C13),6)="Total:"),LEFT(TRIM('MSR RAW'!C13),SEARCH(" - ",TRIM('MSR RAW'!C13))-1),"") | F13: =IF(E13="","",TRIM(MID(TRIM('MSR RAW'!C13),SEARCH(" - ",TRIM('MSR RAW'!C13))+3,LEN(TRIM('MSR RAW'!C13))-SEARCH(" - ",TRIM('MSR RAW'!C13))-9))) | G13: =IF(E13="","",IFERROR(VLOOKUP(E13,'CATEGORY MAP'!$A$2:$B$20,2,FALSE()),"REVIEW")) | H13: =IF(E13="","",IFERROR(VALUE(SUBSTITUTE('MSR RAW'!P13,",","")),0)) | I13: =IF(E13="","",IFERROR(VALUE(SUBSTITUTE('MSR RAW'!S13,",","")),0))
A14: 14 | B14: =IF('MSR RAW'!$A$3="","",'MSR RAW'!$A$3) | C14: =IF(LEFT(TRIM('MSR RAW'!A14),11)="Department:",TRIM('MSR RAW'!A14),C13) | D14: =IF(LEFT(TRIM('MSR RAW'!B14),9)="Location:",TRIM(MID('MSR RAW'!B14,10,999)),D13) | E14: =IF(AND(ISNUMBER(SEARCH(" - ",TRIM('MSR RAW'!C14))),RIGHT(TRIM('MSR RAW'!C14),6)="Total:"),LEFT(TRIM('MSR RAW'!C14),SEARCH(" - ",TRIM('MSR RAW'!C14))-1),"") | F14: =IF(E14="","",TRIM(MID(TRIM('MSR RAW'!C14),SEARCH(" - ",TRIM('MSR RAW'!C14))+3,LEN(TRIM('MSR RAW'!C14))-SEARCH(" - ",TRIM('MSR RAW'!C14))-9))) | G14: =IF(E14="","",IFERROR(VLOOKUP(E14,'CATEGORY MAP'!$A$2:$B$20,2,FALSE()),"REVIEW")) | H14: =IF(E14="","",IFERROR(VALUE(SUBSTITUTE('MSR RAW'!P14,",","")),0)) | I14: =IF(E14="","",IFERROR(VALUE(SUBSTITUTE('MSR RAW'!S14,",","")),0))
... A1000: 1000 | B1000: =IF('MSR RAW'!$A$3="","",'MSR RAW'!$A$3) | C1000: =IF(LEFT(TRIM('MSR RAW'!A1000),11)="Department:",TRIM('MSR RAW'!A1000),C999) | D1000: =IF(LEFT(TRIM('MSR RAW'!B1000),9)="Location:",TRIM(MID('MSR RAW'!B1000,10,999)),D999) | E1000: =IF(AND(ISNUMBER(SEARCH(" - ",TRIM('MSR RAW'!C1000))),RIGHT(TRIM('MSR RAW'!C1000),6)="Total:"),LEFT(TRIM('MSR RAW'!C1000),SEARCH(" - ",TRIM('MSR RAW'!C1000))-1),"") | F1000: =IF(E1000="","",TRIM(MID(TRIM('MSR RAW'!C1000),SEARCH(" - ",TRIM('MSR RAW'!C1000))+3,LEN(TRIM('MSR RAW'!C1000))-SEARCH(" - ",TRIM('MSR RAW'!C1000))-9))) | G1000: =IF(E1000="","",IFERROR(VLOOKUP(E1000,'CATEGORY MAP'!$A$2:$B$20,2,FALSE()),"REVIEW")) | H1000: =IF(E1000="","",IFERROR(VALUE(SUBSTITUTE('MSR RAW'!P1000,",","")),0)) | I1000: =IF(E1000="","",IFERROR(VALUE(SUBSTITUTE('MSR RAW'!S1000,",","")),0))

Sheet CONTRACT CALC
A1: CONTRACT DONATION CALCULATION — ASSIGNMENT-DRIVEN
A2: Rates and minimums are controlled here. Event-specific ownership comes from EVENT ASSIGNMENT; MSR sales come from MSR DATA.
A4: Food / Non-Alcoholic Rate | B4: 0.1
A5: Alcoholic Beverage Rate | B5: 0.08
A6: Minimum Donation / Event | B6: 200
A8: Core Logic | B8: Allocated Food/N-A Net × 10% + Allocated Alcohol Net × 8%
A9: Allocation Rule | B9: Each Event + Location + NPO assignment receives Allocation % of that location’s MSR net sales.
A10: Control | B10: Location allocations should total 100% when a location is operated by one or more NPOs.
A12: Event Date | B12: NPO | C12: Location ID | D12: Location Description | E12: MSR Location | F12: Allocation % | G12: MSR Total Net | H12: Alcohol Net | I12: Food / Non-Alc Net | J12: Allocated Net | K12: NEW CONTRACT DONATION | L12: Status
A13: =IF('EVENT ASSIGNMENT'!A2="","",'EVENT ASSIGNMENT'!A2) | B13: =IF('EVENT ASSIGNMENT'!F2="","",'EVENT ASSIGNMENT'!F2) | C13: =IF('EVENT ASSIGNMENT'!C2="","",'EVENT ASSIGNMENT'!C2) | D13: =IF('EVENT ASSIGNMENT'!D2="","",'EVENT ASSIGNMENT'!D2) | E13: =IF('EVENT ASSIGNMENT'!E2="","",'EVENT ASSIGNMENT'!E2) | F13: =IF('EVENT ASSIGNMENT'!G2="","",'EVENT ASSIGNMENT'!G2) | G13: =IF(E13="",0,SUMIFS('MSR DATA'!$I$2:$I$1001,'MSR DATA'!$D$2:$D$1001,E13)) | H13: =IF(E13="",0,SUMIFS('MSR DATA'!$I$2:$I$1001,'MSR DATA'!$D$2:$D$1001,E13,'MSR DATA'!$G$2:$G$1001,"ALCOHOL")) | I13: =G13-H13 | J13: =G13*IF(F13="",0,F13) | K13: =I13*IF(F13="",0,F13)*$B$4+H13*IF(F13="",0,F13)*$B$5 | L13: =IF(B13="","",IF(F13="","MISSING ALLOCATION",IF(ABS(SUMIFS($F$13:$F$112,$A$13:$A$112,A13,$C$13:$C$112,C13)-1)>0.0001,"REVIEW LOCATION ALLOCATION",IF(G13=0,"NO MSR SALES","OK"))))
A14: =IF('EVENT ASSIGNMENT'!A3="","",'EVENT ASSIGNMENT'!A3) | B14: =IF('EVENT ASSIGNMENT'!F3="","",'EVENT ASSIGNMENT'!F3) | C14: =IF('EVENT ASSIGNMENT'!C3="","",'EVENT ASSIGNMENT'!C3) | D14: =IF('EVENT ASSIGNMENT'!D3="","",'EVENT ASSIGNMENT'!D3) | E14: =IF('EVENT ASSIGNMENT'!E3="","",'EVENT ASSIGNMENT'!E3) | F14: =IF('EVENT ASSIGNMENT'!G3="","",'EVENT ASSIGNMENT'!G3) | G14: =IF(E14="",0,SUMIFS('MSR DATA'!$I$2:$I$1001,'MSR DATA'!$D$2:$D$1001,E14)) | H14: =IF(E14="",0,SUMIFS('MSR DATA'!$I$2:$I$1001,'MSR DATA'!$D$2:$D$1001,E14,'MSR DATA'!$G$2:$G$1001,"ALCOHOL")) | I14: =G14-H14 | J14: =G14*IF(F14="",0,F14) | K14: =I14*IF(F14="",0,F14)*$B$4+H14*IF(F14="",0,F14)*$B$5 | L14: =IF(B14="","",IF(F14="","MISSING ALLOCATION",IF(ABS(SUMIFS($F$13:$F$112,$A$13:$A$112,A14,$C$13:$C$112,C14)-1)>0.0001,"REVIEW LOCATION ALLOCATION",IF(G14=0,"NO MSR SALES","OK"))))
A15: =IF('EVENT ASSIGNMENT'!A4="","",'EVENT ASSIGNMENT'!A4) | B15: =IF('EVENT ASSIGNMENT'!F4="","",'EVENT ASSIGNMENT'!F4) | C15: =IF('EVENT ASSIGNMENT'!C4="","",'EVENT ASSIGNMENT'!C4) | D15: =IF('EVENT ASSIGNMENT'!D4="","",'EVENT ASSIGNMENT'!D4) | E15: =IF('EVENT ASSIGNMENT'!E4="","",'EVENT ASSIGNMENT'!E4) | F15: =IF('EVENT ASSIGNMENT'!G4="","",'EVENT ASSIGNMENT'!G4) | G15: =IF(E15="",0,SUMIFS('MSR DATA'!$I$2:$I$1001,'MSR DATA'!$D$2:$D$1001,E15)) | H15: =IF(E15="",0,SUMIFS('MSR DATA'!$I$2:$I$1001,'MSR DATA'!$D$2:$D$1001,E15,'MSR DATA'!$G$2:$G$1001,"ALCOHOL")) | I15: =G15-H15 | J15: =G15*IF(F15="",0,F15) | K15: =I15*IF(F15="",0,F15)*$B$4+H15*IF(F15="",0,F15)*$B$5 | L15: =IF(B15="","",IF(F15="","MISSING ALLOCATION",IF(ABS(SUMIFS($F$13:$F$112,$A$13:$A$112,A15,$C$13:$C$112,C15)-1)>0.0001,"REVIEW LOCATION ALLOCATION",IF(G15=0,"NO MSR SALES","OK"))))
A16: =IF('EVENT ASSIGNMENT'!A5="","",'EVENT ASSIGNMENT'!A5) | B16: =IF('EVENT ASSIGNMENT'!F5="","",'EVENT ASSIGNMENT'!F5) | C16: =IF('EVENT ASSIGNMENT'!C5="","",'EVENT ASSIGNMENT'!C5) | D16: =IF('EVENT ASSIGNMENT'!D5="","",'EVENT ASSIGNMENT'!D5) | E16: =IF('EVENT ASSIGNMENT'!E5="","",'EVENT ASSIGNMENT'!E5) | F16: =IF('EVENT ASSIGNMENT'!G5="","",'EVENT ASSIGNMENT'!G5) | G16: =IF(E16="",0,SUMIFS('MSR DATA'!$I$2:$I$1001,'MSR DATA'!$D$2:$D$1001,E16)) | H16: =IF(E16="",0,SUMIFS('MSR DATA'!$I$2:$I$1001,'MSR DATA'!$D$2:$D$1001,E16,'MSR DATA'!$G$2:$G$1001,"ALCOHOL")) | I16: =G16-H16 | J16: =G16*IF(F16="",0,F16) | K16: =I16*IF(F16="",0,F16)*$B$4+H16*IF(F16="",0,F16)*$B$5 | L16: =IF(B16="","",IF(F16="","MISSING ALLOCATION",IF(ABS(SUMIFS($F$13:$F$112,$A$13:$A$112,A16,$C$13:$C$112,C16)-1)>0.0001,"REVIEW LOCATION ALLOCATION",IF(G16=0,"NO MSR SALES","OK"))))
A17: =IF('EVENT ASSIGNMENT'!A6="","",'EVENT ASSIGNMENT'!A6) | B17: =IF('EVENT ASSIGNMENT'!F6="","",'EVENT ASSIGNMENT'!F6) | C17: =IF('EVENT ASSIGNMENT'!C6="","",'EVENT ASSIGNMENT'!C6) | D17: =IF('EVENT ASSIGNMENT'!D6="","",'EVENT ASSIGNMENT'!D6) | E17: =IF('EVENT ASSIGNMENT'!E6="","",'EVENT ASSIGNMENT'!E6) | F17: =IF('EVENT ASSIGNMENT'!G6="","",'EVENT ASSIGNMENT'!G6) | G17: =IF(E17="",0,SUMIFS('MSR DATA'!$I$2:$I$1001,'MSR DATA'!$D$2:$D$1001,E17)) | H17: =IF(E17="",0,SUMIFS('MSR DATA'!$I$2:$I$1001,'MSR DATA'!$D$2:$D$1001,E17,'MSR DATA'!$G$2:$G$1001,"ALCOHOL")) | I17: =G17-H17 | J17: =G17*IF(F17="",0,F17) | K17: =I17*IF(F17="",0,F17)*$B$4+H17*IF(F17="",0,F17)*$B$5 | L17: =IF(B17="","",IF(F17="","MISSING ALLOCATION",IF(ABS(SUMIFS($F$13:$F$112,$A$13:$A$112,A17,$C$13:$C$112,C17)-1)>0.0001,"REVIEW LOCATION ALLOCATION",IF(G17=0,"NO MSR SALES","OK"))))
A18: =IF('EVENT ASSIGNMENT'!A7="","",'EVENT ASSIGNMENT'!A7) | B18: =IF('EVENT ASSIGNMENT'!F7="","",'EVENT ASSIGNMENT'!F7) | C18: =IF('EVENT ASSIGNMENT'!C7="","",'EVENT ASSIGNMENT'!C7) | D18: =IF('EVENT ASSIGNMENT'!D7="","",'EVENT ASSIGNMENT'!D7) | E18: =IF('EVENT ASSIGNMENT'!E7="","",'EVENT ASSIGNMENT'!E7) | F18: =IF('EVENT ASSIGNMENT'!G7="","",'EVENT ASSIGNMENT'!G7) | G18: =IF(E18="",0,SUMIFS('MSR DATA'!$I$2:$I$1001,'MSR DATA'!$D$2:$D$1001,E18)) | H18: =IF(E18="",0,SUMIFS('MSR DATA'!$I$2:$I$1001,'MSR DATA'!$D$2:$D$1001,E18,'MSR DATA'!$G$2:$G$1001,"ALCOHOL")) | I18: =G18-H18 | J18: =G18*IF(F18="",0,F18) | K18: =I18*IF(F18="",0,F18)*$B$4+H18*IF(F18="",0,F18)*$B$5 | L18: =IF(B18="","",IF(F18="","MISSING ALLOCATION",IF(ABS(SUMIFS($F$13:$F$112,$A$13:$A$112,A18,$C$13:$C$112,C18)-1)>0.0001,"REVIEW LOCATION ALLOCATION",IF(G18=0,"NO MSR SALES","OK"))))
A19: =IF('EVENT ASSIGNMENT'!A8="","",'EVENT ASSIGNMENT'!A8) | B19: =IF('EVENT ASSIGNMENT'!F8="","",'EVENT ASSIGNMENT'!F8) | C19: =IF('EVENT ASSIGNMENT'!C8="","",'EVENT ASSIGNMENT'!C8) | D19: =IF('EVENT ASSIGNMENT'!D8="","",'EVENT ASSIGNMENT'!D8) | E19: =IF('EVENT ASSIGNMENT'!E8="","",'EVENT ASSIGNMENT'!E8) | F19: =IF('EVENT ASSIGNMENT'!G8="","",'EVENT ASSIGNMENT'!G8) | G19: =IF(E19="",0,SUMIFS('MSR DATA'!$I$2:$I$1001,'MSR DATA'!$D$2:$D$1001,E19)) | H19: =IF(E19="",0,SUMIFS('MSR DATA'!$I$2:$I$1001,'MSR DATA'!$D$2:$D$1001,E19,'MSR DATA'!$G$2:$G$1001,"ALCOHOL")) | I19: =G19-H19 | J19: =G19*IF(F19="",0,F19) | K19: =I19*IF(F19="",0,F19)*$B$4+H19*IF(F19="",0,F19)*$B$5 | L19: =IF(B19="","",IF(F19="","MISSING ALLOCATION",IF(ABS(SUMIFS($F$13:$F$112,$A$13:$A$112,A19,$C$13:$C$112,C19)-1)>0.0001,"REVIEW LOCATION ALLOCATION",IF(G19=0,"NO MSR SALES","OK"))))
A20: =IF('EVENT ASSIGNMENT'!A9="","",'EVENT ASSIGNMENT'!A9) | B20: =IF('EVENT ASSIGNMENT'!F9="","",'EVENT ASSIGNMENT'!F9) | C20: =IF('EVENT ASSIGNMENT'!C9="","",'EVENT ASSIGNMENT'!C9) | D20: =IF('EVENT ASSIGNMENT'!D9="","",'EVENT ASSIGNMENT'!D9) | E20: =IF('EVENT ASSIGNMENT'!E9="","",'EVENT ASSIGNMENT'!E9) | F20: =IF('EVENT ASSIGNMENT'!G9="","",'EVENT ASSIGNMENT'!G9) | G20: =IF(E20="",0,SUMIFS('MSR DATA'!$I$2:$I$1001,'MSR DATA'!$D$2:$D$1001,E20)) | H20: =IF(E20="",0,SUMIFS('MSR DATA'!$I$2:$I$1001,'MSR DATA'!$D$2:$D$1001,E20,'MSR DATA'!$G$2:$G$1001,"ALCOHOL")) | I20: =G20-H20 | J20: =G20*IF(F20="",0,F20) | K20: =I20*IF(F20="",0,F20)*$B$4+H20*IF(F20="",0,F20)*$B$5 | L20: =IF(B20="","",IF(F20="","MISSING ALLOCATION",IF(ABS(SUMIFS($F$13:$F$112,$A$13:$A$112,A20,$C$13:$C$112,C20)-1)>0.0001,"REVIEW LOCATION ALLOCATION",IF(G20=0,"NO MSR SALES","OK"))))
A21: =IF('EVENT ASSIGNMENT'!A10="","",'EVENT ASSIGNMENT'!A10) | B21: =IF('EVENT ASSIGNMENT'!F10="","",'EVENT ASSIGNMENT'!F10) | C21: =IF('EVENT ASSIGNMENT'!C10="","",'EVENT ASSIGNMENT'!C10) | D21: =IF('EVENT ASSIGNMENT'!D10="","",'EVENT ASSIGNMENT'!D10) | E21: =IF('EVENT ASSIGNMENT'!E10="","",'EVENT ASSIGNMENT'!E10) | F21: =IF('EVENT ASSIGNMENT'!G10="","",'EVENT ASSIGNMENT'!G10) | G21: =IF(E21="",0,SUMIFS('MSR DATA'!$I$2:$I$1001,'MSR DATA'!$D$2:$D$1001,E21)) | H21: =IF(E21="",0,SUMIFS('MSR DATA'!$I$2:$I$1001,'MSR DATA'!$D$2:$D$1001,E21,'MSR DATA'!$G$2:$G$1001,"ALCOHOL")) | I21: =G21-H21 | J21: =G21*IF(F21="",0,F21) | K21: =I21*IF(F21="",0,F21)*$B$4+H21*IF(F21="",0,F21)*$B$5 | L21: =IF(B21="","",IF(F21="","MISSING ALLOCATION",IF(ABS(SUMIFS($F$13:$F$112,$A$13:$A$112,A21,$C$13:$C$112,C21)-1)>0.0001,"REVIEW LOCATION ALLOCATION",IF(G21=0,"NO MSR SALES","OK"))))
A22: =IF('EVENT ASSIGNMENT'!A11="","",'EVENT ASSIGNMENT'!A11) | B22: =IF('EVENT ASSIGNMENT'!F11="","",'EVENT ASSIGNMENT'!F11) | C22: =IF('EVENT ASSIGNMENT'!C11="","",'EVENT ASSIGNMENT'!C11) | D22: =IF('EVENT ASSIGNMENT'!D11="","",'EVENT ASSIGNMENT'!D11) | E22: =IF('EVENT ASSIGNMENT'!E11="","",'EVENT ASSIGNMENT'!E11) | F22: =IF('EVENT ASSIGNMENT'!G11="","",'EVENT ASSIGNMENT'!G11) | G22: =IF(E22="",0,SUMIFS('MSR DATA'!$I$2:$I$1001,'MSR DATA'!$D$2:$D$1001,E22)) | H22: =IF(E22="",0,SUMIFS('MSR DATA'!$I$2:$I$1001,'MSR DATA'!$D$2:$D$1001,E22,'MSR DATA'!$G$2:$G$1001,"ALCOHOL")) | I22: =G22-H22 | J22: =G22*IF(F22="",0,F22) | K22: =I22*IF(F22="",0,F22)*$B$4+H22*IF(F22="",0,F22)*$B$5 | L22: =IF(B22="","",IF(F22="","MISSING ALLOCATION",IF(ABS(SUMIFS($F$13:$F$112,$A$13:$A$112,A22,$C$13:$C$112,C22)-1)>0.0001,"REVIEW LOCATION ALLOCATION",IF(G22=0,"NO MSR SALES","OK"))))
A23: =IF('EVENT ASSIGNMENT'!A12="","",'EVENT ASSIGNMENT'!A12) | B23: =IF('EVENT ASSIGNMENT'!F12="","",'EVENT ASSIGNMENT'!F12) | C23: =IF('EVENT ASSIGNMENT'!C12="","",'EVENT ASSIGNMENT'!C12) | D23: =IF('EVENT ASSIGNMENT'!D12="","",'EVENT ASSIGNMENT'!D12) | E23: =IF('EVENT ASSIGNMENT'!E12="","",'EVENT ASSIGNMENT'!E12) | F23: =IF('EVENT ASSIGNMENT'!G12="","",'EVENT ASSIGNMENT'!G12) | G23: =IF(E23="",0,SUMIFS('MSR DATA'!$I$2:$I$1001,'MSR DATA'!$D$2:$D$1001,E23)) | H23: =IF(E23="",0,SUMIFS('MSR DATA'!$I$2:$I$1001,'MSR DATA'!$D$2:$D$1001,E23,'MSR DATA'!$G$2:$G$1001,"ALCOHOL")) | I23: =G23-H23 | J23: =G23*IF(F23="",0,F23) | K23: =I23*IF(F23="",0,F23)*$B$4+H23*IF(F23="",0,F23)*$B$5 | L23: =IF(B23="","",IF(F23="","MISSING ALLOCATION",IF(ABS(SUMIFS($F$13:$F$112,$A$13:$A$112,A23,$C$13:$C$112,C23)-1)>0.0001,"REVIEW LOCATION ALLOCATION",IF(G23=0,"NO MSR SALES","OK"))))
A24: =IF('EVENT ASSIGNMENT'!A13="","",'EVENT ASSIGNMENT'!A13) | B24: =IF('EVENT ASSIGNMENT'!F13="","",'EVENT ASSIGNMENT'!F13) | C24: =IF('EVENT ASSIGNMENT'!C13="","",'EVENT ASSIGNMENT'!C13) | D24: =IF('EVENT ASSIGNMENT'!D13="","",'EVENT ASSIGNMENT'!D13) | E24: =IF('EVENT ASSIGNMENT'!E13="","",'EVENT ASSIGNMENT'!E13) | F24: =IF('EVENT ASSIGNMENT'!G13="","",'EVENT ASSIGNMENT'!G13) | G24: =IF(E24="",0,SUMIFS('MSR DATA'!$I$2:$I$1001,'MSR DATA'!$D$2:$D$1001,E24)) | H24: =IF(E24="",0,SUMIFS('MSR DATA'!$I$2:$I$1001,'MSR DATA'!$D$2:$D$1001,E24,'MSR DATA'!$G$2:$G$1001,"ALCOHOL")) | I24: =G24-H24 | J24: =G24*IF(F24="",0,F24) | K24: =I24*IF(F24="",0,F24)*$B$4+H24*IF(F24="",0,F24)*$B$5 | L24: =IF(B24="","",IF(F24="","MISSING ALLOCATION",IF(ABS(SUMIFS($F$13:$F$112,$A$13:$A$112,A24,$C$13:$C$112,C24)-1)>0.0001,"REVIEW LOCATION ALLOCATION",IF(G24=0,"NO MSR SALES","OK"))))
